Workbook

Sheet Sheet1
A1: INDEX | B1: SPMCODE | C1: ALTERNATE.PROJECTCODE | D1: Collector_no | E1: Alt_Coll_No | F1: Rebekahs Determination | G1: Rebekah notes | H1: Hybrid Parentage | I1: TAXA-Current_determination | J1: Collection_date | K1: Collectors | L1: Type_of_material | M1: OWNER | N1: Country | O1: State_Province_Region_territory | P1: substate | Q1: substateRank | R1: site | S1: Locality Notes | T1: habitat | U1: associates | V1: DBH-cm | W1: Height-m | X1: plantAttributesOther | Y1: Determination_HIST_PIPED | Z1: Determined_by | AA1: Determined_date | AB1: determination_reasoning_notes | AC1: latitude.orig | AD1: longitude.orig | AE1: Elevation | AF1: photos | AG1: Collecting_Extracting_notes | AH1: Project | AI1: DNA | AJ1: SpecimenVoucher | AK1: MOR_Acc_Num | AL1: Voucher_Notes | AM1: MOR_BARCODE | AN1: occurrenceID | AO1: SEINet_references | AP1: WholeGenome_BioProject | AQ1: WholeGenome_SRA_Run | AR1: WholeGenome_libraryID | AS1: WholeGenomeFastqR1 | AT1: WholeGenomeFastqR2 | AU1: SRA_biosample_accession | AV1: HYB-SEQ_BioProject | AW1: Lookup-SUBGENUS-by-CurrentTAXA | AX1: LOOKUP-section-by-currentTAXA | AY1: Lookup-CLADE0by-CurrentTAXA
A2: 1903 | B2: QUE001903 | D2: OK-MG372 | I2: Quercus macrocarpa | J2: 42907 | K2: Mira Garner, Sara Desmond, Abigail Moore | L2: fresh, frozen | M2: HIPP | N2: USA | O2: Oklahoma | P2: Cleveland | Q2: County | R2: Oliver's Woods | S2: Norman, University of Oklahoma campus | T2: woody area on roadside | Y2: Quercus macrocarpa Michx. | AC2: 35.17703 | AD2: -97.45019 | AE2: 1110 ft. | AH2: Characterization of Native Oak Germplasm, Quercus macrocarpa and related white oaks. USDA SCA 58-8020-5-005 | AI2: MOR | AJ2: MOR<USA-IL>: Garner, OK-MG372 | AK2: 185382 | AM2: 0095528MOR | AN2: 1B0CB51B-B0EA-44CC-BE12-7F7083F75569 | AO2: https://swbiodiversity.org/seinet/collections/individual/index.php?occid=32894149 | AP2: PRJNA1200080 | AR2: SYST-MOR-0007409 | AS2: SYST-MOR-0007409_S135_1.fq.gz | AT2: SYST-MOR-0007409_S135_2.fq.gz | AW2: subg. Quercus | AX2: Quercus | AY2: Prinoideae
A3: 1904 | B3: QUE001904 | D3: OK-MG373 | I3: Quercus macrocarpa | J3: 42907 | K3: Mira Garner, Sara Desmond, Abigail Moore | L3: fresh, frozen | M3: HIPP | N3: USA | O3: Oklahoma | P3: Cleveland | Q3: County | R3: Oliver's Woods | S3: Norman, University of Oklahoma campus | T3: woods | Y3: Quercus macrocarpa Michx.|Q. macrocarpa | Z3: A.L. Hipp and G. Ribicoff | AA3: 45597 | AB3: NA | AC3: 35.17705 | AD3: -97.44921 | AE3: 1228 ft | AH3: Characterization of Native Oak Germplasm, Quercus macrocarpa and related white oaks. USDA SCA 58-8020-5-005 | AI3: MOR | AJ3: MOR<USA-IL>: Garner, OK-MG373 | AK3: 185383 | AM3: 0095529MOR | AN3: 8C5D8B44-9420-4170-AEA4-D39027A1CCFA | AO3: https://swbiodiversity.org/seinet/collections/individual/index.php?occid=32901923 | AP3: PRJNA1200080 | AR3: SYST-MOR-0007410 | AS3: SYST-MOR-0007410_S136_1.fq.gz | AT3: SYST-MOR-0007410_S136_2.fq.gz | AU3: SAMN46848228 | AV3: PRJNA1223965 | AW3: subg. Quercus | AX3: Quercus | AY3: Prinoideae
A4: 1905 | B4: QUE001905 | D4: OK-MG374 | I4: Quercus macrocarpa | J4: 42907 | K4: Mira Garner, Sara Desmond, Abigail Moore | L4: fresh, frozen | M4: HIPP | N4: USA | O4: Oklahoma | P4: Cleveland | Q4: County | R4: Oliver's Woods | S4: Norman, University of Oklahoma campus | T4: woods | Y4: Quercus macrocarpa Michx. | AC4: 35.17722 | AD4: -97.44967 | AE4: 1133 ft | AH4: Characterization of Native Oak Germplasm, Quercus macrocarpa and related white oaks. USDA SCA 58-8020-5-005 | AI4: MOR | AJ4: MOR<USA-IL>: Garner, OK-MG374 | AK4: 185384 | AM4: 0095530MOR | AN4: F3FEAF8D-071F-45E0-8F3A-68429C396CE5 | AO4: https://swbiodiversity.org/seinet/collections/individual/index.php?occid=32891891 | AP4: PRJNA1200080 | AR4: SYST-MOR-0007411 | AS4: SYST-MOR-0007411_S137_1.fq.gz | AT4: SYST-MOR-0007411_S137_2.fq.gz | AW4: subg. Quercus | AX4: Quercus | AY4: Prinoideae
A5: 1906 | B5: QUE001906 | D5: OK-MG375 | I5: Quercus macrocarpa | J5: 42907 | K5: Mira Garner, Sara Desmond, Abigail Moore | L5: fresh, frozen | M5: HIPP | N5: USA | O5: Oklahoma | P5: Cleveland | Q5: County | R5: Oliver's Woods | S5: Norman, University of Oklahoma campus | T5: woods | Y5: Quercus macrocarpa Michx. | AC5: 35.17704 | AD5: -97.44977 | AE5: 1105 ft | AH5: Characterization of Native Oak Germplasm, Quercus macrocarpa and related white oaks. USDA SCA 58-8020-5-005 | AI5: MOR | AJ5: MOR<USA-IL>: Garner, OK-MG375 | AK5: 185385 | AM5: 0095531MOR | AN5: A5B0B55E-FE3B-4429-804D-028A19C55504 | AO5: https://swbiodiversity.org/seinet/collections/individual/index.php?occid=32903254 | AP5: PRJNA1200080 | AR5: SYST-MOR-0007412 | AS5: SYST-MOR-0007412_S138_1.fq.gz | AT5: SYST-MOR-0007412_S138_2.fq.gz | AW5: subg. Quercus | AX5: Quercus | AY5: Prinoideae
A6: 1907 | B6: QUE001907 | D6: OK-MG376 | I6: Quercus macrocarpa | J6: 42907 | K6: Mira Garner, Sara Desmond, Abigail Moore | L6: fresh, frozen | M6: HIPP | N6: USA | O6: Oklahoma | P6: Cleveland | Q6: County | R6: Oliver's Woods | S6: Norman, University of Oklahoma campus | T6: woods | Y6: Quercus macrocarpa Michx.|Q. macrocarpa | Z6: A.L. Hipp and G. Ribicoff | AA6: 45597 | AB6: NA | AC6: 35.17688 | AD6: -97.4497 | AE6: 1210 ft | AH6: Characterization of Native Oak Germplasm, Quercus macrocarpa and related white oaks. USDA SCA 58-8020-5-005 | AI6: MOR | AJ6: MOR<USA-IL>: Garner, OK-MG376 | AK6: 185386 | AM6: 0095532MOR | AN6: E1BB2E7A-821A-476E-903A-5643984C9EB9 | AO6: https://swbiodiversity.org/seinet/collections/individual/index.php?occid=32891468 | AP6: PRJNA1200080 | AR6: SYST-MOR-0007413 | AS6: SYST-MOR-0007413_S139_1.fq.gz | AT6: SYST-MOR-0007413_S139_2.fq.gz | AU6: SAMN46848229 | AV6: PRJNA1223965 | AW6: subg. Quercus | AX6: Quercus | AY6: Prinoideae
A7: 1908 | B7: QUE001908 | D7: OK-MG377 | I7: Quercus macrocarpa | J7: 42907 | K7: Mira Garner, Sara Desmond, Abigail Moore | L7: fresh, frozen | M7: HIPP | N7: USA | O7: Oklahoma | P7: Cleveland | Q7: County | R7: Oliver's Woods | S7: Norman, University of Oklahoma campus | T7: woods | Y7: Quercus macrocarpa Michx. | AC7: 35.17669 | AD7: -97.44988 | AE7: 1107 ft | AH7: Characterization of Native Oak Germplasm, Quercus macrocarpa and related white oaks. USDA SCA 58-8020-5-005 | AI7: MOR | AJ7: MOR<USA-IL>: Garner, OK-MG377 | AK7: 185387 | AM7: 0095533MOR | AN7: EB765CC1-B929-450E-9A3E-981E5741AF11 | AO7: https://swbiodiversity.org/seinet/collections/individual/index.php?occid=32892568 | AP7: PRJNA1200080 | AR7: SYST-MOR-0007414 | AS7: SYST-MOR-0007414_S140_1.fq.gz | AT7: SYST-MOR-0007414_S140_2.fq.gz | AW7: subg. Quercus | AX7: Quercus | AY7: Prinoideae
A8: 1909 | B8: QUE001909 | D8: OK-MG378 | I8: Quercus macrocarpa | J8: 42907 | K8: Mira Garner, Sara Desmond, Abigail Moore | L8: fresh, frozen | M8: HIPP | N8: USA | O8: Oklahoma | P8: Cleveland | Q8: County | R8: Oliver's Woods | S8: Norman, University of Oklahoma campus | T8: woods | Y8: Quercus macrocarpa Michx. | AC8: 35.17635 | AD8: -97.45009 | AE8: 1067 ft | AH8: Characterization of Native Oak Germplasm, Quercus macrocarpa and related white oaks. USDA SCA 58-8020-5-005 | AI8: MOR | AJ8: MOR<USA-IL>: Garner, OK-MG378 | AK8: 185388 | AM8: 0095534MOR | AN8: B0738385-C50A-4FFB-9881-46D2836F4069 | AO8: https://swbiodiversity.org/seinet/collections/individual/index.php?occid=32903946 | AP8: PRJNA1200080 | AR8: SYST-MOR-0007415 | AS8: SYST-MOR-0007415_S141_1.fq.gz | AT8: SYST-MOR-0007415_S141_2.fq.gz | AW8: subg. Quercus | AX8: Quercus | AY8: Prinoideae
A9: 1910 | B9: QUE001910 | D9: OK-MG379 | I9: Quercus macrocarpa | J9: 42907 | K9: Mira Garner, Sara Desmond, Abigail Moore | L9: fresh, frozen | M9: HIPP | N9: USA | O9: Oklahoma | P9: Cleveland | Q9: County | R9: Oliver's Woods | S9: Norman, University of Oklahoma campus | T9: woods | Y9: Quercus macrocarpa Michx. | AC9: 35.17695 | AD9: -97.44996 | AE9: 1110 ft | AH9: Characterization of Native Oak Germplasm, Quercus macrocarpa and related white oaks. USDA SCA 58-8020-5-005 | AI9: MOR | AJ9: MOR<USA-IL>: Garner, OK-MG379 | AK9: 184679 | AM9: 0094442MOR | AN9: 1B05A235-2E83-4243-A675-EF3A9DBF616D | AO9: https://swbiodiversity.org/seinet/collections/individual/index.php?occid=32894145 | AP9: PRJNA1200080 | AR9: SYST-MOR-0007416 | AS9: SYST-MOR-0007416_S142_1.fq.gz | AT9: SYST-MOR-0007416_S142_2.fq.gz | AW9: subg. Quercus | AX9: Quercus | AY9: Prinoideae
A10: 1911 | B10: QUE001911 | D10: OK-MG380 | I10: Quercus macrocarpa | J10: 42907 | K10: Mira Garner, Sara Desmond, Abigail Moore | L10: fresh, frozen | M10: HIPP | N10: USA | O10: Oklahoma | P10: Cleveland | Q10: County | R10: Oliver's Woods | S10: Norman, University of Oklahoma campus | T10: woods | Y10: Quercus macrocarpa Michx. | AC10: 35.17714 | AD10: -97.45005 | AE10: 1162 ft | AH10: Characterization of Native Oak Germplasm, Quercus macrocarpa and related white oaks. USDA SCA 58-8020-5-005 | AI10: MOR | AJ10: MOR<USA-IL>: Garner, OK-MG380 | AK10: 185825 | AM10: 0096836MOR | AN10: 2704FDD5-21A8-488B-9F3F-84FC04A58E3C | AO10: https://swbiodiversity.org/seinet/collections/individual/index.php?occid=32895260 | AP10: PRJNA1200080 | AR10: SYST-MOR-0007417 | AS10: SYST-MOR-0007417_S143_1.fq.gz | AT10: SYST-MOR-0007417_S143_2.fq.gz | AW10: subg. Quercus | AX10: Quercus | AY10: Prinoideae
A11: 1912 | B11: QUE001912 | D11: OK-MG381 | I11: Quercus macrocarpa | J11: 42907 | K11: Mira Garner, Sara Desmond, Abigail Moore | L11: fresh, frozen | M11: HIPP | N11: USA | O11: Oklahoma | P11: Cleveland | Q11: County | R11: Oliver's Woods | S11: Norman, University of Oklahoma campus | T11: woods | Y11: Quercus macrocarpa Michx.|Q. macrocarpa | Z11: A.L. Hipp and G. Ribicoff | AA11: 45597 | AB11: NA | AC11: 35.17722 | AD11: -97.45003 | AE11: 1151 ft | AH11: Characterization of Native Oak Germplasm, Quercus macrocarpa and related white oaks. USDA SCA 58-8020-5-005 | AI11: MOR | AJ11: MOR<USA-IL>: Garner, OK-MG381 | AK11: 185389 | AM11: 0095535MOR | AN11: 76850C3C-06E5-4D7A-A759-BE75CAFAC371 | AO11: https://swbiodiversity.org/seinet/collections/individual/index.php?occid=32900700 | AP11: PRJNA1200080 | AR11: SYST-MOR-0007418 | AS11: SYST-MOR-0007418_S144_1.fq.gz | AT11: SYST-MOR-0007418_S144_2.fq.gz | AU11: SAMN46848230 | AV11: PRJNA1223965 | AW11: subg. Quercus | AX11: Quercus | AY11: Prinoideae
A12: 1929 | B12: QUE001929 | D12: MO-MG398 | I12: Quercus macrocarpa | J12: 42909 | K12: Mira Garner, Sara Desmond | L12: fresh, frozen | M12: HIPP | N12: USA | O12: Missouri | P12: Shannon | Q12: County | R12: Eminence, Buttin Rock Access | S12: near river | T12: Flood plain (rocky) | Y12: Quercus macrocarpa Michx.|Quercus macrocarpa | Z12: A.L. Hipp and G. Ribicoff | AA12: 45597 | AB12: NA | AE12: 320 | AG12: GPS: (34.79766, -92.31501) 320 ft. These coordinates match better previous site. | AH12: Characterization of Native Oak Germplasm, Quercus macrocarpa and related white oaks. USDA SCA 58-8020-5-005 | AI12: MOR | AJ12: MOR<USA-IL>: Garner, MO-MG398 | AK12: 184694 | AM12: 0094457MOR | AN12: 17D22E26-7B55-4529-825A-F405BA94EC0D | AO12: https://swbiodiversity.org/seinet/collections/individual/index.php?occid=32894014 | AP12: PRJNA1200080 | AR12: SYST-MOR-0007419 | AS12: SYST-MOR-0007419_S145_1.fq.gz | AT12: SYST-MOR-0007419_S145_2.fq.gz | AU12: SAMN46848241 | AV12: PRJNA1223965 | AW12: subg. Quercus | AX12: Quercus | AY12: Prinoideae
A13: 1931 | B13: QUE001931 | D13: MO-MG400 | I13: Quercus macrocarpa | J13: 42909 | K13: Mira Garner, Sara Desmond | L13: fresh, frozen | M13: HIPP | N13: USA | O13: Missouri | P13: Shannon | Q13: County | R13: Eminence, Buttin Rock Access | S13: near river | T13: Flood plain (rocky) | Y13: Quercus macrocarpa Michx. ? | AC13: 37.15767 | AD13: -91.36474 | AE13: 658 ft | AH13: Characterization of Native Oak Germplasm, Quercus macrocarpa and related white oaks. USDA SCA 58-8020-5-005 | AI13: MOR | AJ13: MOR<USA-IL>: Garner, MO-MG400 | AK13: 184696 | AM13: 0094459MOR | AN13: A7AD188D-86CD-45CF-A20A-A3A701BBD4BC | AO13: https://swbiodiversity.org/seinet/collections/individual/index.php?occid=32904249 | AP13: PRJNA1200080 | AR13: SYST-MOR-0007420 | AS13: SYST-MOR-0007420_S146_1.fq.gz | AT13: SYST-MOR-0007420_S146_2.fq.gz | AW13: subg. Quercus | AX13: Quercus | AY13: Prinoideae
A14: 1933 | B14: QUE001933 | D14: MO-MG402 | I14: Quercus macrocarpa | J14: 42909 | K14: Mira Garner, Sara Desmond | L14: fresh, frozen | M14: HIPP | N14: USA | O14: Missouri | P14: Shannon | Q14: County | R14: Eminence, Buttin Rock Access | S14: near river | T14: Flood plain (rocky) | Y14: Quercus macrocarpa Michx.|Q. macrocarpa | Z14: A.L. Hipp and G. Ribicoff | AA14: 45597 | AB14: NA | AC14: 37.15687 | AD14: -91.36471 | AE14: 644 ft | AH14: Characterization of Native Oak Germplasm, Quercus macrocarpa and related white oaks. USDA SCA 58-8020-5-005 | AI14: MOR | AJ14: MOR<USA-IL>: Garner, MO-MG402 | AK14: 184697 | AM14: 0094460MOR | AN14: BF9014CB-BC74-4F80-A06F-2BA13470897B | AO14: https://swbiodiversity.org/seinet/collections/individual/index.php?occid=32889307 | AP14: PRJNA1200080 | AR14: SYST-MOR-0007421 | AS14: SYST-MOR-0007421_S147_1.fq.gz | AT14: SYST-MOR-0007421_S147_2.fq.gz | AU14: SAMN46848244 | AV14: PRJNA1223965 | AW14: subg. Quercus | AX14: Quercus | AY14: Prinoideae
A15: 1934 | B15: QUE001934 | D15: MO-MG403 | I15: Quercus macrocarpa | J15: 42909 | K15: Mira Garner, Sara Desmond | L15: fresh, frozen | M15: HIPP | N15: USA | O15: Missouri | P15: Shannon | Q15: County | R15: Eminence, Buttin Rock Access | S15: near trailer park | T15: Flood plain (rocky) | Y15: Quercus macrocarpa Michx. | AC15: 37.15686 | AD15: -91.36501 | AE15: 588 ft | AH15: Characterization of Native Oak Germplasm, Quercus macrocarpa and related white oaks. USDA SCA 58-8020-5-005 | AI15: MOR | AJ15: MOR<USA-IL>: Garner, MO-MG403 | AK15: 186782 | AM15: 0097830MOR | AN15: 4C0FCE45-01F8-40FE-A26E-DFB5234990B1 | AO15: https://swbiodiversity.org/seinet/collections/individual/index.php?occid=32898224 | AP15: PRJNA1200080 | AR15: SYST-MOR-0007422 | AS15: SYST-MOR-0007422_S148_1.fq.gz | AT15: SYST-MOR-0007422_S148_2.fq.gz | AW15: subg. Quercus | AX15: Quercus | AY15: Prinoideae
A16: 1935 | B16: QUE001935 | D16: MO-MG404 | I16: Quercus macrocarpa | J16: 42909 | K16: Mira Garner, Sara Desmond | L16: fresh, frozen | M16: HIPP | N16: USA | O16: Missouri | P16: Shannon | Q16: County | R16: Eminence, Buttin Rock Access | S16: near trailer park | T16: Flood plain (rocky) | Y16: Quercus macrocarpa Michx. | AC16: 37.15726 | AD16: -91.36518 | AE16: 722 ft | AH16: Characterization of Native Oak Germplasm, Quercus macrocarpa and related white oaks. USDA SCA 58-8020-5-005 | AI16: MOR | AJ16: MOR<USA-IL>: Garner, MO-MG404 | AK16: 186775 | AM16: 0097823MOR | AN16: E820B09F-737D-40F8-AE94-AC549B09DA65 | AO16: https://swbiodiversity.org/seinet/collections/individual/index.php?occid=32892837 | AP16: PRJNA1200080 | AR16: SYST-MOR-0007423 | AS16: SYST-MOR-0007423_S149_1.fq.gz | AT16: SYST-MOR-0007423_S149_2.fq.gz | AW16: subg. Quercus | AX16: Quercus | AY16: Prinoideae
A17: 1936 | B17: QUE001936 | D17: MO-MG405 | I17: Quercus macrocarpa | J17: 42909 | K17: Mira Garner, Sara Desmond | L17: fresh, frozen | M17: HIPP | N17: USA | O17: Missouri | P17: Shannon | Q17: County | R17: Eminence, Buttin Rock Access | S17: near river | T17: Flood plain (rocky) | Y17: Quercus macrocarpa Michx.|Q. macrocarpa | Z17: A.L. Hipp and G. Ribicoff | AA17: 45597 | AB17: NA | AC17: 37.15758 | AD17: -91.36513 | AE17: 670 ft | AH17: Characterization of Native Oak Germplasm, Quercus macrocarpa and related white oaks. USDA SCA 58-8020-5-005 | AI17: MOR | AJ17: MOR<USA-IL>: Garner, MO-MG405 | AK17: 184698 | AM17: 0094461MOR | AN17: 7814F359-D097-4070-BD93-FC6A4422172C | AO17: https://swbiodiversity.org/seinet/collections/individual/index.php?occid=32901107 | AP17: PRJNA1200080 | AR17: SYST-MOR-0007424 | AS17: SYST-MOR-0007424_S150_1.fq.gz | AT17: SYST-MOR-0007424_S150_2.fq.gz | AU17: SAMN46848245 | AV17: PRJNA1223965 | AW17: subg. Quercus | AX17: Quercus | AY17: Prinoideae
A18: 1950 | B18: QUE001950 | D18: MB-MG506 | I18: Quercus macrocarpa | J18: 42922 | K18: Mira Garner, Sara Desmond, Bruce Ford | L18: fresh, frozen | M18: HIPP | N18: Canada | O18: Manitoba | R18: Whiteshell Provincial Park | T18: granite hill top, graminoid dominated, scattered oaks | Y18: Quercus macrocarpa Michx. | AC18: 49.71359 | AD18: -95.24349 | AE18: 1172 ft | AH18: Characterization of Native Oak Germplasm, Quercus macrocarpa and related white oaks. USDA SCA 58-8020-5-005 | AI18: MOR | AJ18: MOR<USA-IL>: Garner, MB-MG506 | AK18: 184786 | AM18: 0094465MOR | AN18: 9CB9FE3F-E5C2-4D9F-B384-B7F122593424 | AO18: https://swbiodiversity.org/seinet/collections/individual/index.php?occid=32902746 | AP18: PRJNA1200080 | AR18: SYST-MOR-0007357 | AS18: SYST-MOR-0007357_S83_1.fq.gz | AT18: SYST-MOR-0007357_S83_2.fq.gz | AW18: subg. Quercus | AX18: Quercus | AY18: Prinoideae
A19: 1951 | B19: QUE001951 | D19: MB-MG507 | I19: Quercus macrocarpa | J19: 42922 | K19: Mira Garner, Sara Desmond, Bruce Ford | L19: fresh, frozen | M19: HIPP | N19: Canada | O19: Manitoba | R19: Whiteshell Provincial Park | T19: granite hill top, graminoid dominated, scattered oaks | Y19: Quercus macrocarpa Michx. | AC19: 49.71376 | AD19: -95.24385 | AE19: 1164 ft | AH19: Characterization of Native Oak Germplasm, Quercus macrocarpa and related white oaks. USDA SCA 58-8020-5-005 | AI19: MOR | AJ19: MOR<USA-IL>: Garner, MB-MG507 | AK19: 184787 | AM19: 0094466MOR | AN19: 69344D93-B62C-4FD3-A7BD-2C75F4B4224F | AO19: https://swbiodiversity.org/seinet/collections/individual/index.php?occid=32899981 | AP19: PRJNA1200080 | AR19: SYST-MOR-0007358 | AS19: SYST-MOR-0007358_S84_1.fq.gz | AT19: SYST-MOR-0007358_S84_2.fq.gz | AU19: SAMN46848251 | AV19: PRJNA1223965 | AW19: subg. Quercus | AX19: Quercus | AY19: Prinoideae
A20: 1952 | B20: QUE001952 | D20: MB-MG508 | I20: Quercus macrocarpa | J20: 42922 | K20: Mira Garner, Sara Desmond, Bruce Ford | L20: fresh, frozen | M20: HIPP | N20: Canada | O20: Manitoba | R20: Whiteshell Provincial Park | T20: granite hill, edge of pipeline | Y20: Quercus macrocarpa Michx. | AC20: 49.71278 | AD20: -95.24432 | AE20: 1161 ft | AH20: Characterization of Native Oak Germplasm, Quercus macrocarpa and related white oaks. USDA SCA 58-8020-5-005 | AI20: MOR | AJ20: MOR<USA-IL>: Garner, MB-MG508 | AK20: 184788 | AM20: 0094467MOR | AN20: 5F7FC7BD-6CE9-4570-90A9-C377B303C819 | AO20: https://swbiodiversity.org/seinet/collections/individual/index.php?occid=32899444 | AP20: PRJNA1200080 | AR20: SYST-MOR-0007359 | AS20: SYST-MOR-0007359_S85_1.fq.gz | AT20: SYST-MOR-0007359_S85_2.fq.gz | AW20: subg. Quercus | AX20: Quercus | AY20: Prinoideae
A21: 1953 | B21: QUE001953 | D21: MB-MG509 | I21: Quercus macrocarpa | J21: 42922 | K21: Mira Garner, Sara Desmond, Bruce Ford | L21: fresh, frozen | M21: HIPP | N21: Canada | O21: Manitoba | R21: Whiteshell Provincial Park | S21: near side of Block4 Rd. | T21: granite hill top, graminoid dominated, scattered oaks | Y21: Quercus macrocarpa Michx. | AC21: 49.71278 | AD21: -95.2445 | AE21: 1190 ft | AH21: Characterization of Native Oak Germplasm, Quercus macrocarpa and related white oaks. USDA SCA 58-8020-5-005 | AI21: MOR | AJ21: MOR<USA-IL>: Garner, MB-MG509 | AK21: 184789 | AM21: 0094468MOR | AN21: 3A28C8D5-FA33-4BA2-AF7B-03FC0557198C | AO21: https://swbiodiversity.org/seinet/collections/individual/index.php?occid=32896704 | AP21: PRJNA1200080 | AR21: SYST-MOR-0007360 | AS21: SYST-MOR-0007360_S86_1.fq.gz | AT21: SYST-MOR-0007360_S86_2.fq.gz | AW21: subg. Quercus | AX21: Quercus | AY21: Prinoideae
A22: 1954 | B22: QUE001954 | D22: MB-MG510 | I22: Quercus macrocarpa | J22: 42922 | K22: Mira Garner, Sara Desmond, Bruce Ford | L22: fresh, frozen | M22: HIPP | N22: Canada | O22: Manitoba | R22: Whiteshell Provincial Park | S22: driveway off Block 4 Rd. | T22: granite hill top, graminoid dominated, scattered oaks | Y22: Quercus macrocarpa Michx. | AC22: 49.71216 | AD22: -95.24463 | AE22: 1132 ft | AH22: Characterization of Native Oak Germplasm, Quercus macrocarpa and related white oaks. USDA SCA 58-8020-5-005 | AI22: MOR | AJ22: MOR<USA-IL>: Garner, MB-MG510 | AK22: 184790 | AM22: 0094469MOR | AN22: 5086887E-854D-43E3-872B-BED3C273891A | AO22: https://swbiodiversity.org/seinet/collections/individual/index.php?occid=32897403 | AP22: PRJNA1200080 | AR22: SYST-MOR-0007361 | AS22: SYST-MOR-0007361_S87_1.fq.gz | AT22: SYST-MOR-0007361_S87_2.fq.gz | AW22: subg. Quercus | AX22: Quercus | AY22: Prinoideae
A23: 1955 | B23: QUE001955 | D23: MB-MG511 | I23: Quercus macrocarpa | J23: 42922 | K23: Mira Garner, Sara Desmond, Bruce Ford | L23: fresh, frozen | M23: HIPP | N23: Canada | O23: Manitoba | R23: Whiteshell Provincial Park | S23: driveway off Block 4 Rd. | T23: granite hill top, graminoid dominated, scattered oaks | Y23: Quercus macrocarpa Michx.|Q. macrocarpa | Z23: A.L. Hipp and G. Ribicoff | AA23: 45597 | AB23: NA | AC23: 49.71204 | AD23: -95.2448 | AE23: 1146 ft | AH23: Characterization of Native Oak Germplasm, Quercus macrocarpa and related white oaks. USDA SCA 58-8020-5-005 | AI23: MOR | AJ23: MOR<USA-IL>: Garner, MB-MG511 | AK23: 184791 | AM23: 0094470MOR | AN23: FDA8A786-D73C-46F9-971E-2E361BCD299B | AO23: https://swbiodiversity.org/seinet/collections/individual/index.php?occid=32893163 | AP23: PRJNA1200080 | AR23: SYST-MOR-0007362 | AS23: SYST-MOR-0007362_S88_1.fq.gz | AT23: SYST-MOR-0007362_S88_2.fq.gz | AU23: SAMN46848252 | AV23: PRJNA1223965 | AW23: subg. Quercus | AX23: Quercus | AY23: Prinoideae
A24: 1956 | B24: QUE001956 | D24: MB-MG512 | I24: Quercus macrocarpa | J24: 42922 | K24: Mira Garner, Sara Desmond, Bruce Ford | L24: fresh, frozen | M24: HIPP | N24: Canada | O24: Manitoba | R24: Whiteshell Provincial Park | S24: driveway off Block 4 Rd. | T24: granite hill top, graminoid dominated, scattered oaks | Y24: Quercus macrocarpa Michx. | AC24: 49.71195 | AD24: -95.24492 | AE24: 1136 ft | AH24: Characterization of Native Oak Germplasm, Quercus macrocarpa and related white oaks. USDA SCA 58-8020-5-005 | AI24: MOR | AJ24: MOR<USA-IL>: Garner, MB-MG512 | AK24: 184792 | AM24: 0094471MOR | AN24: A35BBADB-F1B3-45D0-B23C-164C854379E1 | AO24: https://swbiodiversity.org/seinet/collections/individual/index.php?occid=32902370 | AP24: PRJNA1200080 | AR24: SYST-MOR-0007363 | AS24: SYST-MOR-0007363_S89_1.fq.gz | AT24: SYST-MOR-0007363_S89_2.fq.gz | AW24: subg. Quercus | AX24: Quercus | AY24: Prinoideae
A25: 1957 | B25: QUE001957 | D25: MB-MG513 | I25: Quercus macrocarpa | J25: 42922 | K25: Mira Garner, Sara Desmond, Bruce Ford | L25: fresh, frozen | M25: HIPP | N25: Canada | O25: Manitoba | R25: Whiteshell Provincial Park | S25: driveway off Block 4 Rd. | T25: granite hill top, graminoid dominated, scattered oaks | Y25: Quercus macrocarpa Michx. | AC25: 49.71209 | AD25: -95.24496 | AE25: 1142 ft | AH25: Characterization of Native Oak Germplasm, Quercus macrocarpa and related white oaks. USDA SCA 58-8020-5-005 | AI25: MOR | AJ25: MOR<USA-IL>: Garner, MB-MG513 | AK25: 184793 | AM25: 0094472MOR | AN25: 4623A47F-5F67-47B3-B1A7-0FE6E8D85359 | AO25: https://swbiodiversity.org/seinet/collections/individual/index.php?occid=32897228 | AP25: PRJNA1200080 | AR25: SYST-MOR-0007364 | AS25: SYST-MOR-0007364_S90_1.fq.gz | AT25: SYST-MOR-0007364_S90_2.fq.gz | AW25: subg. Quercus | AX25: Quercus | AY25: Prinoideae
A26: 1958 | B26: QUE001958 | D26: MB-MG514 | I26: Quercus macrocarpa | J26: 42922 | K26: Mira Garner, Sara Desmond, Bruce Ford | L26: fresh, frozen | M26: HIPP | N26: Canada | O26: Manitoba | R26: Whiteshell Provincial Park | T26: granite hill top, graminoid dominated, scattered oaks | Y26: Quercus macrocarpa Michx. | AC26: 49.71187 | AD26: -95.24472 | AE26: 1129 ft | AH26: Characterization of Native Oak Germplasm, Quercus macrocarpa and related white oaks. USDA SCA 58-8020-5-005 | AI26: MOR | AJ26: MOR<USA-IL>: Garner, MB-MG514 | AK26: 184794 | AM26: 0094761MOR | AN26: 39448A13-F434-4E2E-96EB-B553CF88E750 | AO26: https://swbiodiversity.org/seinet/collections/individual/index.php?occid=32896034 | AP26: PRJNA1200080 | AR26: SYST-MOR-0007365 | AS26: SYST-MOR-0007365_S91_1.fq.gz | AT26: SYST-MOR-0007365_S91_2.fq.gz | AW26: subg. Quercus | AX26: Quercus | AY26: Prinoideae
A27: 1959 | B27: QUE001959 | D27: MB-MG515 | I27: Quercus macrocarpa | J27: 42922 | K27: Mira Garner, Sara Desmond, Bruce Ford | L27: fresh, frozen | M27: HIPP | N27: Canada | O27: Manitoba | R27: Whiteshell Provincial Park | T27: granite hill top, graminoid dominated, scattered oaks | Y27: Quercus macrocarpa Michx.|Q. macrocarpa | Z27: A.L. Hipp and G. Ribicoff | AA27: 45597 | AB27: NA | AC27: 49.71187 | AD27: -95.24456 | AE27: 1139 ft | AH27: Characterization of Native Oak Germplasm, Quercus macrocarpa and related white oaks. USDA SCA 58-8020-5-005 | AI27: MOR | AJ27: MOR<USA-IL>: Garner, MB-MG515 | AK27: 184795 | AM27: 0094762MOR | AN27: EBC5CC3D-A829-48D9-9464-24869C027C16 | AO27: https://swbiodiversity.org/seinet/collections/individual/index.php?occid=32892877 | AP27: PRJNA1200080 | AR27: SYST-MOR-0007366 | AS27: SYST-MOR-0007366_S92_1.fq.gz | AT27: SYST-MOR-0007366_S92_2.fq.gz | AU27: SAMN46848253 | AV27: PRJNA1223965 | AW27: subg. Quercus | AX27: Quercus | AY27: Prinoideae
A28: 1960 | B28: QUE001960 | D28: MB-MG516 | I28: Quercus macrocarpa | J28: 42923 | K28: Mira Garner, Sara Desmond | L28: fresh, frozen | M28: HIPP | N28: Canada | O28: Manitoba | R28: Spruce Woods Provincial Park | T28: Open grassland, scattered oaks | Y28: Quercus macrocarpa Michx.|Q. macrocarpa | Z28: A.L. Hipp and G. Ribicoff | AA28: 45597 | AB28: NA | AC28: 49.76104 | AD28: -99.15971 | AE28: 1239 ft | AH28: Characterization of Native Oak Germplasm, Quercus macrocarpa and related white oaks. USDA SCA 58-8020-5-005 | AI28: MOR | AJ28: MOR<USA-IL>: Garner, MB-MG516 | AK28: 184796 | AM28: 0094763MOR | AN28: D597206D-E7ED-4306-AA7F-A6299DEA4269 | AO28: https://swbiodiversity.org/seinet/collections/individual/index.php?occid=32890562 | AP28: PRJNA1200080 | AR28: SYST-MOR-0007367 | AS28: SYST-MOR-0007367_S93_1.fq.gz | AT28: SYST-MOR-0007367_S93_2.fq.gz | AU28: SAMN46848254 | AV28: PRJNA1223965 | AW28: subg. Quercus | AX28: Quercus | AY28: Prinoideae
A29: 1961 | B29: QUE001961 | D29: MB-MG517 | I29: Quercus macrocarpa | J29: 42923 | K29: Mira Garner, Sara Desmond | L29: fresh, frozen | M29: HIPP | N29: Canada | O29: Manitoba | R29: Spruce Woods Provincial Park | T29: Open grassland, scattered oaks | Y29: Quercus macrocarpa Michx. | AC29: 49.76095 | AD29: -99.15983 | AE29: 1238 ft | AH29: Characterization of Native Oak Germplasm, Quercus macrocarpa and related white oaks. USDA SCA 58-8020-5-005 | AI29: MOR | AJ29: MOR<USA-IL>: Garner, MB-MG517 | AK29: 184797 | AM29: 0094764MOR | AN29: 0694611B-9776-4FAD-A50A-537DC1C74081 | AO29: https://swbiodiversity.org/seinet/collections/individual/index.php?occid=32898061 | AP29: PRJNA1200080 | AR29: SYST-MOR-0007368 | AS29: SYST-MOR-0007368_S94_1.fq.gz | AT29: SYST-MOR-0007368_S94_2.fq.gz | AW29: subg. Quercus | AX29: Quercus | AY29: Prinoideae
A30: 1962 | B30: QUE001962 | D30: MB-MG518 | I30: Quercus macrocarpa | J30: 42923 | K30: Mira Garner, Sara Desmond | L30: fresh, frozen | M30: HIPP | N30: Canada | O30: Manitoba | R30: Spruce Woods Provincial Park | T30: Open grassland, scattered oaks | Y30: Quercus macrocarpa Michx. | AC30: 49.76061 | AD30: -99.15928 | AE30: 1239 ft | AH30: Characterization of Native Oak Germplasm, Quercus macrocarpa and related white oaks. USDA SCA 58-8020-5-005 | AI30: MOR | AJ30: MOR<USA-IL>: Garner, MB-MG518 | AK30: 184798 | AM30: 0094765MOR | AN30: EF972DF2-FF43-4470-AF01-B9A73B373522 | AO30: https://swbiodiversity.org/seinet/collections/individual/index.php?occid=32892262 | AP30: PRJNA1200080 | AR30: SYST-MOR-0007369 | AS30: SYST-MOR-0007369_S95_1.fq.gz | AT30: SYST-MOR-0007369_S95_2.fq.gz | AW30: subg. Quercus | AX30: Quercus | AY30: Prinoideae
A31: 1963 | B31: QUE001963 | D31: MB-MG519 | I31: Quercus macrocarpa | J31: 42923 | K31: Mira Garner, Sara Desmond | L31: fresh, frozen | M31: HIPP | N31: Canada | O31: Manitoba | R31: Spruce Woods Provincial Park | T31: Edge of open grassland and spruce grove. | Y31: Quercus macrocarpa Michx.|Q. macrocarpa | Z31: A.L. Hipp and G. Ribicoff | AA31: 45597 | AB31: NA | AC31: 49.76137 | AD31: -99.1604 | AE31: 1253 ft | AH31: Characterization of Native Oak Germplasm, Quercus macrocarpa and related white oaks. USDA SCA 58-8020-5-005 | AI31: MOR | AJ31: MOR<USA-IL>: Garner, MB-MG519 | AK31: 184799 | AM31: 0094766MOR | AN31: A8C24DBB-7A98-4FE8-9A33-F6B9F090D7E4 | AO31: https://swbiodiversity.org/seinet/collections/individual/index.php?occid=32903572 | AP31: PRJNA1200080 | AR31: SYST-MOR-0007370 | AS31: SYST-MOR-0007370_S96_1.fq.gz | AT31: SYST-MOR-0007370_S96_2.fq.gz | AU31: SAMN46848255 | AV31: PRJNA1223965 | AW31: subg. Quercus | AX31: Quercus | AY31: Prinoideae
A32: 1964 | B32: QUE001964 | D32: MB-MG520 | I32: Quercus macrocarpa | J32: 42923 | K32: Mira Garner, Sara Desmond | L32: fresh, frozen | M32: HIPP | N32: Canada | O32: Manitoba | R32: Spruce Woods Provincial Park | T32: Open grassland, scattered oaks | Y32: Quercus| Quercus macrocarpa Michx | Z32: A.Hipp | AA32: 44873 | AB32: NA | AC32: 49.76117 | AD32: -99.16142 | AE32: 1236 ft | AH32: Characterization of Native Oak Germplasm, Quercus macrocarpa and related white oaks. USDA SCA 58-8020-5-005 | AI32: MOR | AJ32: MOR<USA-IL>: Garner, MB-MG520 | AK32: 184800 | AM32: 0094767MOR | AN32: 8F8C437F-A257-4DE8-9D07-3FDCC28B4590 | AO32: https://swbiodiversity.org/seinet/collections/individual/index.php?occid=32902069 | AP32: PRJNA1200080 | AR32: SYST-MOR-0007371 | AS32: SYST-MOR-0007371_S97_1.fq.gz | AT32: SYST-MOR-0007371_S97_2.fq.gz | AW32: subg. Quercus | AX32: Quercus | AY32: Prinoideae
A33: 1965 | B33: QUE001965 | D33: MB-MG521 | I33: Quercus macrocarpa | J33: 42923 | K33: Mira Garner, Sara Desmond | L33: fresh, frozen | M33: HIPP | N33: Canada | O33: Manitoba | R33: Spruce Woods Provincial Park | T33: Open grassland, scattered oaks | Y33: Quercus macrocarpa Michx. | AC33: 49.76147 | AD33: -99.15886 | AE33: 1250 ft | AH33: Characterization of Native Oak Germplasm, Quercus macrocarpa and related white oaks. USDA SCA 58-8020-5-005 | AI33: MOR | AJ33: MOR<USA-IL>: Garner, MB-MG521 | AK33: 184801 | AM33: 0094768MOR | AN33: 7A97C2AA-3775-49A5-9383-645FC2AF301A | AO33: https://swbiodiversity.org/seinet/collections/individual/index.php?occid=32901617 | AP33: PRJNA1200080 | AR33: SYST-MOR-0007372 | AS33: SYST-MOR-0007372_S98_1.fq.gz | AT33: SYST-MOR-0007372_S98_2.fq.gz | AW33: subg. Quercus | AX33: Quercus | AY33: Prinoideae
A34: 1966 | B34: QUE001966 | D34: MB-MG522 | I34: Quercus macrocarpa | J34: 42923 | K34: Mira Garner, Sara Desmond | L34: fresh, frozen | M34: HIPP | N34: Canada | O34: Manitoba | R34: Spruce Woods Provincial Park | T34: Open grassland, scattered oaks | Y34: Quercus macrocarpa Michx. | AC34: 49.76103 | AD34: -99.15848 | AE34: 1252 ft | AH34: Characterization of Native Oak Germplasm, Quercus macrocarpa and related white oaks. USDA SCA 58-8020-5-005 | AI34: MOR | AJ34: MOR<USA-IL>: Garner, MB-MG522 | AK34: 184802 | AM34: 0094769MOR | AN34: 29EBF677-1B29-47E1-9F2F-5A33024FF652 | AO34: https://swbiodiversity.org/seinet/collections/individual/index.php?occid=32895016 | AP34: PRJNA1200080 | AR34: SYST-MOR-0007373 | AS34: SYST-MOR-0007373_S99_1.fq.gz | AT34: SYST-MOR-0007373_S99_2.fq.gz | AW34: subg. Quercus | AX34: Quercus | AY34: Prinoideae
A35: 1967 | B35: QUE001967 | D35: MB-MG523 | I35: Quercus macrocarpa | J35: 42923 | K35: Mira Garner, Sara Desmond | L35: fresh, frozen | M35: HIPP | N35: Canada | O35: Manitoba | R35: Spruce Woods Provincial Park | T35: Oak grove in open grassland | Y35: Quercus macrocarpa Michx. | AC35: 49.76043 | AD35: -99.15858 | AE35: 1250 ft | AH35: Characterization of Native Oak Germplasm, Quercus macrocarpa and related white oaks. USDA SCA 58-8020-5-005 | AI35: MOR | AJ35: MOR<USA-IL>: Garner, MB-MG523 | AK35: 184803 | AM35: 0094770MOR | AN35: 4F9E0BBB-2600-4B9F-B296-CEF11575CD98 | AO35: https://swbiodiversity.org/seinet/collections/individual/index.php?occid=32898269 | AP35: PRJNA1200080 | AR35: SYST-MOR-0007374 | AS35: SYST-MOR-0007374_S100_1.fq.gz | AT35: SYST-MOR-0007374_S100_2.fq.gz | AW35: subg. Quercus | AX35: Quercus | AY35: Prinoideae
A36: 1968 | B36: QUE001968 | D36: MB-MG524 | I36: Quercus macrocarpa | J36: 42923 | K36: Mira Garner, Sara Desmond | L36: fresh, frozen | M36: HIPP | N36: Canada | O36: Manitoba | R36: Spruce Woods Provincial Park | T36: Open grassland, scattered oaks | Y36: Quercus macrocarpa Michx. | AC36: 49.76006 | AD36: -99.15826 | AE36: 1256 ft | AH36: Characterization of Native Oak Germplasm, Quercus macrocarpa and related white oaks. USDA SCA 58-8020-5-005 | AI36: MOR | AJ36: MOR<USA-IL>: Garner, MB-MG524 | AK36: 184810 | AM36: 0094777MOR | AN36: DEC1A0E9-8863-4338-B755-2D6979E46CB3 | AO36: https://swbiodiversity.org/seinet/collections/individual/index.php?occid=32891958 | AP36: PRJNA1200080 | AR36: SYST-MOR-0007375 | AS36: SYST-MOR-0007375_S101_1.fq.gz | AT36: SYST-MOR-0007375_S101_2.fq.gz | AW36: subg. Quercus | AX36: Quercus | AY36: Prinoideae
A37: 1969 | B37: QUE001969 | D37: MB-MG525 | I37: Quercus macrocarpa | J37: 42923 | K37: Mira Garner, Sara Desmond | L37: fresh, frozen | M37: HIPP | N37: Canada | O37: Manitoba | R37: Spruce Woods Provincial Park | T37: Open grassland, scattered oaks | Y37: Quercus macrocarpa Michx.|Q. macrocarpa | Z37: A.L. Hipp and G. Ribicoff | AA37: 45597 | AB37: NA | AC37: 49.76055 | AD37: -99.15844 | AE37: 1285 ft | AH37: Characterization of Native Oak Germplasm, Quercus macrocarpa and related white oaks. USDA SCA 58-8020-5-005 | AI37: MOR | AJ37: MOR<USA-IL>: Garner, MB-MG525 | AK37: 184811 | AM37: 0094778MOR | AN37: EE1255ED-764C-4AE9-BD7C-D57DD035C3A5 | AO37: https://swbiodiversity.org/seinet/collections/individual/index.php?occid=32891804 | AP37: PRJNA1200080 | AR37: SYST-MOR-0007376 | AS37: SYST-MOR-0007376_S102_1.fq.gz | AT37: SYST-MOR-0007376_S102_2.fq.gz | AU37: SAMN46848256 | AV37: PRJNA1223965 | AW37: subg. Quercus | AX37: Quercus | AY37: Prinoideae
A38: 1970 | B38: QUE001970 | D38: MB-MG526 | I38: Quercus macrocarpa | J38: 42923 | K38: Mira Garner, Sara Desmond | L38: fresh, frozen | M38: HIPP | N38: Canada | O38: Manitoba | R38: Assiniboine Forest | S38: near parking lot/entrance to trail | T38: Aspen and Oak woods | Y38: Quercus macrocarpa Michx. | AE38: 1255 | AG38: gps collected: 49.76058, -99.15864, 1255 ft. These coordinates match better previous site. | AH38: Characterization of Native Oak Germplasm, Quercus macrocarpa and related white oaks. USDA SCA 58-8020-5-005 | AI38: MOR | AJ38: MOR<USA-IL>: Garner, MB-MG526 | AK38: 184812 | AM38: 0094779MOR | AN38: D3637413-DDA4-4ABF-A5C1-D7DB04375320 | AO38: https://swbiodiversity.org/seinet/collections/individual/index.php?occid=32891249 | AP38: PRJNA1200080 | AR38: SYST-MOR-0007377 | AS38: SYST-MOR-0007377_S103_1.fq.gz | AT38: SYST-MOR-0007377_S103_2.fq.gz | AW38: subg. Quercus | AX38: Quercus | AY38: Prinoideae
A39: 1971 | B39: QUE001971 | D39: MB-MG527 | I39: Quercus macrocarpa | J39: 42923 | K39: Mira Garner, Sara Desmond | L39: fresh, frozen | M39: HIPP | N39: Canada | O39: Manitoba | R39: Assiniboine Forest | S39: near trail | T39: Aspen and Oak woods | Y39: Quercus macrocarpa Michx.|Q. macrocarpa | Z39: A.L. Hipp and G. Ribicoff | AA39: 45597 | AB39: NA | AC39: 49.85783 | AD39: -97.24911 | AE39: 788 ft | AH39: Characterization of Native Oak Germplasm, Quercus macrocarpa and related white oaks. USDA SCA 58-8020-5-005 | AI39: MOR | AJ39: MOR<USA-IL>: Garner, MB-MG527 | AK39: 184813 | AM39: 0094780MOR | AN39: 6379DAFC-32C9-4ABB-8656-294E336DFDC6 | AO39: https://swbiodiversity.org/seinet/collections/individual/index.php?occid=32899497 | AP39: PRJNA1200080 | AR39: SYST-MOR-0007378 | AS39: SYST-MOR-0007378_S104_1.fq.gz | AT39: SYST-MOR-0007378_S104_2.fq.gz | AU39: SAMN46848257 | AV39: PRJNA1223965 | AW39: subg. Quercus | AX39: Quercus | AY39: Prinoideae
A40: 1972 | B40: QUE001972 | D40: MB-MG528 | I40: Quercus macrocarpa | J40: 42923 | K40: Mira Garner, Sara Desmond | L40: fresh, frozen | M40: HIPP | N40: Canada | O40: Manitoba | R40: Assiniboine Forest | S40: off trail in woody area | T40: woody area | Y40: Quercus macrocarpa Michx. | AC40: 49.85778 | AD40: -97.24848 | AE40: 777 ft | AH40: Characterization of Native Oak Germplasm, Quercus macrocarpa and related white oaks. USDA SCA 58-8020-5-005 | AI40: MOR | AJ40: MOR<USA-IL>: Garner, MB-MG528 | AK40: 184814 | AM40: 0094781MOR | AN40: EAF80350-69EE-4CC4-A083-55894790ED29 | AO40: https://swbiodiversity.org/seinet/collections/individual/index.php?occid=32892535 | AP40: PRJNA1200080 | AR40: SYST-MOR-0007379 | AS40: SYST-MOR-0007379_S105_1.fq.gz | AT40: SYST-MOR-0007379_S105_2.fq.gz | AW40: subg. Quercus | AX40: Quercus | AY40: Prinoideae
...

Sheet Sheet2
A1: INDEX | B1: SPMCODE | C1: ALTERNATE.PROJECTCODE | D1: Collector_no | E1: Alt_Coll_No | F1: Rebekahs Determination | G1: Rebekah notes | H1: Source | I1: Hybrid Parentage | J1: Other_notes | K1: FullAdmixture_notes | L1: taxonomic_notes | M1: TAXA-Current_determination | N1: Collection_date | O1: Collectors | P1: Type_of_material | Q1: OWNER | R1: Country | S1: State_Province_Region_territory | T1: substate | U1: substateRank | V1: site | W1: Locality Notes | X1: habitat | Y1: associates | Z1: DBH-cm | AA1: Height-m | AB1: plantAttributesOther | AC1: Determination_HIST_PIPED | AD1: Determined_by | AE1: Determined_date | AF1: determination_reasoning_notes | AG1: latitude.orig | AH1: longitude.orig | AI1: Elevation | AJ1: photos | AK1: Collecting_Extracting_notes | AL1: Project | AM1: DNA | AN1: SpecimenVoucher | AO1: MOR_Acc_Num | AP1: Voucher_Notes | AQ1: MOR_BARCODE | AR1: occurrenceID | AS1: SEINet_references | AT1: WholeGenome_BioProject | AU1: WholeGenome_SRA_Run | AV1: WholeGenome_libraryID | AW1: WholeGenomeFastqR1 | AX1: WholeGenomeFastqR2 | AY1: SRA_biosample_accession | AZ1: HYB-SEQ_BioProject | BA1: Lookup-SUBGENUS-by-CurrentTAXA | BB1: LOOKUP-section-by-currentTAXA | BC1: Lookup-CLADE0by-CurrentTAXA
A2: 3892 | B2: QUE003892 | C2: AR_BRP_409_MG | D2: AR_BRP_409_MG | K2: =IFERROR(VLOOKUP(D2,Sheet4!A$1:M$56,11,FALSE),"") | L2: =_xlfn.CONCAT(J2,K2) | M2: Quercus lyrata | N2: 44803 | O2: Leah Samuels, Mira Garner | P2: fresh, frozen | Q2: HIPP | R2: USA | S2: Arkansas | T2: Pulaski | U2: County | V2: Burns Park | W2: Little Rock | X2: Near creek, dense forest with little foliage | Y2: Ulmus sp., Bluejack oak, Carya ovata, Celtis sp., Round leaf ragwort, honeysuckle, Carex sp., | AB2: Seeds ripening | AC2: Quercus lyrata Walt. | AG2: 34.804528 | AH2: -92.326498 | AI2: 283 ft | AL2: Dimensions of Biodiversity: US/China Collaborative Research: Consequences of diversity in Asian and American tree sygameons for functional variation, adaptation and symbiont biodiversity (#2129281) | AM2: MOR | AN2: MOR<USA-IL>: Samuels, AR_BRP_409_MG | AO2: 194234 | AQ2: 0111235MOR | AR2: 22351E95-A791-459A-A7DF-B4C2767DB9C6 | AS2: https://swbiodiversity.org/seinet/collections/individual/index.php?occid=34693220 | AT2: PRJNA1200080 | AV2: SYST-MOR-0007129 | AW2: SYST-MOR-0007129_S182_1.fq.gz | AX2: SYST-MOR-0007129_S182_2.fq.gz | BA2: subg. Quercus | BB2: Quercus | BC2: Prinoideae
A3: 3893 | B3: QUE003893 | C3: AR_BRP_410_MG | D3: AR_BRP_410_MG | K3: =IFERROR(VLOOKUP(D3,Sheet4!A$1:M$56,11,FALSE),"") | L3: =_xlfn.CONCAT(J3,K3) | M3: Quercus macrocarpa | N3: 44803 | O3: Leah Samuels, Mira Garner | P3: fresh, frozen | Q3: HIPP | R3: USA | S3: Arkansas | T3: Pulaski | U3: County | V3: Burns Park | W3: Little Rock | X3: Creek side forest with sparse foliage | Y3: Carya sp., Ulmus sp., Fraxinus sp., Carex sp., poison ivy, cross vine, supplejack | AB3: Male flowers showing | AC3: Quercus macrocarpa Michx. | AG3: 34.804342 | AH3: -92.326645 | AI3: 284 ft | AL3: Dimensions of Biodiversity: US/China Collaborative Research: Consequences of diversity in Asian and American tree sygameons for functional variation, adaptation and symbiont biodiversity (#2129281) | AM3: MOR | AN3: MOR<USA-IL>: Samuels, AR_BRP_410_MG | AO3: 194576 | AQ3: 0111328MOR | AR3: 68A652B8-18C1-47DA-980A-55043FCA0666 | AS3: https://swbiodiversity.org/seinet/collections/individual/index.php?occid=34693474 | AT3: PRJNA1200080 | AV3: SYST-MOR-0007130 | AW3: SYST-MOR-0007130_S183_1.fq.gz | AX3: SYST-MOR-0007130_S183_2.fq.gz | BA3: subg. Quercus | BB3: Quercus | BC3: Prinoideae
A4: 3894 | B4: QUE003894 | C4: AR_BRP_411_MG | D4: AR_BRP_411_MG | K4: =IFERROR(VLOOKUP(D4,Sheet4!A$1:M$56,11,FALSE),"") | L4: =_xlfn.CONCAT(J4,K4) | M4: Quercus stellata | N4: 44803 | O4: Leah Samuels, Mira Garner | P4: fresh, frozen | Q4: HIPP | R4: USA | S4: Arkansas | T4: Pulaski | U4: County | V4: Burns Park | W4: Little Rock | X4: Lawn near creek | Y4: Ulmus sp., Pinus sp., Poaceae | AB4: Seeds ripening | AC4: Quercus stellata Wangenh. | AG4: 34.804413 | AH4: -92.326312 | AI4: 280 ft | AL4: Dimensions of Biodiversity: US/China Collaborative Research: Consequences of diversity in Asian and American tree sygameons for functional variation, adaptation and symbiont biodiversity (#2129281) | AM4: MOR | AN4: MOR<USA-IL>: Samuels, AR_BRP_411_MG | AO4: 193548 | AQ4: 0111450MOR | AR4: 51AB6567-EB8A-4697-90A6-FC4E1DB6B150 | AS4: https://swbiodiversity.org/seinet/collections/individual/index.php?occid=34693375 | AT4: PRJNA1200080 | AV4: SYST-MOR-0007131 | AW4: SYST-MOR-0007131_S184_1.fq.gz | AX4: SYST-MOR-0007131_S184_2.fq.gz | BA4: subg. Quercus | BB4: Quercus | BC4: Stellatae
A5: 3895 | B5: QUE003895 | C5: AR_BRP_412_MG | D5: AR_BRP_412_MG | K5: =IFERROR(VLOOKUP(D5,Sheet4!A$1:M$56,11,FALSE),"") | L5: =_xlfn.CONCAT(J5,K5) | M5: Quercus macrocarpa | N5: 44803 | O5: Leah Samuels, Mira Garner | P5: fresh, frozen | Q5: HIPP | R5: USA | S5: Arkansas | T5: Pulaski | U5: County | V5: Burns Park | W5: Little Rock | X5: Marshy forest with sparse foliage | Y5: Carya ovata, Ulmus sp., Fraxinus sp., Quercus macrocarpa, Carex sp. | AC5: Quercus macrocarpa Michx. | AG5: 34.805006 | AH5: -92.327103 | AI5: 290 ft | AL5: Dimensions of Biodiversity: US/China Collaborative Research: Consequences of diversity in Asian and American tree sygameons for functional variation, adaptation and symbiont biodiversity (#2129281) | AM5: MOR | AN5: MOR<USA-IL>: Samuels, AR_BRP_412_MG | AO5: 194575 | AQ5: 0111324MOR | AR5: 2E2FA26A-FABE-45F9-83AC-3580A70BD36F | AS5: https://swbiodiversity.org/seinet/collections/individual/index.php?occid=34693298 | AT5: PRJNA1200080 | AV5: SYST-MOR-0007132 | AW5: SYST-MOR-0007132_S185_1.fq.gz | AX5: SYST-MOR-0007132_S185_2.fq.gz | BA5: subg. Quercus | BB5: Quercus | BC5: Prinoideae
A6: 3896 | B6: QUE003896 | C6: AR_BRP_413_MG | D6: AR_BRP_413_MG | K6: =IFERROR(VLOOKUP(D6,Sheet4!A$1:M$56,11,FALSE),"") | L6: =_xlfn.CONCAT(J6,K6) | M6: Quercus stellata | N6: 44803 | O6: Leah Samuels, Mira Garner | P6: fresh, frozen | Q6: HIPP | R6: USA | S6: Arkansas | T6: Pulaski | U6: County | V6: Burns Park | W6: Little Rock | X6: Marshy forest, low foliage, dense forest | Y6: Carya sp., bluejack oak, post oak, Carex sp., Poison ivy, American jump seed, Leafy elephants foot | AC6: Quercus stellata Wangenh. | AG6: 34.805382 | AH6: -92.327057 | AI6: 294 ft | AL6: Dimensions of Biodiversity: US/China Collaborative Research: Consequences of diversity in Asian and American tree sygameons for functional variation, adaptation and symbiont biodiversity (#2129281) | AM6: MOR | AN6: MOR<USA-IL>: Samuels, AR_BRP_413_MG | AO6: 193549 | AQ6: 0111451MOR | AR6: AA48B6CC-2B13-4925-B59F-EB07F227FE02 | AS6: https://swbiodiversity.org/seinet/collections/individual/index.php?occid=34693636 | AT6: PRJNA1200080 | AV6: SYST-MOR-0007133 | AW6: SYST-MOR-0007133_S186_1.fq.gz | AX6: SYST-MOR-0007133_S186_2.fq.gz | BA6: subg. Quercus | BB6: Quercus | BC6: Stellatae
A7: 3897 | B7: QUE003897 | C7: AR_BRP_414_MG | D7: AR_BRP_414_MG | K7: =IFERROR(VLOOKUP(D7,Sheet4!A$1:M$56,11,FALSE),"") | L7: =_xlfn.CONCAT(J7,K7) | M7: Quercus lyrata | N7: 44803 | O7: Leah Samuels, Mira Garner | P7: fresh, frozen | Q7: HIPP | R7: USA | S7: Arkansas | T7: Pulaski | U7: County | V7: Burns Park | W7: Little Rock | X7: Marshy forest with little foliage | Y7: Carya sp., Quercus rubra, Ulmus sp., Fraxinus sp., Quercus lyrata, Carex sp., Virginia creeper, Bluejack oak | AC7: Quercus lyrata Walt. | AG7: 34.805731 | AH7: -92.327413 | AI7: 344 ft | AL7: Dimensions of Biodiversity: US/China Collaborative Research: Consequences of diversity in Asian and American tree sygameons for functional variation, adaptation and symbiont biodiversity (#2129281) | AM7: MOR | AN7: MOR<USA-IL>: Samuels, AR_BRP_414_MG | AO7: 194235 | AQ7: 0111234MOR | AR7: 70F2D442-A98C-4EAF-9EC3-029D428B602E | AS7: https://swbiodiversity.org/seinet/collections/individual/index.php?occid=34693434 | AT7: PRJNA1200080 | AV7: SYST-MOR-0007134 | AW7: SYST-MOR-0007134_S187_1.fq.gz | AX7: SYST-MOR-0007134_S187_2.fq.gz | BA7: subg. Quercus | BB7: Quercus | BC7: Prinoideae
A8: 3898 | B8: QUE003898 | C8: AR_BRP_415_MG | D8: AR_BRP_415_MG | K8: =IFERROR(VLOOKUP(D8,Sheet4!A$1:M$56,11,FALSE),"") | L8: =_xlfn.CONCAT(J8,K8) | M8: Quercus alba | N8: 44803 | O8: Leah Samuels, Mira Garner | P8: fresh, frozen | Q8: HIPP | R8: USA | S8: Arkansas | T8: Pulaski | U8: County | V8: Burns Park | W8: Little Rock | X8: Marshy forest (formerly marshy?) with very little ground cover | Y8: Ulmus sp., Basswood, Carya sp., Virginia creeper, Carex sp., Bluejack oak, American jump seed | AC8: Quercus alba L. | AG8: 34.80591 | AH8: -92.327568 | AI8: 304 ft | AL8: Dimensions of Biodiversity: US/China Collaborative Research: Consequences of diversity in Asian and American tree sygameons for functional variation, adaptation and symbiont biodiversity (#2129281) | AM8: MOR | AN8: MOR<USA-IL>: Samuels, AR_BRP_415_MG | AO8: 194165 | AQ8: 0110979MOR | AR8: E6B3A95B-F00D-4949-A1CD-7674436389D5 | AS8: https://swbiodiversity.org/seinet/collections/individual/index.php?occid=34693782 | AT8: PRJNA1200080 | AV8: SYST-MOR-0007135 | AW8: SYST-MOR-0007135_S188_1.fq.gz | AX8: SYST-MOR-0007135_S188_2.fq.gz | BA8: subg. Quercus | BB8: Quercus | BC8: Albae
A9: 3899 | B9: QUE003899 | C9: AR_BRP_416_MG | D9: AR_BRP_416_MG | K9: =IFERROR(VLOOKUP(D9,Sheet4!A$1:M$56,11,FALSE),"") | L9: =_xlfn.CONCAT(J9,K9) | M9: Quercus stellata | N9: 44803 | O9: Leah Samuels, Mira Garner | P9: fresh, frozen | Q9: HIPP | R9: USA | S9: Arkansas | T9: Pulaski | U9: County | V9: Burns Park | W9: Little Rock | X9: Forest with no/little underbrush | Y9: Fraxinus sp., Carya sp., Quercus stellata, Carex sp., Anglepod | AC9: Quercus stellata Wangenh. | AG9: 34.806737 | AH9: -92.328943 | AI9: 297 ft | AL9: Dimensions of Biodiversity: US/China Collaborative Research: Consequences of diversity in Asian and American tree sygameons for functional variation, adaptation and symbiont biodiversity (#2129281) | AM9: MOR | AN9: MOR<USA-IL>: Samuels, AR_BRP_416_MG | AO9: 193550 | AQ9: 0111452MOR | AR9: 506FEDE5-4F1B-4B45-B0FD-591C3B4E89AD | AS9: https://swbiodiversity.org/seinet/collections/individual/index.php?occid=34693341 | AT9: PRJNA1200080 | AV9: SYST-MOR-0007136 | AW9: SYST-MOR-0007136_S189_1.fq.gz | AX9: SYST-MOR-0007136_S189_2.fq.gz | BA9: subg. Quercus | BB9: Quercus | BC9: Stellatae
A10: 3900 | B10: QUE003900 | C10: AR_BRP_417_MG | D10: AR_BRP_417_MG | K10: =IFERROR(VLOOKUP(D10,Sheet4!A$1:M$56,11,FALSE),"") -> Based on ADMIXTURE results of 78,187 SNPs, may be trace admixed with Quercus bicolor | L10: =_xlfn.CONCAT(J10,K10) -> Based on ADMIXTURE results of 78,187 SNPs, may be trace admixed with Quercus bicolor | M10: Quercus macrocarpa | N10: 44803 | O10: Leah Samuels, Mira Garner | P10: fresh, frozen | Q10: HIPP | R10: USA | S10: Arkansas | T10: Pulaski | U10: County | V10: Burns Park | W10: Little Rock | X10: High density forest with little underbrush | Y10: Carya sp., red oak, bluejack oak, Carex sp., River cane, Maple leaf viburnum, Poison ivy | AC10: Quercus macrocarpa Michx. | AG10: 34.806243 | AH10: -92.33009 | AI10: 289 ft | AL10: Dimensions of Biodiversity: US/China Collaborative Research: Consequences of diversity in Asian and American tree sygameons for functional variation, adaptation and symbiont biodiversity (#2129281) | AM10: MOR | AN10: MOR<USA-IL>: Samuels, AR_BRP_417_MG | AO10: 194574 | AQ10: 0111325MOR | AR10: FA01ECD2-EC71-4492-9BEE-88595D1F0B20 | AS10: https://swbiodiversity.org/seinet/collections/individual/index.php?occid=34693742 | AT10: PRJNA1200080 | AV10: SYST-MOR-0007137 | AW10: SYST-MOR-0007137_S190_1.fq.gz | AX10: SYST-MOR-0007137_S190_2.fq.gz | BA10: subg. Quercus | BB10: Quercus | BC10: Prinoideae
A11: 3901 | B11: QUE003901 | C11: AR_BRP_418_MG | D11: AR_BRP_418_MG | K11: =IFERROR(VLOOKUP(D11,Sheet4!A$1:M$56,11,FALSE),"") | L11: =_xlfn.CONCAT(J11,K11) | M11: Quercus lyrata | N11: 44803 | O11: Leah Samuels, Mira Garner | P11: fresh, frozen | Q11: HIPP | R11: USA | S11: Arkansas | T11: Pulaski | U11: County | V11: Burns Park | W11: Little Rock | X11: Forest with low underbrush on edge of grasslands/pasture | Y11: Carya sp., Fraxinus sp., cedar elm, post oak, Possumhaw | AB11: Male flowers showing | AC11: Quercus lyrata Walt. | AG11: 34.806528 | AH11: -92.330323 | AI11: 284 ft | AL11: Dimensions of Biodiversity: US/China Collaborative Research: Consequences of diversity in Asian and American tree sygameons for functional variation, adaptation and symbiont biodiversity (#2129281) | AM11: MOR | AN11: MOR<USA-IL>: Samuels, AR_BRP_418_MG | AO11: 194236 | AQ11: 0111233MOR | AR11: E94AF73D-8B2F-4040-B82A-417BA1DEF59B | AS11: https://swbiodiversity.org/seinet/collections/individual/index.php?occid=34693729 | AT11: PRJNA1200080 | AV11: SYST-MOR-0007138 | AW11: SYST-MOR-0007138_S191_1.fq.gz | AX11: SYST-MOR-0007138_S191_2.fq.gz | BA11: subg. Quercus | BB11: Quercus | BC11: Prinoideae
A12: 3902 | B12: QUE003902 | C12: AR_BRP_419_MG | D12: AR_BRP_419_MG | K12: =IFERROR(VLOOKUP(D12,Sheet4!A$1:M$56,11,FALSE),"") | L12: =_xlfn.CONCAT(J12,K12) | M12: Quercus stellata | N12: 44803 | O12: Leah Samuels, Mira Garner | P12: fresh, frozen | Q12: HIPP | R12: USA | S12: Arkansas | T12: Pulaski | U12: County | V12: Burns Park | W12: Little Rock | X12: Forest on edge of grasslands/pasture Low/little underbrush | Y12: Carya sp., Fraxinus sp., cedar elm, Quercus lyrata, Celtis sp., Possumhaw | AC12: Quercus stellata Wangenh. | AG12: 34.806536 | AH12: -92.330338 | AI12: 302 ft | AL12: Dimensions of Biodiversity: US/China Collaborative Research: Consequences of diversity in Asian and American tree sygameons for functional variation, adaptation and symbiont biodiversity (#2129281) | AM12: MOR | AN12: MOR<USA-IL>: Samuels, AR_BRP_419_MG | AO12: 193551 | AQ12: 0111453MOR | AR12: 0CEA1600-167B-4642-A243-B4371EFB6971 | AS12: https://swbiodiversity.org/seinet/collections/individual/index.php?occid=34693174 | AT12: PRJNA1200080 | AV12: SYST-MOR-0007139 | AW12: SYST-MOR-0007139_S192_1.fq.gz | AX12: SYST-MOR-0007139_S192_2.fq.gz | BA12: subg. Quercus | BB12: Quercus | BC12: Stellatae
A13: 3903 | B13: QUE003903 | C13: AR_BRP_420_MG | D13: AR_BRP_420_MG | K13: =IFERROR(VLOOKUP(D13,Sheet4!A$1:M$56,11,FALSE),"") | L13: =_xlfn.CONCAT(J13,K13) | M13: Quercus alba | N13: 44803 | O13: Leah Samuels, Mira Garner | P13: fresh, frozen | Q13: HIPP | R13: USA | S13: Arkansas | T13: Pulaski | U13: County | V13: Burns Park | W13: Little Rock | X13: Small hilltop in forest, more underbrush than surrounding areas | Y13: Red oak, Fraxinus sp., Quercus alba, Carya sp., River cane, American jump seed, Hackberry, Smilax sp. | AC13: Quercus alba L. | AG13: 34.803473 | AH13: -92.329471 | AI13: 308 ft | AL13: Dimensions of Biodiversity: US/China Collaborative Research: Consequences of diversity in Asian and American tree sygameons for functional variation, adaptation and symbiont biodiversity (#2129281) | AM13: MOR | AN13: MOR<USA-IL>: Samuels, AR_BRP_420_MG | AO13: 194166 | AQ13: 0110980MOR | AR13: A26842E6-8E75-4581-A013-4A5546E207CB | AS13: https://swbiodiversity.org/seinet/collections/individual/index.php?occid=34693612 | AT13: PRJNA1200080 | AV13: SYST-MOR-0007140 | AW13: SYST-MOR-0007140_S193_1.fq.gz | AX13: SYST-MOR-0007140_S193_2.fq.gz | BA13: subg. Quercus | BB13: Quercus | BC13: Albae
A14: 3904 | B14: QUE003904 | C14: AR_BRP_421_MG | D14: AR_BRP_421_MG | K14: =IFERROR(VLOOKUP(D14,Sheet4!A$1:M$56,11,FALSE),"") | L14: =_xlfn.CONCAT(J14,K14) | M14: Quercus muehlenbergii | N14: 44803 | O14: Leah Samuels, Mira Garner | P14: fresh, frozen | Q14: HIPP | R14: USA | S14: Arkansas | T14: Pulaski | U14: County | V14: Burns Park | W14: Little Rock | X14: Forest with little underbrush | Y14: Carya sp., red oak group, Quercus muehlenbergii, River cane | AC14: Quercus muehlenbergii Engelm. | AG14: 34.801995 | AH14: -92.328255 | AI14: 301 ft | AL14: Dimensions of Biodiversity: US/China Collaborative Research: Consequences of diversity in Asian and American tree sygameons for functional variation, adaptation and symbiont biodiversity (#2129281) | AM14: MOR | AN14: MOR<USA-IL>: Samuels, AR_BRP_421_MG | AO14: 194498 | AQ14: 0111134MOR | AR14: 0D136631-0255-4884-9282-0FB40EC75B08 | AS14: https://swbiodiversity.org/seinet/collections/individual/index.php?occid=34693180 | AT14: PRJNA1200080 | AV14: SYST-MOR-0007141 | AW14: SYST-MOR-0007141_S194_1.fq.gz | AX14: SYST-MOR-0007141_S194_2.fq.gz | BA14: subg. Quercus | BB14: Quercus | BC14: Prinoideae
A15: 3905 | B15: QUE003905 | C15: AR_BRP_422_MG | D15: AR_BRP_422_MG | K15: =IFERROR(VLOOKUP(D15,Sheet4!A$1:M$56,11,FALSE),"") | L15: =_xlfn.CONCAT(J15,K15) | M15: Quercus muehlenbergii | N15: 44803 | O15: Leah Samuels, Mira Garner | P15: fresh, frozen | Q15: HIPP | R15: USA | S15: Arkansas | T15: Pulaski | U15: County | V15: Burns Park | W15: Little Rock | X15: Forest with dead leaves as ground cover, very little underbrush | Y15: Fraxinus sp., Quercus muehlenbergii, Carya sp., red oak group, Vitus sp., Ulmus sp. | AC15: Quercus muehlenbergii Engelm. | AG15: 34.801789 | AH15: -92.328063 | AI15: 300 ft | AL15: Dimensions of Biodiversity: US/China Collaborative Research: Consequences of diversity in Asian and American tree sygameons for functional variation, adaptation and symbiont biodiversity (#2129281) | AM15: MOR | AN15: MOR<USA-IL>: Samuels, AR_BRP_422_MG | AO15: 194499 | AQ15: 0111135MOR | AR15: FB2DFECB-BC2E-48C0-9A14-290DA019D534 | AS15: https://swbiodiversity.org/seinet/collections/individual/index.php?occid=34693778 | AT15: PRJNA1200080 | AV15: SYST-MOR-0007142 | AW15: SYST-MOR-0007142_S195_1.fq.gz | AX15: SYST-MOR-0007142_S195_2.fq.gz | BA15: subg. Quercus | BB15: Quercus | BC15: Prinoideae
A16: 3906 | B16: QUE003906 | C16: AR_BRP_423_MG | D16: AR_BRP_423_MG | K16: =IFERROR(VLOOKUP(D16,Sheet4!A$1:M$56,11,FALSE),"") | L16: =_xlfn.CONCAT(J16,K16) | M16: Quercus macrocarpa | N16: 44803 | O16: Leah Samuels, Mira Garner | P16: fresh, frozen | Q16: HIPP | R16: USA | S16: Arkansas | T16: Pulaski | U16: County | V16: Burns Park | W16: Little Rock | X16: Forest with tall sparse grasses | Y16: Carya ovata, Quercus macrocarpa, black cherry, Poison ivy, River cane, Carex sp., Bignonia sp. | AC16: Quercus macrocarpa Michx. | AG16: 34.802582 | AH16: -92.327239 | AI16: 297 ft | AL16: Dimensions of Biodiversity: US/China Collaborative Research: Consequences of diversity in Asian and American tree sygameons for functional variation, adaptation and symbiont biodiversity (#2129281) | AM16: MOR | AN16: MOR<USA-IL>: Samuels, AR_BRP_423_MG | AO16: 194573 | AQ16: 0111327MOR | AR16: B0508080-F829-4A5A-99B7-6C58647ED1A7 | AS16: https://swbiodiversity.org/seinet/collections/individual/index.php?occid=34693623 | AT16: PRJNA1200080 | AV16: SYST-MOR-0007143 | AW16: SYST-MOR-0007143_S196_1.fq.gz | AX16: SYST-MOR-0007143_S196_2.fq.gz | BA16: subg. Quercus | BB16: Quercus | BC16: Prinoideae
A17: 3907 | B17: QUE003907 | C17: AR_BRP_424_MG | D17: AR_BRP_424_MG | K17: =IFERROR(VLOOKUP(D17,Sheet4!A$1:M$56,11,FALSE),"") | L17: =_xlfn.CONCAT(J17,K17) | M17: Quercus alba | N17: 44803 | O17: Leah Samuels, Mira Garner | P17: fresh, frozen | Q17: HIPP | R17: USA | S17: Arkansas | T17: Pulaski | U17: County | V17: Burns Park | W17: Little Rock | X17: Forest with low sedge underbrush | Y17: Carya sp., Ulmus sp., Carex sp., Hackberry | AC17: Quercus alba L. | AG17: 34.803696 | AH17: -92.327312 | AI17: 289 ft | AL17: Dimensions of Biodiversity: US/China Collaborative Research: Consequences of diversity in Asian and American tree sygameons for functional variation, adaptation and symbiont biodiversity (#2129281) | AM17: MOR | AN17: MOR<USA-IL>: Samuels, AR_BRP_424_MG | AO17: 194167 | AQ17: 0110981MOR | AR17: 9794DC4E-0657-4A74-A84E-C0800CBCEC5F | AS17: https://swbiodiversity.org/seinet/collections/individual/index.php?occid=34693530 | AT17: PRJNA1200080 | AV17: SYST-MOR-0007144 | AW17: SYST-MOR-0007144_S197_1.fq.gz | AX17: SYST-MOR-0007144_S197_2.fq.gz | BA17: subg. Quercus | BB17: Quercus | BC17: Albae
A18: 3908 | B18: QUE003908 | C18: AR_BRP_425_MG | D18: AR_BRP_425_MG | K18: =IFERROR(VLOOKUP(D18,Sheet4!A$1:M$56,11,FALSE),"") | L18: =_xlfn.CONCAT(J18,K18) | M18: Quercus stellata | N18: 44803 | O18: Leah Samuels, Mira Garner | P18: fresh, frozen | Q18: HIPP | R18: USA | S18: Arkansas | T18: Pulaski | U18: County | V18: Burns Park | W18: Little Rock | X18: Forest with sedge ground cover | Y18: Carya sp., Celtis sp., Pinus sp., bluejack oak, Carex sp., Smilax sp. | AC18: Quercus stellata Wangenh. | AG18: 34.805414 | AH18: -92.324096 | AI18: 284 ft | AL18: Dimensions of Biodiversity: US/China Collaborative Research: Consequences of diversity in Asian and American tree sygameons for functional variation, adaptation and symbiont biodiversity (#2129281) | AM18: MOR | AN18: MOR<USA-IL>: Samuels, AR_BRP_425_MG | AO18: 193552 | AQ18: 0111449MOR | AR18: 03500CAB-11A2-41F9-9927-69C8F443BFE3 | AS18: https://swbiodiversity.org/seinet/collections/individual/index.php?occid=34693136 | AT18: PRJNA1200080 | AV18: SYST-MOR-0007145 | AW18: SYST-MOR-0007145_S198_1.fq.gz | AX18: SYST-MOR-0007145_S198_2.fq.gz | BA18: subg. Quercus | BB18: Quercus | BC18: Stellatae
A19: 3909 | B19: QUE003909 | C19: AR_BRP_426_MG | D19: AR_BRP_426_MG | K19: =IFERROR(VLOOKUP(D19,Sheet4!A$1:M$56,11,FALSE),"") | L19: =_xlfn.CONCAT(J19,K19) | M19: Quercus macrocarpa | N19: 44803 | O19: Leah Samuels, Mira Garner | P19: fresh, frozen | Q19: HIPP | R19: USA | S19: Arkansas | T19: Pulaski | U19: County | V19: Burns Park | W19: Little Rock | X19: Forest with mostly Carex underbrush | Y19: Bluejack oak, red oak group, Ulmus sp., Carya sp., post oak, Carex sp., Lespedeza sp. | AB19: Seeds ripening | AC19: Quercus macrocarpa Michx. | AG19: 34.80609 | AH19: -92.323036 | AI19: 283 ft | AL19: Dimensions of Biodiversity: US/China Collaborative Research: Consequences of diversity in Asian and American tree sygameons for functional variation, adaptation and symbiont biodiversity (#2129281) | AM19: MOR | AN19: MOR<USA-IL>: Samuels, AR_BRP_426_MG | AO19: 194572 | AQ19: 0111326MOR | AR19: 8F36FD54-F495-4B2F-AC90-201A13AA2F7D | AS19: https://swbiodiversity.org/seinet/collections/individual/index.php?occid=34693566 | AT19: PRJNA1200080 | AV19: SYST-MOR-0007146 | AW19: SYST-MOR-0007146_S199_1.fq.gz | AX19: SYST-MOR-0007146_S199_2.fq.gz | BA19: subg. Quercus | BB19: Quercus | BC19: Prinoideae
