Workbook

Sheet s8_hyb_wide_v3_RMnotes
B1: sample | C1: alb | D1: biclyr | E1: lob | F1: mac | G1: micmon | H1: muepri | I1: sinstemar | J1: pureCount | K1: hybCount | L1: hyb | N1: sinstemar_1 | O1: muepri_1 | P1: alb_1 | Q1: biclyr_1 | R1: lob_1 | S1: mac1_1 | T1: mac2_1 | U1: micmon_1 | V1: macComb | X1: collectionNumber | Y1: genomeID | Z1: genomeID | AA1: Parent1 | AB1: P1% | AC1: Parent2 | AD1: P2% | AF1: Parent3 | AG1: P3%
A2: 430 | B2: SYST-MOR-0007129 | C2: none | D2: pure? | E2: none | F2: none | G2: none | H2: none | I2: none | J2: 1 | K2: 0 | L2: pure | M2: =IF(AND(W2<0.58,W2>0.2),"F1",IF(W2<0.74,"BC1?",">0.74")) -> >0.74 | N2: 0 | O2: 0 | P2: 0 | Q2: 0.9999 | R2: 0 | S2: 0 | T2: 0 | U2: 0 | V2: 2e-05 | W2: =MAX(N2:R2,U2,V2) -> 0.9999 | X2: AR_BRP_409_MG | Y2: =VLOOKUP(X2,Sheet1!A:B,2,FALSE) -> Quercus lyrata Walt. | Z2: Quercus lyrata Walt. | AB2: =MAX(N2:R2,U2,V2) -> 0.9999 | AD2: =IF(W2<0.99,LARGE((N2:R2,U2,V2),2),"0") -> 0 | AE2: =IF(AND(AB2<0.99,AD2>0.1),"admixed with",IF(AND(AB2<0.99,AD2>0.01),"trace admixed with ","")) | AH2: =_xlfn.CONCAT("Based on ADMIXTURE results of 78,187 SNPs, ",AE2,AC2) -> Based on ADMIXTURE results of 78,187 SNPs,
A3: 431 | B3: SYST-MOR-0007130 | C3: none | D3: none | E3: none | F3: pure? | G3: none | H3: none | I3: none | J3: 1 | K3: 0 | L3: pure | M3: =IF(AND(W3<0.58,W3>0.2),"F1",IF(W3<0.74,"BC1?",">0.74")) -> >0.74 | N3: 0 | O3: 0 | P3: 0 | Q3: 0 | R3: 0 | S3: 0.9999 | T3: 0 | U3: 0 | V3: 0.99994 | W3: =MAX(N3:R3,U3,V3) -> 0.99994 | X3: AR_BRP_410_MG | Y3: =VLOOKUP(X3,Sheet1!A:B,2,FALSE) -> Quercus macrocarpa Michx. | Z3: Quercus macrocarpa Michx. | AB3: =MAX(N3:R3,U3,V3) -> 0.99994 | AD3: =IF(W3<0.99,LARGE((N3:R3,U3,V3),2),"0") -> 0 | AE3: =IF(AND(AB3<0.99,AD3>0.1),"admixed with",IF(AND(AB3<0.99,AD3>0.01),"trace admixed with ","")) | AH3: =_xlfn.CONCAT("Based on ADMIXTURE results of 78,187 SNPs, ",AE3,AC3) -> Based on ADMIXTURE results of 78,187 SNPs,
A4: 432 | B4: SYST-MOR-0007131 | C4: none | D4: none | E4: none | F4: none | G4: none | H4: none | I4: pure? | J4: 1 | K4: 0 | L4: pure | M4: =IF(AND(W4<0.58,W4>0.2),"F1",IF(W4<0.74,"BC1?",">0.74")) -> >0.74 | N4: 0.9999 | O4: 0 | P4: 0 | Q4: 0 | R4: 0 | S4: 0 | T4: 0 | U4: 0 | V4: 2e-05 | W4: =MAX(N4:R4,U4,V4) -> 0.9999 | X4: AR_BRP_411_MG | Y4: =VLOOKUP(X4,Sheet1!A:B,2,FALSE) -> Quercus stellata Wangenh. | Z4: Quercus stellata Wangenh. | AB4: =MAX(N4:R4,U4,V4) -> 0.9999 | AD4: =IF(W4<0.99,LARGE((N4:R4,U4,V4),2),"0") -> 0 | AE4: =IF(AND(AB4<0.99,AD4>0.1),"admixed with",IF(AND(AB4<0.99,AD4>0.01),"trace admixed with ","")) | AH4: =_xlfn.CONCAT("Based on ADMIXTURE results of 78,187 SNPs, ",AE4,AC4) -> Based on ADMIXTURE results of 78,187 SNPs,
A5: 433 | B5: SYST-MOR-0007132 | C5: none | D5: none | E5: none | F5: pure? | G5: none | H5: none | I5: none | J5: 1 | K5: 0 | L5: pure | M5: =IF(AND(W5<0.58,W5>0.2),"F1",IF(W5<0.74,"BC1?",">0.74")) -> >0.74 | N5: 0 | O5: 0 | P5: 0 | Q5: 0 | R5: 0 | S5: 0.9999 | T5: 0 | U5: 0 | V5: 0.99994 | W5: =MAX(N5:R5,U5,V5) -> 0.99994 | X5: AR_BRP_412_MG | Y5: =VLOOKUP(X5,Sheet1!A:B,2,FALSE) -> Quercus macrocarpa Michx. | Z5: Quercus macrocarpa Michx. | AB5: =MAX(N5:R5,U5,V5) -> 0.99994 | AD5: =IF(W5<0.99,LARGE((N5:R5,U5,V5),2),"0") -> 0 | AE5: =IF(AND(AB5<0.99,AD5>0.1),"admixed with",IF(AND(AB5<0.99,AD5>0.01),"trace admixed with ","")) | AH5: =_xlfn.CONCAT("Based on ADMIXTURE results of 78,187 SNPs, ",AE5,AC5) -> Based on ADMIXTURE results of 78,187 SNPs,
A6: 434 | B6: SYST-MOR-0007133 | C6: none | D6: none | E6: none | F6: none | G6: none | H6: none | I6: pure? | J6: 1 | K6: 0 | L6: pure | M6: =IF(AND(W6<0.58,W6>0.2),"F1",IF(W6<0.74,"BC1?",">0.74")) -> >0.74 | N6: 0.9999 | O6: 0 | P6: 0 | Q6: 0 | R6: 0 | S6: 0 | T6: 0 | U6: 0 | V6: 2e-05 | W6: =MAX(N6:R6,U6,V6) -> 0.9999 | X6: AR_BRP_413_MG | Y6: =VLOOKUP(X6,Sheet1!A:B,2,FALSE) -> Quercus stellata Wangenh. | Z6: Quercus stellata Wangenh. | AB6: =MAX(N6:R6,U6,V6) -> 0.9999 | AD6: =IF(W6<0.99,LARGE((N6:R6,U6,V6),2),"0") -> 0 | AE6: =IF(AND(AB6<0.99,AD6>0.1),"admixed with",IF(AND(AB6<0.99,AD6>0.01),"trace admixed with ","")) | AH6: =_xlfn.CONCAT("Based on ADMIXTURE results of 78,187 SNPs, ",AE6,AC6) -> Based on ADMIXTURE results of 78,187 SNPs,
A7: 435 | B7: SYST-MOR-0007134 | C7: none | D7: pure? | E7: none | F7: none | G7: none | H7: none | I7: none | J7: 1 | K7: 0 | L7: pure | M7: =IF(AND(W7<0.58,W7>0.2),"F1",IF(W7<0.74,"BC1?",">0.74")) -> >0.74 | N7: 0 | O7: 0 | P7: 0 | Q7: 0.9999 | R7: 0 | S7: 0 | T7: 0 | U7: 0 | V7: 2e-05 | W7: =MAX(N7:R7,U7,V7) -> 0.9999 | X7: AR_BRP_414_MG | Y7: =VLOOKUP(X7,Sheet1!A:B,2,FALSE) -> Quercus lyrata Walt. | Z7: Quercus lyrata Walt. | AB7: =MAX(N7:R7,U7,V7) -> 0.9999 | AD7: =IF(W7<0.99,LARGE((N7:R7,U7,V7),2),"0") -> 0 | AE7: =IF(AND(AB7<0.99,AD7>0.1),"admixed with",IF(AND(AB7<0.99,AD7>0.01),"trace admixed with ","")) | AH7: =_xlfn.CONCAT("Based on ADMIXTURE results of 78,187 SNPs, ",AE7,AC7) -> Based on ADMIXTURE results of 78,187 SNPs,
A8: 436 | B8: SYST-MOR-0007135 | C8: pure? | D8: none | E8: none | F8: none | G8: none | H8: none | I8: none | J8: 1 | K8: 0 | L8: pure | M8: =IF(AND(W8<0.58,W8>0.2),"F1",IF(W8<0.74,"BC1?",">0.74")) -> >0.74 | N8: 0 | O8: 0 | P8: 0.9999 | Q8: 0 | R8: 0 | S8: 0 | T8: 0 | U8: 0 | V8: 2e-05 | W8: =MAX(N8:R8,U8,V8) -> 0.9999 | X8: AR_BRP_415_MG | Y8: =VLOOKUP(X8,Sheet1!A:B,2,FALSE) -> Quercus alba L. | Z8: Quercus alba L. | AB8: =MAX(N8:R8,U8,V8) -> 0.9999 | AD8: =IF(W8<0.99,LARGE((N8:R8,U8,V8),2),"0") -> 0 | AE8: =IF(AND(AB8<0.99,AD8>0.1),"admixed with",IF(AND(AB8<0.99,AD8>0.01),"trace admixed with ","")) | AH8: =_xlfn.CONCAT("Based on ADMIXTURE results of 78,187 SNPs, ",AE8,AC8) -> Based on ADMIXTURE results of 78,187 SNPs,
A9: 437 | B9: SYST-MOR-0007136 | C9: none | D9: none | E9: none | F9: none | G9: none | H9: none | I9: pure? | J9: 1 | K9: 0 | L9: pure | M9: =IF(AND(W9<0.58,W9>0.2),"F1",IF(W9<0.74,"BC1?",">0.74")) -> >0.74 | N9: 0.9999 | O9: 0 | P9: 0 | Q9: 0 | R9: 0 | S9: 0 | T9: 0 | U9: 0 | V9: 2e-05 | W9: =MAX(N9:R9,U9,V9) -> 0.9999 | X9: AR_BRP_416_MG | Y9: =VLOOKUP(X9,Sheet1!A:B,2,FALSE) -> Quercus stellata Wangenh. | Z9: Quercus stellata Wangenh. | AB9: =MAX(N9:R9,U9,V9) -> 0.9999 | AD9: =IF(W9<0.99,LARGE((N9:R9,U9,V9),2),"0") -> 0 | AE9: =IF(AND(AB9<0.99,AD9>0.1),"admixed with",IF(AND(AB9<0.99,AD9>0.01),"trace admixed with ","")) | AH9: =_xlfn.CONCAT("Based on ADMIXTURE results of 78,187 SNPs, ",AE9,AC9) -> Based on ADMIXTURE results of 78,187 SNPs,
A10: 438 | B10: SYST-MOR-0007137 | C10: none | D10: hybrid? | E10: none | F10: pure? | G10: none | H10: none | I10: none | J10: 1 | K10: 1 | L10: uncertain hybrid | M10: =IF(AND(W10<0.58,W10>0.2),"F1",IF(W10<0.74,"BC1?",">0.74")) -> >0.74 | N10: 0 | O10: 0 | P10: 0 | Q10: 0.0243 | R10: 0 | S10: 0.9545 | T10: 0.0212 | U10: 0 | V10: 0.975677 | W10: =MAX(N10:R10,U10,V10) -> 0.975677 | X10: AR_BRP_417_MG | Y10: =VLOOKUP(X10,Sheet1!A:B,2,FALSE) -> Quercus macrocarpa Michx. | Z10: Quercus macrocarpa Michx. | AB10: =MAX(N10:R10,U10,V10) -> 0.975677 | AC10: Quercus bicolor | AD10: =IF(W10<0.99,LARGE((N10:R10,U10,V10),2),"0") -> 0.0243 | AE10: =IF(AND(AB10<0.99,AD10>0.1,AB10>0.6),"admixed with ",IF(AND(AB10<0.99,AD10>0.01,AD10<0.4),"may be trace admixed with ","")) -> may be trace admixed with | AH10: =_xlfn.CONCAT("Based on ADMIXTURE results of 78,187 SNPs, ",AE10,AC10) -> Based on ADMIXTURE results of 78,187 SNPs, may be trace admixed with Quercus bicolor
A11: 439 | B11: SYST-MOR-0007138 | C11: none | D11: pure? | E11: none | F11: none | G11: none | H11: none | I11: none | J11: 1 | K11: 0 | L11: pure | M11: =IF(AND(W11<0.58,W11>0.2),"F1",IF(W11<0.74,"BC1?",">0.74")) -> >0.74 | N11: 0 | O11: 0 | P11: 0 | Q11: 0.9999 | R11: 0 | S11: 0 | T11: 0 | U11: 0 | V11: 2e-05 | W11: =MAX(N11:R11,U11,V11) -> 0.9999 | X11: AR_BRP_418_MG | Y11: =VLOOKUP(X11,Sheet1!A:B,2,FALSE) -> Quercus lyrata Walt. | Z11: Quercus lyrata Walt. | AB11: =MAX(N11:R11,U11,V11) -> 0.9999 | AD11: =IF(W11<0.99,LARGE((N11:R11,U11,V11),2),"0") -> 0 | AE11: =IF(AND(AB11<0.99,AD11>0.1),"admixed with",IF(AND(AB11<0.99,AD11>0.01),"trace admixed with ","")) | AH11: =_xlfn.CONCAT("Based on ADMIXTURE results of 78,187 SNPs, ",AE11,AC11) -> Based on ADMIXTURE results of 78,187 SNPs,
A12: 440 | B12: SYST-MOR-0007139 | C12: none | D12: none | E12: none | F12: none | G12: none | H12: none | I12: pure? | J12: 1 | K12: 0 | L12: pure | M12: =IF(AND(W12<0.58,W12>0.2),"F1",IF(W12<0.74,"BC1?",">0.74")) -> >0.74 | N12: 0.9999 | O12: 0 | P12: 0 | Q12: 0 | R12: 0 | S12: 0 | T12: 0 | U12: 0 | V12: 2e-05 | W12: =MAX(N12:R12,U12,V12) -> 0.9999 | X12: AR_BRP_419_MG | Y12: =VLOOKUP(X12,Sheet1!A:B,2,FALSE) -> Quercus stellata Wangenh. | Z12: Quercus stellata Wangenh. | AB12: =MAX(N12:R12,U12,V12) -> 0.9999 | AD12: =IF(W12<0.99,LARGE((N12:R12,U12,V12),2),"0") -> 0 | AE12: =IF(AND(AB12<0.99,AD12>0.1),"admixed with",IF(AND(AB12<0.99,AD12>0.01),"trace admixed with ","")) | AH12: =_xlfn.CONCAT("Based on ADMIXTURE results of 78,187 SNPs, ",AE12,AC12) -> Based on ADMIXTURE results of 78,187 SNPs,
A13: 441 | B13: SYST-MOR-0007140 | C13: pure? | D13: none | E13: none | F13: none | G13: none | H13: none | I13: none | J13: 1 | K13: 0 | L13: pure | M13: =IF(AND(W13<0.58,W13>0.2),"F1",IF(W13<0.74,"BC1?",">0.74")) -> >0.74 | N13: 0 | O13: 0 | P13: 0.9999 | Q13: 0 | R13: 0 | S13: 0 | T13: 0 | U13: 0 | V13: 2e-05 | W13: =MAX(N13:R13,U13,V13) -> 0.9999 | X13: AR_BRP_420_MG | Y13: =VLOOKUP(X13,Sheet1!A:B,2,FALSE) -> Quercus alba L. | Z13: Quercus alba L. | AB13: =MAX(N13:R13,U13,V13) -> 0.9999 | AD13: =IF(W13<0.99,LARGE((N13:R13,U13,V13),2),"0") -> 0 | AE13: =IF(AND(AB13<0.99,AD13>0.1),"admixed with",IF(AND(AB13<0.99,AD13>0.01),"trace admixed with ","")) | AH13: =_xlfn.CONCAT("Based on ADMIXTURE results of 78,187 SNPs, ",AE13,AC13) -> Based on ADMIXTURE results of 78,187 SNPs,
A14: 442 | B14: SYST-MOR-0007141 | C14: none | D14: none | E14: none | F14: none | G14: none | H14: pure? | I14: none | J14: 1 | K14: 0 | L14: pure | M14: =IF(AND(W14<0.58,W14>0.2),"F1",IF(W14<0.74,"BC1?",">0.74")) -> >0.74 | N14: 0 | O14: 0.9999 | P14: 0 | Q14: 0 | R14: 0 | S14: 0 | T14: 0 | U14: 0 | V14: 2e-05 | W14: =MAX(N14:R14,U14,V14) -> 0.9999 | X14: AR_BRP_421_MG | Y14: =VLOOKUP(X14,Sheet1!A:B,2,FALSE) -> Quercus muehlenbergii Engelm. | Z14: Quercus muehlenbergii Engelm. | AB14: =MAX(N14:R14,U14,V14) -> 0.9999 | AD14: =IF(W14<0.99,LARGE((N14:R14,U14,V14),2),"0") -> 0 | AE14: =IF(AND(AB14<0.99,AD14>0.1),"admixed with",IF(AND(AB14<0.99,AD14>0.01),"trace admixed with ","")) | AH14: =_xlfn.CONCAT("Based on ADMIXTURE results of 78,187 SNPs, ",AE14,AC14) -> Based on ADMIXTURE results of 78,187 SNPs,
A15: 443 | B15: SYST-MOR-0007142 | C15: none | D15: none | E15: none | F15: none | G15: none | H15: pure? | I15: none | J15: 1 | K15: 0 | L15: pure | M15: =IF(AND(W15<0.58,W15>0.2),"F1",IF(W15<0.74,"BC1?",">0.74")) -> >0.74 | N15: 0 | O15: 0.9999 | P15: 0 | Q15: 0 | R15: 0 | S15: 0 | T15: 0 | U15: 0 | V15: 2e-05 | W15: =MAX(N15:R15,U15,V15) -> 0.9999 | X15: AR_BRP_422_MG | Y15: =VLOOKUP(X15,Sheet1!A:B,2,FALSE) -> Quercus muehlenbergii Engelm. | Z15: Quercus muehlenbergii Engelm. | AB15: =MAX(N15:R15,U15,V15) -> 0.9999 | AD15: =IF(W15<0.99,LARGE((N15:R15,U15,V15),2),"0") -> 0 | AE15: =IF(AND(AB15<0.99,AD15>0.1),"admixed with",IF(AND(AB15<0.99,AD15>0.01),"trace admixed with ","")) | AH15: =_xlfn.CONCAT("Based on ADMIXTURE results of 78,187 SNPs, ",AE15,AC15) -> Based on ADMIXTURE results of 78,187 SNPs,
A16: 444 | B16: SYST-MOR-0007143 | C16: none | D16: none | E16: none | F16: pure? | G16: none | H16: none | I16: none | J16: 1 | K16: 0 | L16: pure | M16: =IF(AND(W16<0.58,W16>0.2),"F1",IF(W16<0.74,"BC1?",">0.74")) -> >0.74 | N16: 0 | O16: 0 | P16: 0 | Q16: 0 | R16: 0 | S16: 0.9999 | T16: 0 | U16: 0 | V16: 0.99994 | W16: =MAX(N16:R16,U16,V16) -> 0.99994 | X16: AR_BRP_423_MG | Y16: =VLOOKUP(X16,Sheet1!A:B,2,FALSE) -> Quercus macrocarpa Michx. | Z16: Quercus macrocarpa Michx. | AB16: =MAX(N16:R16,U16,V16) -> 0.99994 | AD16: =IF(W16<0.99,LARGE((N16:R16,U16,V16),2),"0") -> 0 | AE16: =IF(AND(AB16<0.99,AD16>0.1),"admixed with",IF(AND(AB16<0.99,AD16>0.01),"trace admixed with ","")) | AH16: =_xlfn.CONCAT("Based on ADMIXTURE results of 78,187 SNPs, ",AE16,AC16) -> Based on ADMIXTURE results of 78,187 SNPs,
A17: 445 | B17: SYST-MOR-0007144 | C17: pure? | D17: none | E17: none | F17: none | G17: none | H17: none | I17: none | J17: 1 | K17: 0 | L17: pure | M17: =IF(AND(W17<0.58,W17>0.2),"F1",IF(W17<0.74,"BC1?",">0.74")) -> >0.74 | N17: 0 | O17: 0 | P17: 0.9999 | Q17: 0 | R17: 0 | S17: 0 | T17: 0 | U17: 0 | V17: 2e-05 | W17: =MAX(N17:R17,U17,V17) -> 0.9999 | X17: AR_BRP_424_MG | Y17: =VLOOKUP(X17,Sheet1!A:B,2,FALSE) -> Quercus alba L. | Z17: Quercus alba L. | AB17: =MAX(N17:R17,U17,V17) -> 0.9999 | AD17: =IF(W17<0.99,LARGE((N17:R17,U17,V17),2),"0") -> 0 | AE17: =IF(AND(AB17<0.99,AD17>0.1),"admixed with",IF(AND(AB17<0.99,AD17>0.01),"trace admixed with ","")) | AH17: =_xlfn.CONCAT("Based on ADMIXTURE results of 78,187 SNPs, ",AE17,AC17) -> Based on ADMIXTURE results of 78,187 SNPs,
A18: 446 | B18: SYST-MOR-0007145 | C18: none | D18: none | E18: none | F18: none | G18: none | H18: none | I18: pure? | J18: 1 | K18: 0 | L18: pure | M18: =IF(AND(W18<0.58,W18>0.2),"F1",IF(W18<0.74,"BC1?",">0.74")) -> >0.74 | N18: 0.9999 | O18: 0 | P18: 0 | Q18: 0 | R18: 0 | S18: 0 | T18: 0 | U18: 0 | V18: 2e-05 | W18: =MAX(N18:R18,U18,V18) -> 0.9999 | X18: AR_BRP_425_MG | Y18: =VLOOKUP(X18,Sheet1!A:B,2,FALSE) -> Quercus stellata Wangenh. | Z18: Quercus stellata Wangenh. | AB18: =MAX(N18:R18,U18,V18) -> 0.9999 | AD18: =IF(W18<0.99,LARGE((N18:R18,U18,V18),2),"0") -> 0 | AE18: =IF(AND(AB18<0.99,AD18>0.1),"admixed with",IF(AND(AB18<0.99,AD18>0.01),"trace admixed with ","")) | AH18: =_xlfn.CONCAT("Based on ADMIXTURE results of 78,187 SNPs, ",AE18,AC18) -> Based on ADMIXTURE results of 78,187 SNPs,
A19: 447 | B19: SYST-MOR-0007146 | C19: none | D19: none | E19: none | F19: pure? | G19: none | H19: none | I19: none | J19: 1 | K19: 0 | L19: pure | M19: =IF(AND(W19<0.58,W19>0.2),"F1",IF(W19<0.74,"BC1?",">0.74")) -> >0.74 | N19: 0 | O19: 0 | P19: 0 | Q19: 0.0173 | R19: 0 | S19: 0.9827 | T19: 0 | U19: 0 | V19: 0.982681 | W19: =MAX(N19:R19,U19,V19) -> 0.982681 | X19: AR_BRP_426_MG | Y19: =VLOOKUP(X19,Sheet1!A:B,2,FALSE) -> Quercus macrocarpa Michx. | Z19: Quercus macrocarpa Michx. | AB19: =MAX(N19:R19,U19,V19) -> 0.982681 | AD19: =IF(W19<0.99,LARGE((N19:R19,U19,V19),2),"0") -> 0.0173 | AE19: =IF(AND(AB19<0.99,AD19>0.1),"admixed with",IF(AND(AB19<0.99,AD19>0.01),"trace admixed with ","")) -> trace admixed with | AH19: =_xlfn.CONCAT("Based on ADMIXTURE results of 78,187 SNPs, ",AE19,AC19) -> Based on ADMIXTURE results of 78,187 SNPs, trace admixed with
A20: 448 | B20: SYST-MOR-0007147 | C20: none | D20: pure? | E20: none | F20: none | G20: none | H20: none | I20: none | J20: 1 | K20: 0 | L20: pure | M20: =IF(AND(W20<0.58,W20>0.2),"F1",IF(W20<0.74,"BC1?",">0.74")) -> >0.74 | N20: 0 | O20: 0 | P20: 0 | Q20: 0.9999 | R20: 0 | S20: 0 | T20: 0 | U20: 0 | V20: 2e-05 | W20: =MAX(N20:R20,U20,V20) -> 0.9999 | X20: AR_BRP_427_MG | Y20: =VLOOKUP(X20,Sheet1!A:B,2,FALSE) -> Quercus lyrata Walt. | Z20: Quercus lyrata Walt. | AB20: =MAX(N20:R20,U20,V20) -> 0.9999 | AD20: =IF(W20<0.99,LARGE((N20:R20,U20,V20),2),"0") -> 0 | AE20: =IF(AND(AB20<0.99,AD20>0.1),"admixed with",IF(AND(AB20<0.99,AD20>0.01),"trace admixed with ","")) | AH20: =_xlfn.CONCAT("Based on ADMIXTURE results of 78,187 SNPs, ",AE20,AC20) -> Based on ADMIXTURE results of 78,187 SNPs,
A21: 449 | B21: SYST-MOR-0007148 | C21: pure? | D21: none | E21: none | F21: none | G21: none | H21: none | I21: none | J21: 1 | K21: 0 | L21: pure | M21: =IF(AND(W21<0.58,W21>0.2),"F1",IF(W21<0.74,"BC1?",">0.74")) -> >0.74 | N21: 0 | O21: 0 | P21: 0.9999 | Q21: 0 | R21: 0 | S21: 0 | T21: 0 | U21: 0 | V21: 2e-05 | W21: =MAX(N21:R21,U21,V21) -> 0.9999 | X21: AR_BRP_428_MG | Y21: =VLOOKUP(X21,Sheet1!A:B,2,FALSE) -> Quercus alba L. | Z21: Quercus alba L. | AB21: =MAX(N21:R21,U21,V21) -> 0.9999 | AD21: =IF(W21<0.99,LARGE((N21:R21,U21,V21),2),"0") -> 0 | AE21: =IF(AND(AB21<0.99,AD21>0.1),"admixed with",IF(AND(AB21<0.99,AD21>0.01),"trace admixed with ","")) | AH21: =_xlfn.CONCAT("Based on ADMIXTURE results of 78,187 SNPs, ",AE21,AC21) -> Based on ADMIXTURE results of 78,187 SNPs,
A22: 450 | B22: SYST-MOR-0007149 | C22: pure? | D22: none | E22: none | F22: none | G22: none | H22: none | I22: none | J22: 1 | K22: 0 | L22: pure | M22: =IF(AND(W22<0.58,W22>0.2),"F1",IF(W22<0.74,"BC1?",">0.74")) -> >0.74 | N22: 0 | O22: 0 | P22: 0.9999 | Q22: 0 | R22: 0 | S22: 0 | T22: 0 | U22: 0 | V22: 2e-05 | W22: =MAX(N22:R22,U22,V22) -> 0.9999 | X22: AR_BRP_429_MG | Y22: =VLOOKUP(X22,Sheet1!A:B,2,FALSE) -> Quercus alba L. | Z22: Quercus alba L. | AB22: =MAX(N22:R22,U22,V22) -> 0.9999 | AD22: =IF(W22<0.99,LARGE((N22:R22,U22,V22),2),"0") -> 0 | AE22: =IF(AND(AB22<0.99,AD22>0.1),"admixed with",IF(AND(AB22<0.99,AD22>0.01),"trace admixed with ","")) | AH22: =_xlfn.CONCAT("Based on ADMIXTURE results of 78,187 SNPs, ",AE22,AC22) -> Based on ADMIXTURE results of 78,187 SNPs,
... A29: 100 | B29: SYST-MOR-0006799 | C29: none | D29: none | E29: none | F29: pure? | G29: none | H29: none | I29: none | J29: 1 | K29: 0 | L29: pure | M29: =IF(AND(W29<0.58,W29>0.2),"F1",IF(W29<0.74,"BC1?",">0.74")) -> >0.74 | N29: 0 | O29: 0 | P29: 0.0044 | Q29: 0 | R29: 0 | S29: 0.1306 | T29: 0.8649 | U29: 0 | V29: 0.995545 | W29: =MAX(N29:R29,U29,V29) -> 0.995545 | X29: IA_CHP_067_MG | Y29: =VLOOKUP(X29,Sheet1!A:B,2,FALSE) -> Quercus macrocarpa Michx. | Z29: Quercus macrocarpa Michx. | AB29: =MAX(N29:R29,U29,V29) -> 0.995545 | AD29: =IF(W29<0.99,LARGE((N29:R29,U29,V29),2),"0") -> 0 | AE29: =IF(AND(AB29<0.99,AD29>0.1),"admixed with",IF(AND(AB29<0.99,AD29>0.01),"trace admixed with ","")) | AH29: =_xlfn.CONCAT("Based on ADMIXTURE results of 78,187 SNPs, ",AE29,AC29) -> Based on ADMIXTURE results of 78,187 SNPs,
A30: 101 | B30: SYST-MOR-0006800 | C30: none | D30: pure? | E30: none | F30: hybrid? | G30: none | H30: none | I30: none | J30: 1 | K30: 1 | L30: uncertain hybrid | M30: =IF(AND(W30<0.58,W30>0.2),"F1",IF(W30<0.74,"BC1?",">0.74")) -> >0.74 | N30: 0 | O30: 0 | P30: 0 | Q30: 0.9473 | R30: 0 | S30: 0 | T30: 0.0526 | U30: 0 | V30: 0.052613 | W30: =MAX(N30:R30,U30,V30) -> 0.9473 | X30: IA_CHP_068_MG | Y30: =VLOOKUP(X30,Sheet1!A:B,2,FALSE) -> Quercus bicolor Willd. | Z30: Quercus bicolor Willd. | AB30: =MAX(N30:R30,U30,V30) -> 0.9473 | AC30: Quercus macrocarpa | AD30: =IF(W30<0.99,LARGE((N30:R30,U30,V30),2),"0") -> 0.052613 | AE30: =IF(AND(AB30<0.99,AD30>0.1,AB30>0.6),"admixed with ",IF(AND(AB30<0.99,AD30>0.01,AD30<0.4),"may be trace admixed with ","")) -> may be trace admixed with | AH30: =_xlfn.CONCAT("Based on ADMIXTURE results of 78,187 SNPs, ",AE30,AC30) -> Based on ADMIXTURE results of 78,187 SNPs, may be trace admixed with Quercus macrocarpa
A31: 102 | B31: SYST-MOR-0006801 | C31: none | D31: none | E31: none | F31: pure? | G31: none | H31: none | I31: none | J31: 1 | K31: 0 | L31: pure | M31: =IF(AND(W31<0.58,W31>0.2),"F1",IF(W31<0.74,"BC1?",">0.74")) -> >0.74 | N31: 0 | O31: 0 | P31: 0 | Q31: 0 | R31: 0 | S31: 0 | T31: 0.9999 | U31: 0 | V31: 0.99994 | W31: =MAX(N31:R31,U31,V31) -> 0.99994 | X31: IA_CHP_069_MG | Y31: =VLOOKUP(X31,Sheet1!A:B,2,FALSE) -> Quercus macrocarpa Michx. | Z31: Quercus macrocarpa Michx. | AB31: =MAX(N31:R31,U31,V31) -> 0.99994 | AD31: =IF(W31<0.99,LARGE((N31:R31,U31,V31),2),"0") -> 0 | AE31: =IF(AND(AB31<0.99,AD31>0.1),"admixed with",IF(AND(AB31<0.99,AD31>0.01),"trace admixed with ","")) | AH31: =_xlfn.CONCAT("Based on ADMIXTURE results of 78,187 SNPs, ",AE31,AC31) -> Based on ADMIXTURE results of 78,187 SNPs,
A32: 103 | B32: SYST-MOR-0006802 | C32: none | D32: none | E32: none | F32: pure? | G32: none | H32: none | I32: none | J32: 1 | K32: 0 | L32: pure | M32: =IF(AND(W32<0.58,W32>0.2),"F1",IF(W32<0.74,"BC1?",">0.74")) -> >0.74 | N32: 0 | O32: 0 | P32: 0 | Q32: 0 | R32: 0 | S32: 0.1112 | T32: 0.8887 | U32: 0 | V32: 0.99994 | W32: =MAX(N32:R32,U32,V32) -> 0.99994 | X32: IA_CHP_070_MG | Y32: =VLOOKUP(X32,Sheet1!A:B,2,FALSE) -> Quercus macrocarpa Michx. | Z32: Quercus macrocarpa Michx. | AB32: =MAX(N32:R32,U32,V32) -> 0.99994 | AD32: =IF(W32<0.99,LARGE((N32:R32,U32,V32),2),"0") -> 0 | AE32: =IF(AND(AB32<0.99,AD32>0.1),"admixed with",IF(AND(AB32<0.99,AD32>0.01),"trace admixed with ","")) | AH32: =_xlfn.CONCAT("Based on ADMIXTURE results of 78,187 SNPs, ",AE32,AC32) -> Based on ADMIXTURE results of 78,187 SNPs,
A33: 84 | B33: SYST-MOR-0006783 | C33: pure? | D33: none | E33: none | F33: none | G33: none | H33: none | I33: none | J33: 1 | K33: 0 | L33: pure | M33: =IF(AND(W33<0.58,W33>0.2),"F1",IF(W33<0.74,"BC1?",">0.74")) -> >0.74 | N33: 0 | O33: 0 | P33: 0.9862 | Q33: 0.0036 | R33: 0 | S33: 0 | T33: 0.0101 | U33: 0 | V33: 0.010103 | W33: =MAX(N33:R33,U33,V33) -> 0.9862 | X33: IA_LNW_051_MG | Y33: =VLOOKUP(X33,Sheet1!A:B,2,FALSE) -> Quercus alba L. | Z33: Quercus alba L. | AB33: =MAX(N33:R33,U33,V33) -> 0.9862 | AD33: =IF(W33<0.99,LARGE((N33:R33,U33,V33),2),"0") -> 0.010103 | AE33: =IF(AND(AB33<0.99,AD33>0.1),"admixed with",IF(AND(AB33<0.99,AD33>0.01),"trace admixed with ","")) -> trace admixed with | AH33: =_xlfn.CONCAT("Based on ADMIXTURE results of 78,187 SNPs, ",AE33,AC33) -> Based on ADMIXTURE results of 78,187 SNPs, trace admixed with
A34: 85 | B34: SYST-MOR-0006784 | C34: pure? | D34: none | E34: none | F34: none | G34: none | H34: none | I34: none | J34: 1 | K34: 0 | L34: pure | M34: =IF(AND(W34<0.58,W34>0.2),"F1",IF(W34<0.74,"BC1?",">0.74")) -> >0.74 | N34: 0 | O34: 0 | P34: 0.9999 | Q34: 0 | R34: 0 | S34: 0 | T34: 0 | U34: 0 | V34: 2e-05 | W34: =MAX(N34:R34,U34,V34) -> 0.9999 | X34: IA_LNW_052_MG | Y34: =VLOOKUP(X34,Sheet1!A:B,2,FALSE) -> Quercus alba L. | Z34: Quercus alba L. | AB34: =MAX(N34:R34,U34,V34) -> 0.9999 | AD34: =IF(W34<0.99,LARGE((N34:R34,U34,V34),2),"0") -> 0 | AE34: =IF(AND(AB34<0.99,AD34>0.1),"admixed with",IF(AND(AB34<0.99,AD34>0.01),"trace admixed with ","")) | AH34: =_xlfn.CONCAT("Based on ADMIXTURE results of 78,187 SNPs, ",AE34,AC34) -> Based on ADMIXTURE results of 78,187 SNPs,
A35: 86 | B35: SYST-MOR-0006785 | C35: pure? | D35: none | E35: none | F35: none | G35: none | H35: none | I35: none | J35: 1 | K35: 0 | L35: pure | M35: =IF(AND(W35<0.58,W35>0.2),"F1",IF(W35<0.74,"BC1?",">0.74")) -> >0.74 | N35: 0 | O35: 0 | P35: 0.9999 | Q35: 0 | R35: 0 | S35: 0 | T35: 0 | U35: 0 | V35: 2e-05 | W35: =MAX(N35:R35,U35,V35) -> 0.9999 | X35: IA_LNW_053_MG | Y35: =VLOOKUP(X35,Sheet1!A:B,2,FALSE) -> Quercus alba L. | Z35: Quercus alba L. | AB35: =MAX(N35:R35,U35,V35) -> 0.9999 | AD35: =IF(W35<0.99,LARGE((N35:R35,U35,V35),2),"0") -> 0 | AE35: =IF(AND(AB35<0.99,AD35>0.1),"admixed with",IF(AND(AB35<0.99,AD35>0.01),"trace admixed with ","")) | AH35: =_xlfn.CONCAT("Based on ADMIXTURE results of 78,187 SNPs, ",AE35,AC35) -> Based on ADMIXTURE results of 78,187 SNPs,
A36: 87 | B36: SYST-MOR-0006786 | C36: pure? | D36: none | E36: none | F36: none | G36: none | H36: none | I36: none | J36: 1 | K36: 0 | L36: pure | M36: =IF(AND(W36<0.58,W36>0.2),"F1",IF(W36<0.74,"BC1?",">0.74")) -> >0.74 | N36: 0 | O36: 0 | P36: 0.9999 | Q36: 0 | R36: 0 | S36: 0 | T36: 0 | U36: 0 | V36: 2e-05 | W36: =MAX(N36:R36,U36,V36) -> 0.9999 | X36: IA_LNW_054_MG | Y36: =VLOOKUP(X36,Sheet1!A:B,2,FALSE) -> Quercus alba L. | Z36: Quercus alba L. | AB36: =MAX(N36:R36,U36,V36) -> 0.9999 | AD36: =IF(W36<0.99,LARGE((N36:R36,U36,V36),2),"0") -> 0 | AE36: =IF(AND(AB36<0.99,AD36>0.1),"admixed with",IF(AND(AB36<0.99,AD36>0.01),"trace admixed with ","")) | AH36: =_xlfn.CONCAT("Based on ADMIXTURE results of 78,187 SNPs, ",AE36,AC36) -> Based on ADMIXTURE results of 78,187 SNPs,
A37: 88 | B37: SYST-MOR-0006787 | C37: none | D37: none | E37: none | F37: none | G37: none | H37: pure? | I37: none | J37: 1 | K37: 0 | L37: pure | M37: =IF(AND(W37<0.58,W37>0.2),"F1",IF(W37<0.74,"BC1?",">0.74")) -> >0.74 | N37: 0 | O37: 0.9966 | P37: 0 | Q37: 0 | R37: 0 | S37: 0.0034 | T37: 0 | U37: 0 | V37: 0.003373 | W37: =MAX(N37:R37,U37,V37) -> 0.9966 | X37: IA_LNW_055_MG | Y37: =VLOOKUP(X37,Sheet1!A:B,2,FALSE) -> Quercus muehlenbergii Engelm. | Z37: Quercus muehlenbergii Engelm. | AB37: =MAX(N37:R37,U37,V37) -> 0.9966 | AD37: =IF(W37<0.99,LARGE((N37:R37,U37,V37),2),"0") -> 0 | AE37: =IF(AND(AB37<0.99,AD37>0.1),"admixed with",IF(AND(AB37<0.99,AD37>0.01),"trace admixed with ","")) | AH37: =_xlfn.CONCAT("Based on ADMIXTURE results of 78,187 SNPs, ",AE37,AC37) -> Based on ADMIXTURE results of 78,187 SNPs,
A38: 89 | B38: SYST-MOR-0006788 | C38: none | D38: none | E38: none | F38: none | G38: none | H38: pure? | I38: none | J38: 1 | K38: 0 | L38: pure | M38: =IF(AND(W38<0.58,W38>0.2),"F1",IF(W38<0.74,"BC1?",">0.74")) -> >0.74 | N38: 0 | O38: 0.9999 | P38: 0 | Q38: 0 | R38: 0 | S38: 0 | T38: 0 | U38: 0 | V38: 2e-05 | W38: =MAX(N38:R38,U38,V38) -> 0.9999 | X38: IA_LNW_056_MG | Y38: =VLOOKUP(X38,Sheet1!A:B,2,FALSE) -> Quercus muehlenbergii Engelm. | Z38: Quercus muehlenbergii Engelm. | AB38: =MAX(N38:R38,U38,V38) -> 0.9999 | AD38: =IF(W38<0.99,LARGE((N38:R38,U38,V38),2),"0") -> 0 | AE38: =IF(AND(AB38<0.99,AD38>0.1),"admixed with",IF(AND(AB38<0.99,AD38>0.01),"trace admixed with ","")) | AH38: =_xlfn.CONCAT("Based on ADMIXTURE results of 78,187 SNPs, ",AE38,AC38) -> Based on ADMIXTURE results of 78,187 SNPs,
A39: 90 | B39: SYST-MOR-0006789 | C39: none | D39: none | E39: none | F39: none | G39: none | H39: pure? | I39: none | J39: 1 | K39: 0 | L39: pure | M39: =IF(AND(W39<0.58,W39>0.2),"F1",IF(W39<0.74,"BC1?",">0.74")) -> >0.74 | N39: 0 | O39: 0.9881 | P39: 0.0118 | Q39: 0 | R39: 0 | S39: 0 | T39: 0 | U39: 0 | V39: 2e-05 | W39: =MAX(N39:R39,U39,V39) -> 0.9881 | X39: IA_LNW_057_MG | Y39: =VLOOKUP(X39,Sheet1!A:B,2,FALSE) -> Quercus muehlenbergii Engelm. | Z39: Quercus muehlenbergii Engelm. | AB39: =MAX(N39:R39,U39,V39) -> 0.9881 | AD39: =IF(W39<0.99,LARGE((N39:R39,U39,V39),2),"0") -> 0.0118 | AE39: =IF(AND(AB39<0.99,AD39>0.1),"admixed with",IF(AND(AB39<0.99,AD39>0.01),"trace admixed with ","")) -> trace admixed with | AH39: =_xlfn.CONCAT("Based on ADMIXTURE results of 78,187 SNPs, ",AE39,AC39) -> Based on ADMIXTURE results of 78,187 SNPs, trace admixed with
A40: 91 | B40: SYST-MOR-0006790 | C40: none | D40: none | E40: none | F40: none | G40: none | H40: pure? | I40: none | J40: 1 | K40: 0 | L40: pure | M40: =IF(AND(W40<0.58,W40>0.2),"F1",IF(W40<0.74,"BC1?",">0.74")) -> >0.74 | N40: 0 | O40: 0.9999 | P40: 0 | Q40: 0 | R40: 0 | S40: 0 | T40: 0 | U40: 0 | V40: 2e-05 | W40: =MAX(N40:R40,U40,V40) -> 0.9999 | X40: IA_LNW_058_MG | Y40: =VLOOKUP(X40,Sheet1!A:B,2,FALSE) -> Quercus muehlenbergii Engelm. | Z40: Quercus muehlenbergii Engelm. | AB40: =MAX(N40:R40,U40,V40) -> 0.9999 | AD40: =IF(W40<0.99,LARGE((N40:R40,U40,V40),2),"0") -> 0 | AE40: =IF(AND(AB40<0.99,AD40>0.1),"admixed with",IF(AND(AB40<0.99,AD40>0.01),"trace admixed with ","")) | AH40: =_xlfn.CONCAT("Based on ADMIXTURE results of 78,187 SNPs, ",AE40,AC40) -> Based on ADMIXTURE results of 78,187 SNPs,
A41: 92 | B41: SYST-MOR-0006791 | C41: none | D41: none | E41: none | F41: pure? | G41: none | H41: none | I41: none | J41: 1 | K41: 0 | L41: pure | M41: =IF(AND(W41<0.58,W41>0.2),"F1",IF(W41<0.74,"BC1?",">0.74")) -> >0.74 | N41: 0 | O41: 0 | P41: 0 | Q41: 0 | R41: 0 | S41: 0.2169 | T41: 0.783 | U41: 0 | V41: 0.99994 | W41: =MAX(N41:R41,U41,V41) -> 0.99994 | X41: IA_LNW_059_MG | Y41: =VLOOKUP(X41,Sheet1!A:B,2,FALSE) -> Quercus macrocarpa Michx. | Z41: Quercus macrocarpa Michx. | AB41: =MAX(N41:R41,U41,V41) -> 0.99994 | AD41: =IF(W41<0.99,LARGE((N41:R41,U41,V41),2),"0") -> 0 | AE41: =IF(AND(AB41<0.99,AD41>0.1),"admixed with",IF(AND(AB41<0.99,AD41>0.01),"trace admixed with ","")) | AH41: =_xlfn.CONCAT("Based on ADMIXTURE results of 78,187 SNPs, ",AE41,AC41) -> Based on ADMIXTURE results of 78,187 SNPs,
A42: 93 | B42: SYST-MOR-0006792 | C42: none | D42: none | E42: none | F42: pure? | G42: none | H42: none | I42: none | J42: 1 | K42: 0 | L42: pure | M42: =IF(AND(W42<0.58,W42>0.2),"F1",IF(W42<0.74,"BC1?",">0.74")) -> >0.74 | N42: 0 | O42: 0 | P42: 0 | Q42: 0 | R42: 0.0001 | S42: 0.1785 | T42: 0.8213 | U42: 0 | V42: 0.999857 | W42: =MAX(N42:R42,U42,V42) -> 0.999857 | X42: IA_LNW_060_MG | Y42: =VLOOKUP(X42,Sheet1!A:B,2,FALSE) -> Quercus macrocarpa Michx. | Z42: Quercus macrocarpa Michx. | AB42: =MAX(N42:R42,U42,V42) -> 0.999857 | AD42: =IF(W42<0.99,LARGE((N42:R42,U42,V42),2),"0") -> 0 | AE42: =IF(AND(AB42<0.99,AD42>0.1),"admixed with",IF(AND(AB42<0.99,AD42>0.01),"trace admixed with ","")) | AH42: =_xlfn.CONCAT("Based on ADMIXTURE results of 78,187 SNPs, ",AE42,AC42) -> Based on ADMIXTURE results of 78,187 SNPs,
... A57: 551 | B57: SYST-MOR-0007250 | C57: pure? | D57: none | E57: none | F57: none | G57: none | H57: none | I57: none | J57: 1 | K57: 0 | L57: pure | M57: =IF(AND(W57<0.58,W57>0.2),"F1",IF(W57<0.74,"BC1?",">0.74")) -> >0.74 | N57: 0 | O57: 0 | P57: 0.9999 | Q57: 0 | R57: 0 | S57: 0 | T57: 0 | U57: 0 | V57: 2e-05 | W57: =MAX(N57:R57,U57,V57) -> 0.9999 | X57: IL_CHB_530_MG | Y57: =VLOOKUP(X57,Sheet1!A:B,2,FALSE) -> Quercus alba L. | Z57: Quercus alba L. | AB57: =MAX(N57:R57,U57,V57) -> 0.9999 | AD57: =IF(W57<0.99,LARGE((N57:R57,U57,V57),2),"0") -> 0 | AE57: =IF(AND(AB57<0.99,AD57>0.1),"admixed with",IF(AND(AB57<0.99,AD57>0.01),"trace admixed with ","")) | AH57: =_xlfn.CONCAT("Based on ADMIXTURE results of 78,187 SNPs, ",AE57,AC57) -> Based on ADMIXTURE results of 78,187 SNPs,
A58: 18 | B58: SYST-MOR-0006717 | C58: hybrid? | D58: none | E58: none | F58: none | G58: hybrid? | H58: none | I58: none | J58: 0 | K58: 2 | L58: editedpure | M58: =IF(AND(W58<0.58,W58>0.2),"F1",IF(W58<0.74,"BC1?",">0.74")) -> >0.74 | N58: 0 | O58: 0 | P58: 0.0584 | Q58: 0 | R58: 0 | S58: 0 | T58: 0 | U58: 0.9416 | V58: 2e-05 | W58: =MAX(N58:R58,U58,V58) -> 0.9416 | X58: IL_HP_MG919_MG | Y58: =VLOOKUP(X58,Sheet1!A:B,2,FALSE) -> Quercus michauxii Nutt. | Z58: Quercus michauxii Nutt. | AB58: =MAX(N58:R58,U58,V58) -> 0.9416 | AC58: Quercus alba | AD58: =IF(W58<0.99,LARGE((N58:R58,U58,V58),2),"0") -> 0.0584 | AE58: =IF(AND(AB58<0.99,AD58>0.1,AB58>0.6),"admixed with ",IF(AND(AB58<0.99,AD58>0.01,AD58<0.4),"trace admixed with ","")) -> trace admixed with | AG58: =IF(AB58+AD58<0.99,LARGE((N58:R58,U58,V58),3),"") | AH58: Overwrite
A59: 19 | B59: SYST-MOR-0006718 | C59: none | D59: none | E59: none | F59: none | G59: pure? | H59: none | I59: none | J59: 1 | K59: 0 | L59: pure | M59: =IF(AND(W59<0.58,W59>0.2),"F1",IF(W59<0.74,"BC1?",">0.74")) -> >0.74 | N59: 0 | O59: 0 | P59: 0.0529 | Q59: 0 | R59: 0 | S59: 0 | T59: 0 | U59: 0.947 | V59: 2e-05 | W59: =MAX(N59:R59,U59,V59) -> 0.947 | X59: IL_HP_MG920_MG | Y59: =VLOOKUP(X59,Sheet1!A:B,2,FALSE) -> Quercus michauxii Nutt. | Z59: Quercus michauxii Nutt. | AB59: =MAX(N59:R59,U59,V59) -> 0.947 | AD59: =IF(W59<0.99,LARGE((N59:R59,U59,V59),2),"0") -> 0.0529 | AE59: =IF(AND(AB59<0.99,AD59>0.1),"admixed with",IF(AND(AB59<0.99,AD59>0.01),"trace admixed with ","")) -> trace admixed with | AH59: =_xlfn.CONCAT("Based on ADMIXTURE results of 78,187 SNPs, ",AE59,AC59) -> Based on ADMIXTURE results of 78,187 SNPs, trace admixed with
A60: 20 | B60: SYST-MOR-0006719 | C60: none | D60: none | E60: none | F60: none | G60: pure? | H60: none | I60: none | J60: 1 | K60: 0 | L60: pure | M60: =IF(AND(W60<0.58,W60>0.2),"F1",IF(W60<0.74,"BC1?",">0.74")) -> >0.74 | N60: 0 | O60: 0 | P60: 0.0486 | Q60: 0 | R60: 0 | S60: 0 | T60: 0 | U60: 0.9513 | V60: 2e-05 | W60: =MAX(N60:R60,U60,V60) -> 0.9513 | X60: IL_HP_MG921_MG | Y60: =VLOOKUP(X60,Sheet1!A:B,2,FALSE) -> Quercus michauxii Nutt. | Z60: Quercus michauxii Nutt. | AB60: =MAX(N60:R60,U60,V60) -> 0.9513 | AD60: =IF(W60<0.99,LARGE((N60:R60,U60,V60),2),"0") -> 0.0486 | AE60: =IF(AND(AB60<0.99,AD60>0.1),"admixed with",IF(AND(AB60<0.99,AD60>0.01),"trace admixed with ","")) -> trace admixed with | AH60: =_xlfn.CONCAT("Based on ADMIXTURE results of 78,187 SNPs, ",AE60,AC60) -> Based on ADMIXTURE results of 78,187 SNPs, trace admixed with
...

Sheet Sheet2
A1: genomeID | B1: Parent2
A2: Quercus prinoides Willd. | B2: Quercus macrocarpa
A3: Quercus prinoides Willd. | B3: Quercus macrocarpa
A4: Quercus prinoides Willd. | B4: Quercus macrocarpa
A5: Quercus prinoides Willd. | B5: Quercus macrocarpa
A6: Quercus macrocarpa Michx. | B6: Quercus muehlenbergii
A7: Quercus alba L. | B7: Quercus lobata
A8: Quercus macrocarpa Michx. | B8: Quercus lobata
A9: Quercus macrocarpa Michx. | B9: Quercus bicolor
A10: Quercus macrocarpa Michx. | B10: Quercus lobata
A11: Quercus margaretiae Ashe ex Small | B11: other oaks
A12: Quercus macrocarpa Michx. | B12: Quercus lobata
... A47: Quercus macrocarpa Michx. | B47: Quercus lobata

Sheet Sheet3
A1: genomeID | B1: Parent1 | C1: P1% | D1: Parent2 | E1: P2%
A2: Quercus macrocarpa Michx. | C2: 0.662507 | D2: Quercus bicolor | E2: 0.3374 | F2: =C2+E2 -> 0.999907
A3: Quercus macrocarpa Michx. | C3: 0.685731 | D3: Quercus bicolor | E3: 0.3142 | F3: =C3+E3 -> 0.999931
A4: Quercus bicolor Willd. | C4: 0.6945 | D4: Quercus macrocarpa | E4: 0.305473 | F4: =C4+E4 -> 0.999973
A5: Quercus bicolor Willd. | C5: 0.7059 | D5: Quercus alba | E5: 0.258 | F5: =C5+E5 -> 0.9639
A6: Quercus bicolor Willd. | C6: 0.7741 | D6: Quercus macrocarpa | E6: 0.225856 | F6: =C6+E6 -> 0.999956
A7: Quercus macrocarpa Michx. | C7: 0.775548 | D7: Quercus bicolor | E7: 0.2172 | F7: =C7+E7 -> 0.992748
A8: Quercus bicolor Willd. | C8: 0.801 | D8: Quercus macrocarpa | E8: 0.198956 | F8: =C8+E8 -> 0.999956
A9: Quercus macrocarpa Michx. | C9: 0.686284 | D9: Quercus muehlenbergii | E9: 0.1902 | F9: =C9+E9 -> 0.876484
A10: Quercus macrocarpa Michx. | C10: 0.817401 | D10: Quercus bicolor | E10: 0.1825 | F10: =C10+E10 -> 0.999901
A11: Quercus macrocarpa Michx. | C11: 0.679678 | D11: Quercus alba | E11: 0.1723 | F11: =C11+E11 -> 0.851978
A12: Quercus macrocarpa Michx. | C12: 0.823615 | D12: Quercus alba | E12: 0.1571 | F12: =C12+E12 -> 0.980715
A13: Quercus macrocarpa Michx. | C13: 0.848248 | D13: Quercus alba | E13: 0.1517 | F13: =C13+E13 -> 0.999948
... A47: Quercus macrocarpa Michx. | C47: 0.955063 | D47: Quercus lobata | E47: 0.0299 | F47: =C47+E47 -> 0.984963

Sheet Sheet1
A1: collectionNumber | B1: GenomicVoucherID_USE_THIS
A2: AR_BRP_409_MG | B2: Quercus lyrata Walt.
A3: AR_BRP_410_MG | B3: Quercus macrocarpa Michx.
A4: AR_BRP_411_MG | B4: Quercus stellata Wangenh.
A5: AR_BRP_412_MG | B5: Quercus macrocarpa Michx.
A6: AR_BRP_413_MG | B6: Quercus stellata Wangenh.
A7: AR_BRP_414_MG | B7: Quercus lyrata Walt.
A8: AR_BRP_415_MG | B8: Quercus alba L.
A9: AR_BRP_416_MG | B9: Quercus stellata Wangenh.
A10: AR_BRP_417_MG | B10: Quercus macrocarpa Michx.
A11: AR_BRP_418_MG | B11: Quercus lyrata Walt.
A12: AR_BRP_419_MG | B12: Quercus stellata Wangenh.
... A694: WI-MG541 | B694: Quercus macrocarpa Michx.
B695: Quercus lobata Nee.
B696: Quercus lobata Nee.
B697: Quercus lobata Nee.
B698: Quercus lobata Nee.
B699: Quercus lobata Nee.
B700: Quercus lobata Nee.
B701: Quercus lobata Nee.
B702: Quercus lobata Nee.
B703: Quercus lobata Nee.
B704: Quercus lobata Nee.
B705: Quercus lobata Nee.
B706: Quercus lobata Nee.
... B721: Quercus lobata Nee.
