Workbook

Sheet meta_pops_state
A1: state/provIndIowanace | B1: substate | C1: site | D1: collectionNumber | F1: Pop
A2: Arkansas | B2: Pulaski | C2: Burns Park, Little Rock | D2: AR | E2: BRP | F2: =_xlfn.CONCAT(D2,"_",E2) -> AR_BRP
A3: Iowa | B3: Story | C3: Brookside Park | D3: IA | E3: BSP | F3: =_xlfn.CONCAT(D3,"_",E3) -> IA_BSP
A4: Iowa | B4: Linn | C4: Cherokee Park | D4: IA | E4: CHP | F4: =_xlfn.CONCAT(D4,"_",E4) -> IA_CHP
A5: Iowa | B5: Van Buren | C5: Lindsay Wilderness | D5: IA | E5: LNW | F5: =_xlfn.CONCAT(D5,"_",E5) -> IA_LNW
A6: Illinois | B6: Douglas | C6: Chickenbristle | D6: IL | E6: CHB | F6: =_xlfn.CONCAT(D6,"_",E6) -> IL_CHB
A7: Illinois | B7: Johnson | C7: Heron Pond - Little Black Slough Nature Preserve | D7: IL | E7: HP | F7: =_xlfn.CONCAT(D7,"_",E7) -> IL_HP
A8: Illinois | B8: DuPage | C8: The Morton Arboretum | D8: IL | E8: MOR | F8: =_xlfn.CONCAT(D8,"_",E8) -> IL_MOR
A9: Illinois | B9: Jackson | C9: Oakwood Bottoms, Shawnee National Forest | D9: IL | E9: OB | F9: =_xlfn.CONCAT(D9,"_",E9) -> IL_OB
A10: Illinois | B10: Lake | C10: Ryerson Conservation Area | D10: IL | E10: RCA | F10: =_xlfn.CONCAT(D10,"_",E10) -> IL_RCA
A11: Indiana | B11: Monroe | C11: Bayles Road Research and Teaching Preserve | D11: IN | E11: BLR | F11: =_xlfn.CONCAT(D11,"_",E11) -> IN_BLR
A12: Indiana | B12: Monroe | C12: Griffy Lake Research and Teaching Preserve | D12: IN | E12: GRL | F12: =_xlfn.CONCAT(D12,"_",E12) -> IN_GRL
A13: Indiana | B13: Monroe | C13: Indiana University Campus | D13: IN | E13: IUC | F13: =_xlfn.CONCAT(D13,"_",E13) -> IN_IUC
... A32: Massachusetts | B32: Berkshire | C32: Schenob Brook Fen | D32: MA | E32: SBF | F32: =_xlfn.CONCAT(D32,"_",E32) -> MA_SBF
A33: Manitoba | C33: Whiteshell Provincial Park | D33: MB | E33: WPP | F33: =_xlfn.CONCAT(D33,"_",E33) -> MB_WPP
A34: Manitoba | C34: Spruce Woods Provincial Park | D34: MB | E34: SWP | F34: =_xlfn.CONCAT(D34,"_",E34) -> MB_SWP
A35: Manitoba | C35: Assiniboine Forest, near parking lot/entrance to trail | D35: MB | E35: ASF | F35: =_xlfn.CONCAT(D35,"_",E35) -> MB_ASF
A36: Oklahoma | B36: Caddo | C36: Red Rock Canyon Adventure Park | D36: OK | E36: RRC | F36: =_xlfn.CONCAT(D36,"_",E36) -> OK_RRC
A37: Michigan | B37: Ingham | C37: Lake Lansing Park | D37: MI | E37: LLP | F37: =_xlfn.CONCAT(D37,"_",E37) -> MI_LLP
A38: Michigan | B38: Washtenaw | C38: Pinckney Recreation Area | D38: MI | E38: PRA | F38: =_xlfn.CONCAT(D38,"_",E38) -> MI_PRA
A39: Michigan | B39: Bay | C39: Pinconning Park, Campground | D39: MI | E39: PCP | F39: =_xlfn.CONCAT(D39,"_",E39) -> MI_PCP
A40: Kansas | B40: Russell | C40: Minooka Park Recreation Area | D40: KS | E40: MPR | F40: =_xlfn.CONCAT(D40,"_",E40) -> KS_MPR
A41: Minnesota | B41: Anoka | C41: Cedar Creek Research Station | D41: MN | E41: CDR | F41: =_xlfn.CONCAT(D41,"_",E41) -> MN_CDR
A42: Minnesota | B42: Winona | C42: Prairie Moon Nursery | D42: MN | E42: PMN | F42: =_xlfn.CONCAT(D42,"_",E42) -> MN_PMN
A43: Minnesota | B43: Le Sueur | C43: Ottawa Bluffs | D43: MN | E43: OTB | F43: =_xlfn.CONCAT(D43,"_",E43) -> MN_OTB
A44: Missouri | B44: Mississipi | C44: Big Oak Tree State Park | D44: MO | E44: BOT | F44: =_xlfn.CONCAT(D44,"_",E44) -> MO_BOT
A45: Missouri | B45: St. Louis | C45: Castlewood State Park | D45: MO | E45: CSW | F45: =_xlfn.CONCAT(D45,"_",E45) -> MO_CSW
A46: Missouri | B46: Camden | C46: Ha Ha Tonka State Park | D46: MO | E46: HHT | F46: =_xlfn.CONCAT(D46,"_",E46) -> MO_HHT
A47: Missouri | B47: Barton | C47: Prairie State Park | D47: MO | E47: PSP | F47: =_xlfn.CONCAT(D47,"_",E47) -> MO_PSP
... A72: Wisconsin | B72: Sawyer | C72: Round Lake, Chequamegon-Nicolet National Forest | D72: WI | E72: RLF | F72: =_xlfn.CONCAT(D72,"_",E72) -> WI_RLF

Sheet SpeciesPerPop
A1: Pop
A2: AR_BRP
A3: IA_BSP
A4: IA_CHP
A5: IA_LNW
A6: IL_CHB
A7: IL_HP
A8: IL_MOR
A9: IL_OB
A10: IL_RCA
A11: IN_BLR
A12: IN_GRL
... A72: WI_RLF

Sheet Sheet2
A1: Notes
A2: 45775 | B2: Realized that MN Ottawa bluffs and MN Quarry Park Area were both under OTB. Changed Quarry Park Area to QPA

Sheet Sheet3
A1: specimen_id | B1: _record_id | C1: _title | D1: _server_updated_at | E1: _updated_by | F1: _geometry | G1: _latitude | H1: _longitude | I1: putative_species | J1: state | K1: site_name | L1: site_code | M1: tag_id | N1: collector_initials | O1: specimen_id | P1: date | Q1: dbh | R1: height | S1: reproductive_status | T1: presence_of_galls | U1: tally_of_woody_stems_ | V1: other_associated_plant_species | W1: habitat_description | X1: herbarium_specimens_collected | Y1: leaf_samples_collected | Z1: soil_samples_collected | AA1: root_samples_collected | AB1: leaf_and_reproductive_structure_photos | AC1: gall_photos | AD1: whole_tree_photos | AE1: stem_or_bark_photos | AF1: soil_sample_vegetation_photos | AG1: surrounding_tree_photos | AH1: collectorss | AI1: collector_number | AJ1: notes | AK1: verified_species_id | AL1: verified_by | AM1: date_verified | AN1: det_notes | AO1: seconddate | AP1: tree_tag_number
A2: UT_RBC_1_IP | B2: 93fbcc5a-26f0-463c-a82c-6208321f93b4 | C2: Quercus gambelii | D2: 2024-11-20 22:32:12 UTC | E2: FAB ACE | F2: SRID=4326;POINT(-111.8224849 40.7700262) | G2: 40.770026 | H2: -111.82248 | I2: Quercus gambelii | J2: UT | K2: Red Butte Canyon | L2: RBC | M2: 1 | N2: IP | O2: UT_RBC_1_IP | P2: 45543 | Q2: 10 | V2: mostly Q. gambelii | W2: Q. gambelii patch in oak scrubland/savannah near arboretum | X2: yes | Y2: yes | Z2: no | AA2: no | AH2: "Ian Pearse, Marion Pearse, Soren Pearse, Asa Pearse, Jill Baty" | AI2: 269 | AJ2: GPS approximate; Soren's tree
A3: UT_RBC_4_IP | B3: f9c19e6c-943a-4510-ba68-347ab0b9780b | C3: Quercus gambelii | D3: 2024-11-20 22:32:02 UTC | E3: FAB ACE | F3: SRID=4326;POINT(-111.824162 40.76877907) | G3: 40.768779 | H3: -111.82416 | I3: Quercus gambelii | J3: UT | K3: Red Butte Canyon | L3: RBC | M3: 4 | N3: IP | O3: UT_RBC_4_IP | P3: 45543 | Q3: 7 | V3: mostly Q. gambelii | W3: Q. gambelii patch in oak scrubland/savannah near arboretum | X3: yes | Y3: yes | Z3: no | AA3: no | AH3: "Ian Pearse, Marion Pearse, Soren Pearse, Ava Pearse, Jill Baty" | AI3: 272 | AJ3: GPS approximate; Ian's tree
A4: UT_RBC_2_IP | B4: 0bc594a8-299f-4ad3-860c-ea8ae739be69 | C4: Quercus gambelii | D4: 2024-11-20 22:31:53 UTC | E4: FAB ACE | F4: SRID=4326;POINT(-111.822713 40.769849) | G4: 40.769849 | H4: -111.82271 | I4: Quercus gambelii | J4: UT | K4: Red Butte Canyon | L4: RBC | M4: 2 | N4: IP | O4: UT_RBC_2_IP | P4: 45543 | Q4: 14 | V4: mostly Q. gambelii | W4: Q. gambelii patch in oak scrubland/savannah near arboretum | X4: yes | Y4: yes | Z4: no | AA4: no | AH4: "Ian Pearse, Marion Pearse, Soren Pearse, Asa Pearse, Jill Baty" | AI4: 270 | AJ4: GPS approximate; Jill's tree
A5: UT_RBC_3_IP | B5: cf7bc6ab-89e1-49a5-b2f0-0ed70006654e | C5: Quercus gambelii | D5: 2024-11-20 22:31:41 UTC | E5: FAB ACE | F5: SRID=4326;POINT(-111.8233167 40.76940281) | G5: 40.769403 | H5: -111.82332 | I5: Quercus gambelii | J5: UT | K5: Red Butte Canyon | L5: RBC | M5: 3 | N5: IP | O5: UT_RBC_3_IP | P5: 45543 | Q5: 10 | V5: mostly Q. gambelii | W5: Q. gambelii patch in oak scrubland/savannah near arboretum | X5: yes | Y5: yes | Z5: no | AA5: no | AH5: "Ian Pearse, Marion Pearse, Soren Pearse, Asa Pearse, Jill Baty" | AI5: 271 | AJ5: GPS approximate; Asa's tree
A6: UT_RBC_5_IP | B6: 2261ace5-8ee5-4de4-b652-e32b28df236d | C6: Quercus gambelii | D6: 2024-11-20 22:31:22 UTC | E6: FAB ACE | F6: SRID=4326;POINT(-111.82476 40.7682612) | G6: 40.768261 | H6: -111.82476 | I6: Quercus gambelii | J6: UT | K6: Red Butte Canyon | L6: RBC | M6: 5 | N6: IP | O6: UT_RBC_5_IP | P6: 45543 | Q6: 10 | V6: mostly Q. gambelii | W6: Q. gambelii patch in oak scrubland/savannah near arboretum | X6: yes | Y6: yes | Z6: no | AA6: no | AH6: "Ian Pearse, Marion Pearse, Soren Pearse, Asa Pearse, Jill Baty" | AI6: 273 | AJ6: GPS approximate; Marion's tree
A7: CA_DC_1_LJ | B7: 113b3681-69e0-40d0-a5e5-7e72a794c780 | C7: Quercus garryana var. semota | D7: 2024-11-20 22:31:08 UTC | E7: FAB ACE | F7: SRID=4326;POINT(-121.60261 40.15967) | G7: 40.15967 | H7: -121.60261 | I7: Quercus garryana var. semota | J7: CA | K7: Deer Creek | L7: DC | M7: 1 | N7: LJ | O7: CA_DC_1_LJ | P7: 45571 | Q7: 10 | R7: 4 | U7: Quercus garryana var. breweri | V7: Pinus ponderosa, Pseudotsuga menziensii, Quercus kelloggii, Calocedrus decurrens. Shrubs within 10 m: Cercocarpus betuloides, Cercis occidentalis, Toxicodendron diversilobum, Quercus garryana var. breweri, Philadelphus lewisii, ┬┐Prunus cf. subcordata? | W7: Oak woodland denoted by Brewer Oak surrounded by mixed conifer forest. Substrate: volcanic (andesitic ash flow?) elevation: 1028 m | X7: yes | Y7: yes | Z7: no | AA7: no | AG7: e54bb977-0482-464d-9379-79c246e9c0ae,e811182a-eaf6-406b-a8fb-862e6907d621,cee31da0-52fe-4097-b204-99841f291580 | AH7: Lawrence Janeway | AI7: 15103-1 | AJ7: Locality: High Cascade Range. Slope above Road 27N08 (road from Hwy 32 across Deer Creek toward Onion Butte), 2.3 road-km east of the major hairpin turn where road starts dropping into the canyon. WGS84
A8: CA_DC_4_LJ | B8: 9d4c01ac-87f1-4595-b740-fb8133797ad4 | C8: Quercus garryana var. semota | D8: 2024-11-20 22:30:56 UTC | E8: FAB ACE | F8: SRID=4326;POINT(-121.60216 40.15929) | G8: 40.15929 | H8: -121.60216 | I8: Quercus garryana var. semota | J8: CA | K8: Deer Creek | L8: DC | M8: 4 | N8: LJ | O8: CA_DC_4_LJ | P8: 45571 | Q8: 12 | R8: 4 | U8: Quercus garryana var. breweri, sapling of Calocedrus decurrens | V8: Pinus ponderosa, Pseudotsuga menziensii, Quercus kelloggii, Calocedrus decurrens; shrubs: Cercocarpus betuloides, Prunus cf. subcordata?, Cercis occidentalis | W8: Steep east-northeast facing slope of shrubby (mountain mahogany, Brewer oak, redbud), grassy openings, and rock outcrops, surrounded by mixed conifer forest (Ponderosa pine, Douglas-fir, black oak, incense cedar). Substrate: volcanic (andesitic ash flow?) Elevation: 1018 m | X8: yes | Y8: yes | Z8: no | AA8: no | AG8: e8080bdd-1ce0-45bd-9a0a-5341e4a20f09,2d55f0aa-6978-4ac0-afb0-dbbc46d86599,ac8fd2c8-efc8-4814-898d-2aa1d7b0f131 | AH8: Lawrence P. Janeway | AI8: 15103-4 | AJ8: Locality: High Cascade Range. Slope above Road 27N08 (road from Hwy 32 across Deer Creek toward Onion Butte), 2.3 road-km east of the major hairpin turn where road starts dropping into the canyon. WGS84
A9: CA_DC_3_LJ | B9: b6ec0991-ce5b-4ca3-abea-16b5f43eae79 | C9: Quercus garryana var. semota | D9: 2024-11-20 22:30:47 UTC | E9: FAB ACE | F9: SRID=4326;POINT(-121.60221 40.15947) | G9: 40.15947 | H9: -121.60221 | I9: Quercus garryana var. semota | J9: CA | K9: Deer Creek | L9: DC | M9: 3 | N9: LJ | O9: CA_DC_3_LJ | P9: 45571 | Q9: 10 | R9: 3.5 | U9: Quercus garryana var. breweri, Quercus chrysolepis, small Pseudotsuga menziesii | V9: Pinus ponderosa, Pseudotsuga menziensii, Quercus kelloggii, Calocedrus decurrens; shrubs: Cercocarpus betuloides, Cercis occidentalis | W9: Steep east-northeast facing slope of shrubby (mountain mahogany, Brewer oak, redbud), grassy openings, and rock outcrops, surrounded by mixed conifer forest (Ponderosa pine, Douglas-fir, black oak, incense cedar). Substrate: volcanic (andesitic ash flow?) Elevation: 1007 m | X9: yes | Y9: yes | Z9: n/a | AA9: no | AD9: bfd73288-699b-481b-83cd-8f4e87329e45 | AG9: de4ac3ab-0a7f-4a8a-9c4a-428bba154b5b,306f73c9-647f-471c-848c-2f78eed19a58,04f2e21d-6f97-4e68-97d5-98b4f5da436e | AH9: Lawrence P. Janeway | AI9: 15103-3 | AJ9: Locality: High Cascade Range. Slope above Road 27N08 (road from Hwy 32 across Deer Creek toward Onion Butte), 2.3 road-km east of the major hairpin turn where road starts dropping into the canyon. WGS84
A10: CA_DC_5_LJ | B10: b8039ee4-57c6-45a5-bc32-71e667411c06 | C10: Quercus garryana var. semota | D10: 2024-11-20 22:30:37 UTC | E10: FAB ACE | F10: SRID=4326;POINT(-121.6022 40.15957) | G10: 40.15957 | H10: -121.6022 | I10: Quercus garryana var. semota | J10: CA | K10: Deer Creek | L10: DC | M10: 5 | N10: LJ | O10: CA_DC_5_LJ | P10: 45571 | Q10: 12 | R10: 5 | U10: Quercus garryana var. breweri | V10: Pinus ponderosa, Pseudotsuga menziensii, Quercus kelloggii, Calocedrus decurrens; shrubs: Cercocarpus betuloides, Quercus garryana var. breweri, Prunus cf. subcordata?, Cercis occidentalis, Philadelphus lewisii | W10: Steep east-northeast facing slope of shrubby (mountain mahogany, Brewer oak, redbud), grassy openings, and rock outcrops, surrounded by mixed conifer forest (Ponderosa pine, Douglas-fir, black oak, incense cedar). Substrate: volcanic (andesitic ash flow?) Elevation: 1012 m | X10: yes | Y10: yes | Z10: no | AA10: no | AD10: 60ef7461-955d-4826-821e-686092cfcfc4 | AG10: 66c2f4c8-dd8e-4e7b-a930-a7d959651f1b,14307c5c-105a-47f3-bea6-17657e699565,b2de26de-8955-4dde-b93a-467a9da83f79 | AH10: Lawrence P. Janeway | AI10: 15103-5 | AJ10: Closest samples to the dusty road - leaves dusty; Locality: High Cascade Range. Slope above Road 27N08 (road from Hwy 32 across Deer Creek toward Onion Butte), 2.3 road-km east of the major hairpin turn where road starts dropping into the canyon. WGS84
A11: CA_RH_2_LJ | B11: 7aca9f1d-7790-43a0-9e57-189c31377359 | C11: Quercus garryana var. breweri | D11: 2024-11-20 22:30:27 UTC | E11: FAB ACE | F11: SRID=4326;POINT(-121.15902 40.04045) | G11: 40.04045 | H11: -121.15902 | I11: Quercus garryana var. breweri | J11: CA | K11: Red Hill | L11: RH | M11: 2 | N11: LJ | O11: CA_RH_2_LJ | P11: 45571 | R11: 2 | U11: Only burned remains | V11: Pseudotsuga menziensii, Pinus lambertiana, Pinus jeffreyi, Calocedrus decurrens; shrubs:Garrya fremontii, Ceanothus integerrimus, Quercus garryana var. breweri, Ceanothus arcuatus | W11: Southeast-facing slope of rocky red soil serpentine; very open forest of Douglas-fir, sugar pine, Jeffrey pine, incense cedar. Elevation: 1606 | X11: yes | Y11: yes | Z11: no | AA11: no | AD11: cdc67724-762d-4eb3-aca9-dfcdc455db68 | AG11: 25a8895f-0adc-4926-a09d-acd1e8291b43,f6fff36a-5c9b-4efa-b326-56644a2b4b39,9745bec7-6e24-4bf3-9546-a73d893f6619,ca744652-df17-435a-aa4c-1409ab9494f3 | AH11: Lawrence P. Janeway | AI11: 15104-2 | AJ11: Multi-stemmed shrub, leaves and voucher all from one stem; Locality: Northern High Sierra Nevada. Along Road 26N22F (to top of Red Hill) 2.4 road-km from Deadwood Saddle; 2.6 air-km east of the summit of Red Hill. WGS84
A12: CA_RH_1_LJ | B12: c4c8fd72-c625-4b48-a20f-e3f90e7ab2cb | C12: Quercus garryana var. breweri | D12: 2024-11-20 22:30:16 UTC | E12: FAB ACE | F12: SRID=4326;POINT(-121.15899 40.04064) | G12: 40.04064 | H12: -121.15899 | I12: Quercus garryana var. breweri | J12: CA | K12: Red Hill | L12: RH | M12: 1 | N12: LJ | O12: CA_RH_1_LJ | P12: 45571 | R12: 2 | U12: Pinus jeffreyi and fire-kills, plus seedlings of Pinus jeffreyi anjd Calocedrus decurrens | V12: Pseudotsuga menziensii, Pinus lambertiana, Pinus jeffreyi, Calocedrus decurrens; shrubs:Ceanothus arcuatus, Quercus garryana var. breweri, Garrya fremontii, Ceanothus integerrimus, Ribes roezlii | W12: Southeast-facing slope of rocky red soil serpentine; very open forest of Douglas-fir, sugar pine, Jeffrey pine, incense cedar. Elevation 1611 m | X12: yes | Y12: yes | Z12: no | AA12: no | AD12: e430e0cf-945d-4514-a84e-03d481d290a3,09b334ca-e4f4-404c-a565-21c58e568110 | AG12: c87030dd-aed8-4239-b736-eac51620414b,fb9fd2eb-e2da-4a73-8669-9061d6357212,108eb5e0-9d97-4a34-9c14-a184f0c13f55,832b1c23-6d17-44c7-8f3a-b9ac30eef672 | AH12: Lawrence P. Janeway | AI12: 15104-1 | AJ12: Mostly one main stem and some longer branching from base. Probably same size before fire but stump sprouted now. Locality: Northern High Sierra Nevada. Along Road 26N22F (to top of Red Hill) 2.4 road-km from Deadwood Saddle; 2.6 air-km east of the summit of Red Hill. WGS84
A13: CA_RH_3_LJ | B13: 4e28465b-ca0c-4098-86ff-2e7c29972647 | C13: Quercus garryana var. breweri | D13: 2024-11-20 22:29:53 UTC | E13: FAB ACE | F13: SRID=4326;POINT(-121.15919 40.04031) | G13: 40.04031 | H13: -121.15919 | I13: Quercus garryana var. breweri | J13: CA | K13: Red Hill | L13: RH | M13: 3 | N13: LJ | O13: CA_RH_3_LJ | P13: 45571 | U13: Calocedrus decurrens, Pinus jeffreyi, Pseudotsuga menziensii including saplings | V13: Pseudotsuga menziensii, Pinus lambertiana, Pinus jeffreyi, Calocedrus decurrens; shrubs: Ceanothus integerrimus, Ceanothus arcuatus, Quercus garryana var. breweri, Arctostaphylos viscida, Garrya fremontii | W13: Southeast-facing slope of rocky red soil serpentine; very open forest of Douglas-fir, sugar pine, Jeffrey pine, incense cedar. Elevation: 1616 m | X13: yes | Y13: yes | Z13: no | AA13: no | AG13: a08b5636-eab6-4d7a-b58a-359a852d87ff,898a7136-1ce6-421d-aff9-ee6af74244d0,8496f69f-3728-4869-9a86-131e73c8f86f,84e59a8c-d31d-45e8-b11f-adc1de5b313c | AH13: Lawrence P. Janeway | AI13: 15104-3 | AJ13: Shrub with multiple branches, especially from base. All samples and voucher from one stem. Locality: Northern High Sierra Nevada. Along Road 26N22F (to top of Red Hill) 2.4 road-km from Deadwood Saddle; 2.6 air-km east of the summit of Red Hill. WGS84
A14: CA_RH_4_LJ | B14: 667a581d-90fb-441f-9f9f-bb6e00a8797d | C14: Quercus garryana var. breweri | D14: 2024-11-20 22:29:44 UTC | E14: FAB ACE | F14: SRID=4326;POINT(-121.15841 40.0403) | G14: 40.0403 | H14: -121.15841 | I14: Quercus garryana var. breweri | J14: CA | K14: Red Hill | L14: RH | M14: 4 | N14: LJ | O14: CA_RH_4_LJ | P14: 45571 | Q14: 3 | R14: 1 | V14: Pseudotsuga menziensii, Pinus lambertiana, Pinus jeffreyi, Calocedrus decurrens; shrubs: Quercus garryana var. breweri, Ceanothus integerrimus, Garrya fremontii, Ceanothus arcuatus | W14: Southeast-facing slope of rocky red soil serpentine; very open forest of Douglas-fir, sugar pine, Jeffrey pine, incense cedar. Elevation: 1599 m | X14: yes | Y14: yes | Z14: no | AA14: no | AG14: 35e65f81-30ea-4d52-a266-3cdc881e8f7b,b59b6864-8509-4a3c-8728-452ac077affa,39767878-1419-4c83-b19f-cff9d7098676,7978d2ca-b0e9-4d3b-9531-4565c019a7d9 | AH14: Lawrence P. Janeway | AI14: 15104-4 | AJ14: Locality: Northern High Sierra Nevada. Along Road 26N22F (to top of Red Hill) 2.4 road-km from Deadwood Saddle; 2.6 air-km east of the summit of Red Hill. WGS84
A15: CA_RH_5_LJ | B15: 0cad1ff6-02a4-4b36-9f41-9d2dc115dc7e | C15: Quercus garryana var. breweri | D15: 2024-11-20 22:29:35 UTC | E15: FAB ACE | F15: SRID=4326;POINT(-121.15865 40.04015) | G15: 40.04015 | H15: -121.15865 | I15: Quercus garryana var. breweri | J15: CA | K15: Red Hill | L15: RH | M15: 5 | N15: LJ | O15: CA_RH_5_LJ | P15: 45571 | Q15: 4 | R15: 3 | U15: remnant conifer boles | V15: Pseudotsuga menziensii, Pinus lambertiana, Pinus jeffreyi, Calocedrus decurrens; shrubs: Quercus garryana var. breweri, Ceanothus integerrimus, Garrya fremontii, Ceanothus arcuatus | W15: Southeast-facing slope of rocky red soil serpentine; very open forest of Douglas-fir, sugar pine, Jeffrey pine, incense cedar. Elevation: 1596 m | X15: yes | Y15: yes | Z15: no | AA15: no | AG15: f9850a3a-6a41-4b65-ae41-0fb27a8dd4e5,3f2d377d-b8a7-4fe2-82bc-a89e48552c7e,9719ed05-2916-4832-8820-050959a18aa0,200d5d0e-3207-4f1f-88df-12d544aebefb | AH15: Lawrence P. Janeway | AI15: 15104-5 | AJ15: 3 main stems, leaves and voucher from one stem. Locality: Northern High Sierra Nevada. Along Road 26N22F (to top of Red Hill) 2.4 road-km from Deadwood Saddle; 2.6 air-km east of the summit of Red Hill. WGS84
A16: CA_WW_2_LJ | B16: 05db1107-c132-4a01-bbda-bbfee6529faf | C16: Quercus garryana var. semota | D16: 2024-11-20 22:29:25 UTC | E16: FAB ACE | F16: SRID=4326;POINT(-123.00089 40.40159) | G16: 40.40159 | H16: -123.00089 | I16: Quercus garryana var. semota | J16: CA | K16: Wildwood | L16: WW | M16: 2 | N16: LJ | O16: CA_WW_2_LJ | P16: 45572 | Q16: 9 | R16: 4.5 | U16: Quercus garryana var. breweri, Quercus wislizeni var. frutescens | V16: shrubs: Cercocarpus betuloides, few low Quercus garryana var. breweri, Ceanothus arcuatus | W16: Small open southwest-sloping serpentine outcrop, but the shrubby areas are on the adjacent non-serpentine metamorphic substrate; shallow gravelly soil; surrounded by mixed conifer forest. Elevation: 1356 m | X16: yes | Y16: yes | Z16: no | AA16: no | AG16: 4a80cd46-8a76-4f14-95f9-00305c3a9be7,63fb593a-c60a-4f97-8c58-b5099096a49d,f3c7e9d4-f317-4679-89e6-6d8b4faef81e | AH16: Lawrence P. Janeway | AI16: 15105-2 | AJ16: A few Quercus garryana var. breweri appear stressed; Either end of summer drought stress or early fall cool nights stress. Locality: Klamath Ranges. Along Road 30N15 0.1 km northwest of Road 30N01; 4.9 air-km east of Wildwood. WGS84
A17: CA_WW_1_LJ | B17: de70a4e3-c3bf-48f8-865c-76def134ebef | C17: Quercus garryana var. semota | D17: 2024-11-20 22:29:14 UTC | E17: FAB ACE | F17: SRID=4326;POINT(-123.00067 40.40157) | G17: 40.40157 | H17: -123.00067 | I17: Quercus garryana var. semota | J17: CA | K17: Wildwood | L17: WW | M17: 1 | N17: LJ | O17: CA_WW_1_LJ | P17: 45572 | R17: 1 | U17: small Quercus garryana var. breweri | V17: shrubs: Cercocarpus betuloides, Quercus garryana var. breweri | W17: Small open southwest-sloping serpentine outcrop, but the shrubby areas are on the adjacent non-serpentine metamorphic substrate; shallow gravelly soil; surrounded by mixed conifer forest. Elevation: 1364 m | X17: yes | Y17: yes | Z17: no | AA17: no | AD17: c37ab8eb-ddc2-474a-8886-353637807f63,3e4cc372-9ff9-46f9-8c3e-4788415ff00f | AG17: a8fc8f96-f1af-4f96-ac76-137511496280,07858777-203a-4f5a-a0d3-b5a9d0213e6a,b80fcd0a-b979-4658-83c1-8d856165a263 | AH17: Lawrence P. Janeway | AI17: 15105-1 | AJ17: Common multi-branched low shrubs. Leaves and voucher from one stem. Locality: Klamath Ranges. Along Road 30N15 0.1 km northwest of Road 30N01; 4.9 air-km east of Wildwood. WGS84
A18: CA_WW_3_LJ | B18: 1ca352b8-b8f4-4509-9dbf-5d5e0ec8b0ff | C18: Quercus garryana var. semota | D18: 2024-11-20 22:29:05 UTC | E18: FAB ACE | F18: SRID=4326;POINT(-123.00063 40.40097) | G18: 40.40097 | H18: -123.00063 | I18: Quercus garryana var. semota | J18: CA | K18: Wildwood | L18: WW | M18: 3 | N18: LJ | O18: CA_WW_3_LJ | P18: 45572 | Q18: 1 | R18: 23 | U18: Quercus wislizeni var. frutescens | V18: shrubs: Ceanothus arcuatus, Cercocarpus betuloides, Quercus garryana var. breweri | W18: Small open southwest-sloping serpentine outcrop, but the shrubby areas are on the adjacent non-serpentine metamorphic substrate; shallow gravelly soil; surrounded by mixed conifer forest. Elevation: 1353 m | X18: yes | Y18: yes | Z18: no | AA18: no | AG18: edc9537f-c304-4289-895a-96ef388a0366,86cae053-96d5-4621-a1c3-2b7c0c6e5e2f,3e65a541-ff38-47f6-afeb-9c5d32a59578 | AH18: Lawrence P. Janeway | AI18: 15105-3 | AJ18: Locality: Klamath Ranges. Along Road 30N15 0.1 km northwest of Road 30N01; 4.9 air-km east of Wildwood. WGS84
A19: CA_WW_4_LJ | B19: af332df9-5640-4792-bf50-2c220c4fe327 | C19: Quercus garryana var. semota | D19: 2024-11-20 22:28:53 UTC | E19: FAB ACE | F19: SRID=4326;POINT(-123.00058 40.40084) | G19: 40.40084 | H19: -123.00058 | I19: Quercus garryana var. semota | J19: CA | K19: Wildwood | L19: WW | M19: 4 | N19: LJ | O19: CA_WW_4_LJ | P19: 45572 | R19: 1 | V19: shrubs: Quercus garryana var. breweri, Cercocarpus betuloides, Ceanothus arcuatus, Quercus wislizeni var. frutescens | W19: Small open southwest-sloping serpentine outcrop, but the shrubby areas are on the adjacent non-serpentine metamorphic substrate; shallow gravelly soil; surrounded by mixed conifer forest. Elevation: 1343 m | X19: yes | Y19: yes | Z19: no | AA19: no | AG19: 41861dde-aa4f-420b-a838-821afc4e6665,285d977f-bf4a-44b9-b892-4e0fed764ad2,f2ceb207-e5fa-46cb-9c7b-a3c5ce424fb4 | AH19: Lawrence P. Janeway | AI19: 15105-4 | AJ19: Common multi-branched low shrub. Leaves and voucher from one stem. Locality: Klamath Ranges. Along Road 30N15 0.1 km northwest of Road 30N01; 4.9 air-km east of Wildwood. WGS84
A20: CA_WW_5_LJ | B20: 40d655aa-c7cc-45a8-b7fe-3810ca7ff848 | C20: Quercus garryana var. semota | D20: 2024-11-20 22:28:43 UTC | E20: FAB ACE | F20: SRID=4326;POINT(-123.00037 40.40076) | G20: 40.40076 | H20: -123.00037 | I20: Quercus garryana var. semota | J20: CA | K20: Wildwood | L20: WW | M20: 5 | N20: LJ | O20: CA_WW_5_LJ | P20: 45572 | Q20: 10 | R20: 4 | U20: Quercus garryana var. breweri | V20: shrubs: Quercus garryana var. breweri, Cercocarpus betuloides, Ceanothus arcuatus | W20: Small open southwest-sloping serpentine outcrop, but the shrubby areas are on the adjacent non-serpentine metamorphic substrate; shallow gravelly soil; surrounded by mixed conifer forest. Elevation: 1354 m | X20: yes | Y20: yes | Z20: no | AA20: no | AG20: 20f0f1f3-8d01-4902-8acb-10abc3637c74,1dbfc3d5-e510-4e02-a682-754f5319d593,3f95a6f5-0823-4264-b39a-4f3e90f8bc97 | AH20: Lawrence P. Janeway | AI20: 15105-5 | AJ20: Locality: Klamath Ranges. Along Road 30N15 0.1 km northwest of Road 30N01; 4.9 air-km east of Wildwood. WGS84
A21: CA_BR_1_LJ | B21: 108cb359-3b6d-435d-86eb-fc877ecbbb18 | C21: Quercus garryana var. breweri | D21: 2024-11-20 22:28:17 UTC | E21: FAB ACE | F21: SRID=4326;POINT(-122.94738 39.90052) | G21: 39.90052 | H21: -122.94738 | I21: Quercus garryana var. breweri | J21: CA | K21: Buck Rock | L21: BR | M21: 1 | N21: LJ | O21: CA_BR_1_LJ | P21: 45573 | Q21: -2 | R21: 1.5 | U21: Abies concolor, small Calocedrus decurrens | V21: Abies concolor, Ponderosa pine, Calocedrus decurrens, occasional Pinus lambertiana; shrubs: Quercus garryana var. breweri, Amelanchier utahensis, Ceanothus cordulatus, Prunus emarginata | W21: Open gravelly ridgeline in white fir dominated mixed conifer forest (white fir, Ponderosa pine, incense cedar, occasional sugar pine). Elevation: 1898 m | X21: yes | Y21: yes | Z21: no | AA21: no | AD21: b9530cfe-6894-43da-8982-c7ffceedd1fd | AG21: 587e05a6-5b86-41d8-8439-84ca8f4f4ff3,44d31edf-7c06-4177-887c-a8cc406204f8,813811a2-882f-488f-a8f9-95b249e98ca0,73581397-daa7-4c7b-a92a-0af01ee850d7,51cff253-3447-483b-bde0-da9904de2e08,9721e408-f2bd-4928-a6c6-155e62514cef | AH21: Lawrence P. Janeway | AI21: 15108-1 | AJ21: Locality: High North Coast Ranges. Along ┬▒ open ridgeline 0.6 mi south of Buck Rock. WGS84
A22: CA_BR_2_LJ | B22: 0692a142-172d-4f61-83de-99cbff73644a | C22: Quercus garryana var. breweri | D22: 2024-11-20 22:28:07 UTC | E22: FAB ACE | F22: SRID=4326;POINT(-122.94776 39.90083) | G22: 39.90083 | H22: -122.94776 | I22: Quercus garryana var. breweri | J22: CA | K22: Buck Rock | L22: BR | M22: 2 | N22: LJ | O22: CA_BR_2_LJ | P22: 45573 | R22: 0.8 | V22: Abies concolor, Ponderosa pine, Calocedrus decurrens, occasional Pinus lambertiana. shrubs: Quercus garryana var. breweri, Sambucus mexicana var. cerulea, Ceanothus cordulatus, Prunus emarginata, Ribes roezlii, Rubus leucodermis, Arctostaphylos canescens | W22: Open gravelly ridgeline in white fir dominated mixed conifer forest (white fir, Ponderosa pine, incense cedar, occasional sugar pine). Elevation: 1913 m | X22: yes | Y22: yes | Z22: no | AA22: no | AG22: e935f345-8c2b-469c-b607-240b41e43eee,506b7ae6-12f2-434c-8c14-cb0b88f64afe,c074a3ad-eed9-469f-a3e5-b038605f609f,a3a1231f-4308-478e-831b-258dffe1a595,248533fa-82a6-4f56-9934-562f043d9614,60f5cf65-a2d9-4901-a0a9-5513d6e3b68a | AH22: Lawrence P. Janeway | AI22: 15108-2 | AJ22: Multi-stemmed shrub ranges in height 5-8 dm tall. Leaves and voucher from one stem. Locality: High North Coast Ranges. Along ┬▒ open ridgeline 0.6 mi south of Buck Rock. WGS84
A23: CA_BR_3_LJ | B23: b3383061-fdf9-447d-88f7-833e8c357c2c | C23: Quercus garryana var. breweri | D23: 2024-11-20 22:27:55 UTC | E23: FAB ACE | F23: SRID=4326;POINT(-122.94785 39.9005) | G23: 39.9005 | H23: -122.94785 | I23: Quercus garryana var. breweri | J23: CA | K23: Buck Rock | L23: BR | M23: 3 | N23: LJ | O23: CA_BR_3_LJ | P23: 45573 | R23: 1.2 | U23: Abies concolor, sapling Calocedrus decurrens | V23: Abies concolor, Ponderosa pine, Calocedrus decurrens, occasional Pinus lambertiana. shrubs: Symphoricarpos mollis, Quercus garryana var. breweri | W23: Open gravelly ridgeline in white fir dominated mixed conifer forest (white fir, Ponderosa pine, incense cedar, occasional sugar pine). Elevation: 1902 m | X23: yes | Y23: yes | Z23: no | AA23: no | AG23: 35597068-d931-44e5-92a2-1b1f7287a49c,6a2dcbea-cf86-4d56-8320-872b3044e70a,1b0939d1-100a-4846-b03e-9489edd83406,49110acf-b0a9-4870-9df8-5669b5b5cec2,1c6d265b-b074-4273-8e22-7a74bbd5c37d,93e25765-2ecc-46e9-89b6-e23232814e93 | AH23: Lawrence P. Janeway | AI23: 15108-3 | AJ23: Spreading shrub(s) 5-12 dm tall, some branches erect and some decumbent. Locality: High North Coast Ranges. Along ┬▒ open ridgeline 0.6 mi south of Buck Rock. WGS84
A24: CA_BR_4_LJ | B24: 6ac17752-5685-4ac6-abcd-fff71640c49d | C24: Quercus garryana var. breweri | D24: 2024-11-20 22:27:45 UTC | E24: FAB ACE | F24: SRID=4326;POINT(-122.94768 39.90017) | G24: 39.90017 | H24: -122.94768 | I24: Quercus garryana var. breweri | J24: CA | K24: Buck Rock | L24: BR | M24: 4 | N24: LJ | O24: CA_BR_4_LJ | P24: 45573 | R24: 1.8 | V24: Abies concolor, Ponderosa pine, Calocedrus decurrens, occasional Pinus lambertiana. Quercus garryana var. breweri, Prunus emarginata, Ceanothus cordulatus, Amelanchier utahensis | W24: Open gravelly ridgeline in white fir dominated mixed conifer forest (white fir, Ponderosa pine, incense cedar, occasional sugar pine). Elevation: 1896 m | X24: yes | Y24: yes | Z24: no | AA24: no | AG24: 81efe386-3a60-4789-a472-c508a2358573,3adfc2d5-2606-4bd7-88cc-bbfdacd97e43,d889673e-072a-4fe8-8912-4404019a085c,204d7600-e2d8-499d-838b-8a8246b65ec1,23b12f87-315c-45c5-a9aa-376528772ac2,b98b2c48-1460-45b9-a551-f7f7bb6b76fb | AH24: Lawrence P. Janeway | AI24: 15108-4 | AJ24: Sprawling shrub(s) 0.6-1.8 m tall. Locality: High North Coast Ranges. Along ┬▒ open ridgeline 0.6 mi south of Buck Rock. WGS84
A25: CA_BR_5_LJ | B25: a11c646c-aaed-4dda-8f71-316b88aa337e | C25: Quercus garryana var. breweri | D25: 2024-11-20 22:27:35 UTC | E25: FAB ACE | F25: SRID=4326;POINT(-122.948 39.89991) | G25: 39.89991 | H25: -122.948 | I25: Quercus garryana var. breweri | J25: CA | K25: Buck Rock | L25: BR | M25: 5 | N25: LJ | O25: CA_BR_5_LJ | P25: 45573 | R25: 1.5 | U25: Calocedrus decurrens, Abies concolor | V25: Abies concolor, Ponderosa pine, Calocedrus decurrens, occasional Pinus lambertiana. shrubs: Quercus garryana var. breweri, Ceanothus cordulatus | W25: Open gravelly ridgeline in white fir dominated mixed conifer forest (white fir, Ponderosa pine, incense cedar, occasional sugar pine). Elevation: 1902 | X25: yes | Y25: yes | Z25: no | AA25: no | AD25: 3f821919-bdb0-4fcc-8274-2338aa6622c6,2695322d-d52a-4de0-aec5-2e84723e61de | AG25: 0ab9965f-b0e6-4784-9a24-7b5e50c979ef,c7980a90-1051-4bab-8893-4057b3f27af6,fd27a1cd-4eb2-49a3-89db-62d38292bffc,8c2d700b-b282-4202-a898-69cc73d7c825,6a6b4cb7-eced-48da-ac91-68467dd12a77,acbf3a14-34b6-47b7-af31-58cf768855e9 | AH25: Lawrence P. Janeway | AI25: 15108-5 | AJ25: Large sprawling shrub(s) 0.5-1.5 m tall. Locality: High North Coast Ranges. Along ┬▒ open ridgeline 0.6 mi south of Buck Rock. WGS84
A26: CA_BV_1_LJ | B26: 76feca8e-f87d-4922-8d5f-70871fd6ea42 | C26: Quercus garryana var. breweri | D26: 2024-11-20 22:27:22 UTC | E26: FAB ACE | F26: SRID=4326;POINT(-121.292 39.466) | G26: 39.466 | H26: -121.292 | I26: Quercus garryana var. breweri | J26: CA | K26: Brownsville | L26: BV | M26: 1 | N26: LJ | O26: CA_BV_1_LJ | P26: 45574 | R26: 1.8 | U26: Quercus wislizeni var. wislizeni | V26: Arctostaphylos viscida, Quercus garryana var. breweri, Quercus wislizenii, Heteromeles arbutifolia, Cercis occidentalis, Rhamnus ilicifolia. Arctostaphylos viscida, Heteromeles arbutifolia, Ceanothus lemmonii | W26: Southwest-facing dense chaparral of white-leaf manzanita, Brewer oak, interior live oak, toyon, redbud, hollyleaf redberry; rocky gabbro substrate. Elevation: 689 m | X26: yes | Y26: yes | Z26: no | AA26: no | AD26: 53b83138-908e-4a0c-ad96-a46aa19fc0f2 | AG26: 266fe875-57de-4f69-8f36-205fd7df3384,3b57addc-9471-46fc-9997-58c2b990a171 | AH26: Lawrence P. Janeway | AI26: 15110-1 | AJ26: Small cluster of erect stems 1.5-1.8m tall; roadside (dust). Locality: Northern Sierra Nevada Foothills. ALong Ponderosa Way 1.3 road km north of La Porte Road (and Brownsville). WGS84
A27: CA_BV_2_LJ | B27: a2c57563-5a21-478a-9866-2429e8c5ff54 | C27: Quercus garryana var. breweri | D27: 2024-11-20 22:27:11 UTC | E27: FAB ACE | F27: SRID=4326;POINT(-121.29168 39.45636) | G27: 39.45636 | H27: -121.29168 | I27: Quercus garryana var. breweri | J27: CA | K27: Brownsville | L27: BV | M27: 2 | N27: LJ | O27: CA_BV_2_LJ | P27: 45574 | R27: 2 | U27: Pinus ponderosa, Calocedrus decurrens (nearby Quercus wislizeni var. wislizeni, Quercus kelloggii) | V27: Arctostaphylos viscida, Quercus garryana var. breweri, Quercus wislizenii, Heteromeles arbutifolia, Cercis occidentalis, Rhamnus ilicifolia. Arctostaphylos viscida, Cercis occidentalis, Ceanothus lemmonii, Berberis aquifolium, Rhamnus ilicifolia, Toxicodendron diversilobum, Heteromeles arbutifolia | W27: Southwest-facing dense chaparral of white-leaf manzanita, Brewer oak, interior live oak, toyon, redbud, hollyleaf redberry; rocky gabbro substrate. Elevation: 700 m | X27: yes | Y27: yes | Z27: no | AA27: no | AG27: 296d85e1-42b4-4ebe-848b-a264dc2241fd,20ddd3e4-21f6-40bc-b200-53903714c731 | AH27: Lawrence P. Janeway | AI27: 15110-2 | AJ27: Single trunk. Locality: Northern Sierra Nevada Foothills. ALong Ponderosa Way 1.3 road km north of La Porte Road (and Brownsville). WGS84
A28: CA_BV_3_LJ | B28: cebf979c-a257-41b6-a9c8-fc05a1abafa2 | C28: Quercus garryana var. breweri | D28: 2024-11-20 22:26:59 UTC | E28: FAB ACE | F28: SRID=4326;POINT(-121.29162 39.46626) | G28: 39.46626 | H28: -121.29162 | I28: Quercus garryana var. breweri | J28: CA | K28: Brownsville | L28: BV | M28: 3 | N28: LJ | O28: CA_BV_3_LJ | P28: 45574 | Q28: 3 | R28: 3.5 | U28: Pinus ponderosa sapling, small Quercus wislizeni var. wislizeni, Quercus kelloggii seedling (nearby Quercus kelloggii, Heteromeles arbutifolia) | V28: Arctostaphylos viscida, Quercus garryana var. breweri, Quercus wislizenii, Heteromeles arbutifolia, Cercis occidentalis, Rhamnus ilicifolia. shrubs: Arctostaphylos viscida, Ceanothus lemmonii, Cercis occidentalis, Berberis aquifolium, Salvia sonomensis, Rhamnus ilicifolia, Heteromeles arbutifolia, Toxicodendron diversilobum, Pickeringia montana | W28: Southwest-facing dense chaparral of white-leaf manzanita, Brewer oak, interior live oak, toyon, redbud, hollyleaf redberry; rocky gabbro substrate. Elevation: 707 m | X28: yes | Y28: yes | Z28: no | AA28: no | AG28: d9ea71cd-b558-42aa-b21c-eaa15cf1a769,308eaf9d-95ac-474a-9b7a-2304f6295426 | AH28: Lawrence P. Janeway | AI28: 15110-3 | AJ28: Single trunk but leaning into the sun from under a tall Arctostaphylos viscida. Locality: Northern Sierra Nevada Foothills. ALong Ponderosa Way 1.3 road km north of La Porte Road (and Brownsville). WGS84
A29: CA_BV_4_LJ | B29: f2808fea-d6ae-4703-9425-18721367fa67 | C29: Quercus garryana var. breweri | D29: 2024-11-20 22:26:50 UTC | E29: FAB ACE | F29: SRID=4326;POINT(-121.29205 39.4666) | G29: 39.4666 | H29: -121.29205 | I29: Quercus garryana var. breweri | J29: CA | K29: Brownsville | L29: BV | M29: 4 | N29: LJ | O29: CA_BV_4_LJ | P29: 45574 | R29: 2.5 | U29: Quercus wislizeni var. wislizeni (nearby LIDE [Notholithocarpus densiflorus?], Pinus ponderosa) | V29: Arctostaphylos viscida, Quercus garryana var. breweri, Quercus wislizenii, Heteromeles arbutifolia, Cercis occidentalis, Rhamnus ilicifolia. shrubs: Heteromeles arbutifolia, Arctostaphylos viscida | W29: Southwest-facing dense chaparral of white-leaf manzanita, Brewer oak, interior live oak, toyon, redbud, hollyleaf redberry; rocky gabbro substrate. Elevation: 686 m | X29: yes | Y29: yes | Z29: no | AA29: no | AG29: c07d5aa2-1706-42ef-951c-be5f9a161f59,b648448f-e352-45d8-a78c-e7300344f359 | AH29: Lawrence P. Janeway | AI29: 15110-4 | AJ29: Dusty along road. Locality: Northern Sierra Nevada Foothills. ALong Ponderosa Way 1.3 road km north of La Porte Road (and Brownsville). WGS84
A30: CA_BV_5_LJ | B30: 5f32d7cb-4fda-4157-bef7-56b896116340 | C30: Quercus garryana var. breweri | D30: 2024-11-20 22:26:40 UTC | E30: FAB ACE | F30: SRID=4326;POINT(-121.29197 39.46677) | G30: 39.46677 | H30: -121.29197 | I30: Quercus garryana var. breweri | J30: CA | K30: Brownsville | L30: BV | M30: 5 | N30: LJ | O30: CA_BV_5_LJ | P30: 45574 | U30: Quercus wislizeni var. wislizeni, Pinus ponderosa (nearby Pinus sabiniana) | V30: Arctostaphylos viscida, Quercus garryana var. breweri, Quercus wislizenii, Heteromeles arbutifolia, Cercis occidentalis, Rhamnus ilicifolia. shrubs: Ceanothus lemmonii, Berberis aquifolium, Arctostaphylos viscida, Rhamnus ilicifolia | W30: Southwest-facing dense chaparral of white-leaf manzanita, Brewer oak, interior live oak, toyon, redbud, hollyleaf redberry; rocky gabbro substrate. Elevation: 690 m | X30: yes | Y30: yes | Z30: no | AA30: no | AG30: e9ee3b09-1439-4365-9997-39c5f9f1c74f,79ebbafa-75b7-407e-8765-d63ea50acec7 | AH30: Lawrence P. Janeway | AI30: 15110-5 | AJ30: 2-3 long stems arching out from under a large Quercus wislizeni var. wislizeni
A31: WA_SJI_1_PD | B31: 8d22b9ae-bbdf-43d3-9291-815544deb5db | C31: Quercus garryana var. garryana | D31: 2024-11-20 22:26:28 UTC | E31: FAB ACE | F31: SRID=4326;POINT(-123.04203 48.50379) | G31: 48.50379 | H31: -123.04203 | I31: Quercus garryana var. garryana | J31: WA | K31: San Juan Island | L31: SJI | M31: 1 | N31: PD | O31: WA_SJI_1_PD | P31: 45558 | Q31: 75 | R31: 13 | W31: A widely spreading, open-grown tree in a hedgerow of Rubus bifrons and Symphoricarpos album. A large Pseudotsuga menziesii is growing immediately adjacent to it. | X31: no | Y31: yes | Z31: no | AA31: no | AH31: "Peter Dunwiddie, Peter Zika, R. Adam Martin" | AI31: Peter Dunwiddie, Peter Zika, R. Adam Martin 1 | AJ31: Willey/Little Rd junction, San Juan Island
A32: WA_SJI_2_PD | B32: 2b8d0b81-cab2-46b2-b9f6-509514f1cd77 | C32: Quercus garryana var. garryana | D32: 2024-11-20 22:26:19 UTC | E32: FAB ACE | F32: SRID=4326;POINT(-123.04151 48.50654) | G32: 48.50654 | H32: -123.04151 | I32: Quercus garryana var. garryana | J32: WA | K32: San Juan Island | L32: SJI | M32: 2 | N32: PD | O32: WA_SJI_2_PD | P32: 45558 | Q32: 55 | R32: 16 | W32: One of many oaks in an open woodland of large oaks, most trees are open grown and 12-17m (est.) tall. | X32: no | Y32: yes | Z32: no | AA32: no | AH32: "Peter Dunwiddie, Peter Zika, R. Adam Martin" | AI32: Peter Dunwiddie, Peter Zika, R. Adam Martin 2 | AJ32: Locality: North end of Willey Rd, San Juan Island
A33: WA_SJI_3_PD | B33: 328a9f41-1a95-489f-a637-5169930ae2f1 | C33: Quercus garryana var. garryana | D33: 2024-11-20 22:26:08 UTC | E33: FAB ACE | F33: SRID=4326;POINT(-123.0136111 48.54508333) | G33: 48.545083 | H33: -123.01361 | I33: Quercus garryana var. garryana | J33: WA | K33: San Juan Island | L33: SJI | M33: 3 | N33: PD | O33: WA_SJI_3_PD | P33: 45558 | Q33: 75 | R33: 10 | W33: At edge of coastal bald above Friday Harbor shoreline. No other trees or shrubs anywhere nearby. | X33: no | Y33: yes | Z33: no | AA33: no | AH33: "Peter Dunwiddie, Peter Zika, R. Adam Martin" | AI33: Peter Dunwiddie, Peter Zika, R. Adam Martin 3 | AJ33: Locality: Friday Harbor Laboratory grounds, San Juan Island
A34: WA_SJI_4_PD | B34: c71615e4-f92d-4e55-8e97-c19259fbc954 | C34: Quercus garryana var. garryana | D34: 2024-11-20 22:25:58 UTC | E34: FAB ACE | F34: SRID=4326;POINT(-123.143823 48.580145) | G34: 48.580145 | H34: -123.14382 | I34: Quercus garryana var. garryana | J34: WA | K34: San Juan Island | L34: SJI | M34: 4 | N34: PD | O34: WA_SJI_4_PD | P34: 45559 | Q34: 80 | V34: Acer macrophyllum, Symphoricarpos album, Rosa nutkana | W34: No nearby oaks but smaller (10-20cm dbh) Acer macrophyllum close by. Understory of Symphoricarpos album and Rosa nutkana | X34: no | Y34: yes | Z34: no | AA34: no | AH34: "Peter Dunwiddie, Peter Zika, R. Adam Martin" | AI34: Peter Dunwiddie, Peter Zika, R. Adam Martin 4 | AJ34: A large, multi-stemmed (4) tree, trunks ca. 60-80 cm dbh. Locality: Edge of British Camp, West Valley Rd., San Juan Island
A35: WA_SJI_5_PD | B35: 0329249c-cc82-4702-8105-ae2a633cb40e | C35: Quercus garryana var. garryana | D35: 2024-11-20 22:25:49 UTC | E35: FAB ACE | F35: SRID=4326;POINT(-123.140643 48.575688) | G35: 48.575688 | H35: -123.14064 | I35: Quercus garryana var. garryana | J35: WA | K35: San Juan Island | L35: SJI | M35: 5 | N35: PD | O35: WA_SJI_5_PD | P35: 45559 | Q35: 100 | R35: 15 | V35: Pseudotsuga menziesii | W35: Roadside tree at edge of grassy pasture. Several Pseudotsuga menziesii trees within 100 feet | X35: no | Y35: yes | Z35: no | AA35: no | AH35: "Peter Dunwiddie, Peter Zika, R. Adam Martin" | AI35: Peter Dunwiddie, Peter Zika, R. Adam Martin 5 | AJ35: Locality: Alpaca farm, West Valley Rd, San Juan Island
A36: OR_EDM_1_DG | B36: 8737f35c-2d5b-4444-873a-c1f9e2b4c744 | C36: Quercus garryana var. semota | D36: 2024-11-20 22:25:39 UTC | E36: FAB ACE | F36: SRID=4326;POINT(-123.6657217 42.23339833) | G36: 42.233398 | H36: -123.66572 | I36: Quercus garryana var. semota | J36: OR | K36: Eight Dollar Mnt Rd | L36: EDM | M36: 1 | N36: DG | O36: OR_EDM_1_DG | P36: 45572 | W36: Dry, S-facing slope above Illinois R., with broadly spaced pines, Arctostaphylos, dry forbs in October; intermittent serpentine; Q. chrysolepis or Q. chrysolepis ├ù vacciniifolia is present a bit down road to W (a more densely treed area); noted Darlingtonia fens. Elevation 424 m | X36: no | Y36: yes | Z36: no | AA36: no | AH36: Dirk Giesburt | AI36: Dirk Giesburt 1 | AJ36: Very productive acorn season 2023; none in Oct. 2024. Locality: OR Josephine County, Illinois R. basin, Rogue River-Siskiyou National Forest, Eight Dollar Mountain Rd., west of Jeffrey Pine Loop Trailhead, S side of road just below road maintenance deposit area.
A37: OR_EDM_2_DG | B37: 716d4895-1ecf-4c01-8891-acada9bebc4a | C37: Quercus garryana aff. var. semota | D37: 2024-11-20 22:25:28 UTC | E37: FAB ACE | F37: SRID=4326;POINT(-123.6691383 42.23716667) | G37: 42.237167 | H37: -123.66914 | I37: Quercus garryana aff. var. semota | J37: OR | K37: Eight Dollar Mnt Rd | L37: EDM | M37: 2 | N37: DG | O37: OR_EDM_2_DG | P37: 45572 | W37: Dry, S-facing slope above Illinois R., with broadly spaced pines, Arctostaphylos, dry forbs in October; intermittent serpentine; Q. chrysolepis or Q. chrysolepis ├ù vacciniifolia is present a bit down road to W (a more densely treed area); noted Darlingtonia fens. Elevation 422 m | X37: no | Y37: yes | Z37: no | AA37: no | AH37: Dirk Giesburt | AI37: Dirk Giesburt 2 | AJ37: Locality: OR Josephine County, Illinois R. basin, Rogue River-Siskiyou National Forest, Eight Dollar Mountain Rd., west of Jeffrey Pine Loop Trailhead, W of Q. garryana 1, N side of road, top of road cut
A38: OR_EDM_3_DG | B38: aedf313a-7e5a-46e6-a101-124c379e4698 | C38: Quercus garryana | D38: 2024-11-20 22:25:18 UTC | E38: FAB ACE | F38: SRID=4326;POINT(-123.643215 42.23188833) | G38: 42.231888 | H38: -123.64321 | I38: Quercus garryana | J38: OR | K38: Eight Dollar Mnt Rd | L38: EDM | M38: 3 | N38: DG | O38: OR_EDM_3_DG | P38: 45572 | W38: Broken woodland with small-sized, dry-site Q. garryana var. garryana with pines. Elevation 395 m | X38: no | Y38: yes | Z38: no | AA38: no | AH38: Dirk Giesburt | AI38: Dirk Giesburt 3 | AJ38: Locality: OR Josephine County, Illinois R. basin, Rogue River-Siskiyou National Forest, Eight Dollar Mountain Rd., at E end, ~100 m from Hwy 199, S side of road nr. Roadcut
A39: OR_WCR_4_DG | B39: 8732474c-daa4-43d5-8ada-af475e91eed5 | C39: Quercus garryana | D39: 2024-11-20 22:25:07 UTC | E39: FAB ACE | F39: SRID=4326;POINT(-123.5589383 42.37610833) | G39: 42.376108 | H39: -123.55894 | I39: Quercus garryana | J39: OR | K39: Waters Creek Rd | L39: WCR | M39: 4 | N39: DG | O39: OR_WCR_4_DG | P39: 45572 | W39: Wooded, rural residential valley of easterly-flowing Waters Cr.; specimen has riparian location at top of short, steep creek bank. Elevation 368 m | X39: no | Y39: yes | Z39: no | AA39: no | AH39: Dirk Giesburt | AI39: Dirk Giesburt 4 | AJ39: Productive acorn season 2024. Locality: OR Josephine County, Slate Cr. Valley, S side of Rogue R. basin, Waters Cr. Rd., 1.4 mi from Hwy 199, N side of large turnout
A40: OR_RSP_5_DG | B40: 93eb0322-f1de-4e5d-b611-d66216bece43 | C40: Quercus garryana | D40: 2024-11-20 22:24:57 UTC | E40: FAB ACE | F40: SRID=4326;POINT(-123.1290833 42.4104) | G40: 42.4104 | H40: -123.12908 | I40: Quercus garryana | J40: OR | K40: Rogue St. Park | L40: RSP | M40: 5 | N40: DG | O40: OR_RSP_5_DG | P40: 45572 | V40: mostly Q. kelloggii with conifers and introduced tree species | W40: Large tree in flat, exposed, open turf area of park spreading away from Rogue R. bank; mostly Q. kelloggii with conifers and introduced tree species. Elevation 315 m | X40: no | Y40: yes | Z40: no | AA40: no | AH40: Dirk Giesburt | AI40: Dirk Giesburt 5 | AJ40: Locality: OR Jackson County, Rogue R. basin, Valley of the Rogue St. Park, middle of broad turf area toward W end of park's developed area
...

Sheet Sheet4
A1: Seq | B1: Bam | C1: collectionNumber | D1: State | E1: siteABB | F1: Pop | G1: GenomicVoucherID_USE_THIS | H1: Sp | I1: count
A2: SYST-MOR-0007129 | B2: =_xlfn.CONCAT(A2,".bam") -> SYST-MOR-0007129.bam | C2: AR_BRP_409_MG | D2: AR | E2: BRP | F2: AR_BRP | G2: Quercus lyrata Walt. | H2: =IF(ISERROR(FIND("x",LEFT(G2,LEN(G2)-7),1)),RIGHT(LEFT(G2,11),3),G2) -> lyr | I2: 1
A3: SYST-MOR-0007130 | B3: =_xlfn.CONCAT(A3,".bam") -> SYST-MOR-0007130.bam | C3: AR_BRP_410_MG | D3: AR | E3: BRP | F3: AR_BRP | G3: Quercus macrocarpa Michx. | H3: =IF(ISERROR(FIND("x",LEFT(G3,LEN(G3)-7),1)),RIGHT(LEFT(G3,11),3),G3) -> mac | I3: 1
A4: SYST-MOR-0007131 | B4: =_xlfn.CONCAT(A4,".bam") -> SYST-MOR-0007131.bam | C4: AR_BRP_411_MG | D4: AR | E4: BRP | F4: AR_BRP | G4: Quercus stellata Wangenh. | H4: =IF(ISERROR(FIND("x",LEFT(G4,LEN(G4)-7),1)),RIGHT(LEFT(G4,11),3),G4) -> ste | I4: 1
A5: SYST-MOR-0007132 | B5: =_xlfn.CONCAT(A5,".bam") -> SYST-MOR-0007132.bam | C5: AR_BRP_412_MG | D5: AR | E5: BRP | F5: AR_BRP | G5: Quercus macrocarpa Michx. | H5: =IF(ISERROR(FIND("x",LEFT(G5,LEN(G5)-7),1)),RIGHT(LEFT(G5,11),3),G5) -> mac | I5: 1
A6: SYST-MOR-0007133 | B6: =_xlfn.CONCAT(A6,".bam") -> SYST-MOR-0007133.bam | C6: AR_BRP_413_MG | D6: AR | E6: BRP | F6: AR_BRP | G6: Quercus stellata Wangenh. | H6: =IF(ISERROR(FIND("x",LEFT(G6,LEN(G6)-7),1)),RIGHT(LEFT(G6,11),3),G6) -> ste | I6: 1
A7: SYST-MOR-0007134 | B7: =_xlfn.CONCAT(A7,".bam") -> SYST-MOR-0007134.bam | C7: AR_BRP_414_MG | D7: AR | E7: BRP | F7: AR_BRP | G7: Quercus lyrata Walt. | H7: =IF(ISERROR(FIND("x",LEFT(G7,LEN(G7)-7),1)),RIGHT(LEFT(G7,11),3),G7) -> lyr | I7: 1
A8: SYST-MOR-0007135 | B8: =_xlfn.CONCAT(A8,".bam") -> SYST-MOR-0007135.bam | C8: AR_BRP_415_MG | D8: AR | E8: BRP | F8: AR_BRP | G8: Quercus alba L. | H8: =IF(ISERROR(FIND("x",LEFT(G8,LEN(G8)-7),1)),RIGHT(LEFT(G8,11),3),G8) -> alb | I8: 1
A9: SYST-MOR-0007136 | B9: =_xlfn.CONCAT(A9,".bam") -> SYST-MOR-0007136.bam | C9: AR_BRP_416_MG | D9: AR | E9: BRP | F9: AR_BRP | G9: Quercus stellata Wangenh. | H9: =IF(ISERROR(FIND("x",LEFT(G9,LEN(G9)-7),1)),RIGHT(LEFT(G9,11),3),G9) -> ste | I9: 1
A10: SYST-MOR-0007137 | B10: =_xlfn.CONCAT(A10,".bam") -> SYST-MOR-0007137.bam | C10: AR_BRP_417_MG | D10: AR | E10: BRP | F10: AR_BRP | G10: Quercus macrocarpa Michx. | H10: =IF(ISERROR(FIND("x",LEFT(G10,LEN(G10)-7),1)),RIGHT(LEFT(G10,11),3),G10) -> mac | I10: 1
A11: SYST-MOR-0007138 | B11: =_xlfn.CONCAT(A11,".bam") -> SYST-MOR-0007138.bam | C11: AR_BRP_418_MG | D11: AR | E11: BRP | F11: AR_BRP | G11: Quercus lyrata Walt. | H11: =IF(ISERROR(FIND("x",LEFT(G11,LEN(G11)-7),1)),RIGHT(LEFT(G11,11),3),G11) -> lyr | I11: 1
A12: SYST-MOR-0007139 | B12: =_xlfn.CONCAT(A12,".bam") -> SYST-MOR-0007139.bam | C12: AR_BRP_419_MG | D12: AR | E12: BRP | F12: AR_BRP | G12: Quercus stellata Wangenh. | H12: =IF(ISERROR(FIND("x",LEFT(G12,LEN(G12)-7),1)),RIGHT(LEFT(G12,11),3),G12) -> ste | I12: 1
A13: SYST-MOR-0007140 | B13: =_xlfn.CONCAT(A13,".bam") -> SYST-MOR-0007140.bam | C13: AR_BRP_420_MG | D13: AR | E13: BRP | F13: AR_BRP | G13: Quercus alba L. | H13: =IF(ISERROR(FIND("x",LEFT(G13,LEN(G13)-7),1)),RIGHT(LEFT(G13,11),3),G13) -> alb | I13: 1
... A57: SYST-MOR-0007250 | B57: =_xlfn.CONCAT(A57,".bam") -> SYST-MOR-0007250.bam | C57: IL_CHB_530_MG | D57: IL | E57: CHB | F57: IL_CHB | G57: Quercus alba L. | H57: =IF(ISERROR(FIND("x",LEFT(G57,LEN(G57)-7),1)),RIGHT(LEFT(G57,11),3),G57) -> alb | I57: 1
A58: SYST-MOR-0006717 | B58: =_xlfn.CONCAT(A58,".bam") -> SYST-MOR-0006717.bam | C58: IL_HP_MG919_MG | D58: IL | E58: HP | F58: IL_HP | G58: Quercus michauxii Nutt. | H58: mic | I58: 1
A59: SYST-MOR-0006718 | B59: =_xlfn.CONCAT(A59,".bam") -> SYST-MOR-0006718.bam | C59: IL_HP_MG920_MG | D59: IL | E59: HP | F59: IL_HP | G59: Quercus michauxii Nutt. | H59: mic | I59: 1
A60: SYST-MOR-0006719 | B60: =_xlfn.CONCAT(A60,".bam") -> SYST-MOR-0006719.bam | C60: IL_HP_MG921_MG | D60: IL | E60: HP | F60: IL_HP | G60: Quercus michauxii Nutt. | H60: mic | I60: 1
A61: SYST-MOR-0006729 | B61: =_xlfn.CONCAT(A61,".bam") -> SYST-MOR-0006729.bam | C61: IL_MOR_135_MG | D61: IL | E61: MOR | F61: IL_MOR | G61: Quercus macrocarpa Michx. | H61: =IF(ISERROR(FIND("x",LEFT(G61,LEN(G61)-7),1)),RIGHT(LEFT(G61,11),3),G61) -> mac | I61: 1
A62: SYST-MOR-0006732 | B62: =_xlfn.CONCAT(A62,".bam") -> SYST-MOR-0006732.bam | C62: IL_MOR_136_MG | D62: IL | E62: MOR | F62: IL_MOR | G62: Quercus alba L. | H62: =IF(ISERROR(FIND("x",LEFT(G62,LEN(G62)-7),1)),RIGHT(LEFT(G62,11),3),G62) -> alb | I62: 1
A63: SYST-MOR-0006731 | B63: =_xlfn.CONCAT(A63,".bam") -> SYST-MOR-0006731.bam | C63: IL_MOR_137_MG | D63: IL | E63: MOR | F63: IL_MOR | G63: Quercus macrocarpa Michx. | H63: =IF(ISERROR(FIND("x",LEFT(G63,LEN(G63)-7),1)),RIGHT(LEFT(G63,11),3),G63) -> mac | I63: 1
A64: SYST-MOR-0006730 | B64: =_xlfn.CONCAT(A64,".bam") -> SYST-MOR-0006730.bam | C64: IL_MOR_138_MG | D64: IL | E64: MOR | F64: IL_MOR | G64: Quercus alba L. | H64: =IF(ISERROR(FIND("x",LEFT(G64,LEN(G64)-7),1)),RIGHT(LEFT(G64,11),3),G64) -> alb | I64: 1
A65: SYST-MOR-0006733 | B65: =_xlfn.CONCAT(A65,".bam") -> SYST-MOR-0006733.bam | C65: IL_MOR_139_MG | D65: IL | E65: MOR | F65: IL_MOR | G65: Quercus bicolor Willd. | H65: =IF(ISERROR(FIND("x",LEFT(G65,LEN(G65)-7),1)),RIGHT(LEFT(G65,11),3),G65) -> bic | I65: 1
A66: SYST-MOR-0006734 | B66: =_xlfn.CONCAT(A66,".bam") -> SYST-MOR-0006734.bam | C66: IL_MOR_140_MG | D66: IL | E66: MOR | F66: IL_MOR | G66: Quercus alba L. | H66: =IF(ISERROR(FIND("x",LEFT(G66,LEN(G66)-7),1)),RIGHT(LEFT(G66,11),3),G66) -> alb | I66: 1
A67: SYST-MOR-0006736 | B67: =_xlfn.CONCAT(A67,".bam") -> SYST-MOR-0006736.bam | C67: IL_MOR_141_MG | D67: IL | E67: MOR | F67: IL_MOR | G67: Quercus alba L. | H67: =IF(ISERROR(FIND("x",LEFT(G67,LEN(G67)-7),1)),RIGHT(LEFT(G67,11),3),G67) -> alb | I67: 1
A68: SYST-MOR-0006735 | B68: =_xlfn.CONCAT(A68,".bam") -> SYST-MOR-0006735.bam | C68: IL_MOR_142_MG | D68: IL | E68: MOR | F68: IL_MOR | G68: Quercus macrocarpa Michx. | H68: =IF(ISERROR(FIND("x",LEFT(G68,LEN(G68)-7),1)),RIGHT(LEFT(G68,11),3),G68) -> mac | I68: 1
A69: SYST-MOR-0006737 | B69: =_xlfn.CONCAT(A69,".bam") -> SYST-MOR-0006737.bam | C69: IL_MOR_143_MG | D69: IL | E69: MOR | F69: IL_MOR | G69: Quercus macrocarpa Michx. | H69: =IF(ISERROR(FIND("x",LEFT(G69,LEN(G69)-7),1)),RIGHT(LEFT(G69,11),3),G69) -> mac | I69: 1
A70: SYST-MOR-0006739 | B70: =_xlfn.CONCAT(A70,".bam") -> SYST-MOR-0006739.bam | C70: IL_MOR_144_MG | D70: IL | E70: MOR | F70: IL_MOR | G70: Quercus alba L. | H70: =IF(ISERROR(FIND("x",LEFT(G70,LEN(G70)-7),1)),RIGHT(LEFT(G70,11),3),G70) -> alb | I70: 1
A71: SYST-MOR-0006738 | B71: =_xlfn.CONCAT(A71,".bam") -> SYST-MOR-0006738.bam | C71: IL_MOR_145_MG | D71: IL | E71: MOR | F71: IL_MOR | G71: Quercus macrocarpa Michx. | H71: =IF(ISERROR(FIND("x",LEFT(G71,LEN(G71)-7),1)),RIGHT(LEFT(G71,11),3),G71) -> mac | I71: 1
A72: SYST-MOR-0006740 | B72: =_xlfn.CONCAT(A72,".bam") -> SYST-MOR-0006740.bam | C72: IL_MOR_146_MG | D72: IL | E72: MOR | F72: IL_MOR | G72: Quercus macrocarpa Michx. | H72: =IF(ISERROR(FIND("x",LEFT(G72,LEN(G72)-7),1)),RIGHT(LEFT(G72,11),3),G72) -> mac | I72: 1
... A82: SYST-MOR-0006761 | B82: =_xlfn.CONCAT(A82,".bam") -> SYST-MOR-0006761.bam | C82: IL_OB_029_All | D82: IL | E82: OB | F82: IL_OB | G82: Quercus macrocarpa Michx. | H82: =IF(ISERROR(FIND("x",LEFT(G82,LEN(G82)-7),1)),RIGHT(LEFT(G82,11),3),G82) -> mac | I82: 1
A83: SYST-MOR-0006762 | B83: =_xlfn.CONCAT(A83,".bam") -> SYST-MOR-0006762.bam | C83: IL_OB_030_All | D83: IL | E83: OB | F83: IL_OB | G83: Quercus lyrata x Quercus macrocarpa | H83: lyr x mac | I83: 1
A84: SYST-MOR-0007180 | B84: =_xlfn.CONCAT(A84,".bam") -> SYST-MOR-0007180.bam | C84: IL_RCA_460_MG | D84: IL | E84: RCA | F84: IL_RCA | G84: Quercus alba L. | H84: =IF(ISERROR(FIND("x",LEFT(G84,LEN(G84)-7),1)),RIGHT(LEFT(G84,11),3),G84) -> alb | I84: 1
A85: SYST-MOR-0007181 | B85: =_xlfn.CONCAT(A85,".bam") -> SYST-MOR-0007181.bam | C85: IL_RCA_461_MG | D85: IL | E85: RCA | F85: IL_RCA | G85: Quercus macrocarpa Michx. | H85: =IF(ISERROR(FIND("x",LEFT(G85,LEN(G85)-7),1)),RIGHT(LEFT(G85,11),3),G85) -> mac | I85: 1
A86: SYST-MOR-0007182 | B86: =_xlfn.CONCAT(A86,".bam") -> SYST-MOR-0007182.bam | C86: IL_RCA_462_MG | D86: IL | E86: RCA | F86: IL_RCA | G86: Quercus bicolor Willd. | H86: =IF(ISERROR(FIND("x",LEFT(G86,LEN(G86)-7),1)),RIGHT(LEFT(G86,11),3),G86) -> bic | I86: 1
A87: SYST-MOR-0007183 | B87: =_xlfn.CONCAT(A87,".bam") -> SYST-MOR-0007183.bam | C87: IL_RCA_463_MG | D87: IL | E87: RCA | F87: IL_RCA | G87: Quercus macrocarpa Michx. | H87: =IF(ISERROR(FIND("x",LEFT(G87,LEN(G87)-7),1)),RIGHT(LEFT(G87,11),3),G87) -> mac | I87: 1
A88: SYST-MOR-0007184 | B88: =_xlfn.CONCAT(A88,".bam") -> SYST-MOR-0007184.bam | C88: IL_RCA_464_MG | D88: IL | E88: RCA | F88: IL_RCA | G88: Quercus alba L. | H88: =IF(ISERROR(FIND("x",LEFT(G88,LEN(G88)-7),1)),RIGHT(LEFT(G88,11),3),G88) -> alb | I88: 1
A89: SYST-MOR-0007185 | B89: =_xlfn.CONCAT(A89,".bam") -> SYST-MOR-0007185.bam | C89: IL_RCA_465_MG | D89: IL | E89: RCA | F89: IL_RCA | G89: Quercus bicolor Willd. | H89: =IF(ISERROR(FIND("x",LEFT(G89,LEN(G89)-7),1)),RIGHT(LEFT(G89,11),3),G89) -> bic | I89: 1
A90: SYST-MOR-0007186 | B90: =_xlfn.CONCAT(A90,".bam") -> SYST-MOR-0007186.bam | C90: IL_RCA_466_MG | D90: IL | E90: RCA | F90: IL_RCA | G90: Quercus alba L. | H90: =IF(ISERROR(FIND("x",LEFT(G90,LEN(G90)-7),1)),RIGHT(LEFT(G90,11),3),G90) -> alb | I90: 1
A91: SYST-MOR-0007187 | B91: =_xlfn.CONCAT(A91,".bam") -> SYST-MOR-0007187.bam | C91: IL_RCA_467_MG | D91: IL | E91: RCA | F91: IL_RCA | G91: Quercus bicolor Willd. | H91: =IF(ISERROR(FIND("x",LEFT(G91,LEN(G91)-7),1)),RIGHT(LEFT(G91,11),3),G91) -> bic | I91: 1
A92: SYST-MOR-0007188 | B92: =_xlfn.CONCAT(A92,".bam") -> SYST-MOR-0007188.bam | C92: IL_RCA_468_MG | D92: IL | E92: RCA | F92: IL_RCA | G92: Quercus macrocarpa Michx. | H92: =IF(ISERROR(FIND("x",LEFT(G92,LEN(G92)-7),1)),RIGHT(LEFT(G92,11),3),G92) -> mac | I92: 1
...

Sheet Sheet9
A1: Sum of count | B1: Column Labels
A2: Row Labels | B2: mon | C2: mar | D2: alb | E2: alb x mac | F2: alb x mic | G2: alb x mue | H2: bic | I2: bic x mac | J2: lob | K2: lyr | L2: lyr x mac | M2: lyr x mic | N2: mac | O2: mac x mue | P2: mic | Q2: mue | R2: pri | S2: rub | T2: sin | U2: ste | V2: (blank) | W2: Grand Total
A3: AR_BRP | D3: 5 | K3: 4 | N3: 5 | Q3: 2 | U3: 5 | W3: 21
A4: IA_BSP | N4: 5 | W4: 5
A5: IA_CHP | H5: 1 | N5: 4 | W5: 5
A6: IA_LNW | D6: 5 | H6: 2 | N6: 2 | Q6: 6 | W6: 15
A7: IL_CHB | D7: 5 | N7: 5 | W7: 10
A8: IL_HP | P8: 3 | W8: 3
A9: IL_MOR | D9: 6 | H9: 1 | N9: 6 | W9: 13
A10: IL_OB | K10: 4 | L10: 1 | N10: 5 | W10: 10
A11: IL_RCA | D11: 5 | H11: 4 | I11: 1 | N11: 5 | W11: 15
A12: IN_BLR | N12: 2 | W12: 2
A13: IN_BOW | N13: 10 | W13: 10
A14: IN_GRL | D14: 5 | W14: 5
A15: IN_IUC | N15: 1 | W15: 1
A16: IN_LCP | N16: 2 | Q16: 5 | W16: 7
A17: IN_MWT | D17: 4 | H17: 2 | N17: 1 | Q17: 3 | W17: 10
A18: IN_TYL | D18: 3 | G18: 1 | H18: 3 | N18: 3 | Q18: 4 | W18: 14
A19: KS_KCP | R19: 2 | W19: 2
A20: KS_KZP | N20: 5 | Q20: 5 | W20: 10
A21: KS_LWP | N21: 6 | W21: 6
A22: KS_MPR | N22: 10 | W22: 10
A23: KS_SMP | D23: 5 | N23: 5 | Q23: 5 | U23: 5 | W23: 20
A24: KY_ASF | N24: 5 | Q24: 5 | W24: 10
A25: KY_BBF | N25: 5 | Q25: 5 | W25: 10
A26: KY_CSW | N26: 1 | Q26: 2 | W26: 3
A27: KY_GRF | N27: 5 | W27: 5
A28: KY_JJA | D28: 3 | F28: 1 | K28: 4 | M28: 1 | P28: 3 | Q28: 3 | W28: 15
A29: KY_LXC | N29: 4 | W29: 4
A30: MA_BTC | D30: 2 | N30: 1 | Q30: 5 | W30: 8
A31: MA_LKN | D31: 3 | N31: 1 | W31: 4
A32: MA_NMK | N32: 5 | W32: 5
A33: MA_SBF | D33: 2 | N33: 4 | W33: 6
A34: MB_ASF | N34: 10 | W34: 10
A35: MB_SWP | N35: 10 | W35: 10
A36: MB_WPP | N36: 10 | W36: 10
A37: MI_LLP | D37: 5 | H37: 5 | N37: 1 | W37: 11
A38: MI_PCP | I38: 2 | N38: 9 | W38: 11
A39: MI_PRA | D39: 5 | E39: 1 | H39: 4 | N39: 4 | R39: 5 | W39: 19
A40: MN_CDR | D40: 5 | N40: 5 | W40: 10
...

Sheet Sheet1
A1: INDEX | B1: Specimen CODE | C1: Seq | D1: Bam | E1: collectionNumber | F1: State | G1: siteABB | H1: Pop | I1: site | J1: Alt_Coll_No | K1: GenomicVoucherID_USE_THIS | L1: GenomicVoucherID_USE_THIS | M1: Species_reidentified | N1: FieldID_LABEL_Species_author | O1: id_modifier | P1: Genus | Q1: Species_ept | R1: spEpt | S1: collectionDate | T1: collectors | U1: Material type | V1: Received by MOR | W1: country | X1: state/provIndIowanace | Y1: substate | Z1: substateRank | AA1: site | AB1: habitat | AC1: DBH-cm | AD1: determinationOriginal | AE1: latitude.orig | AF1: longitude.orig | AG1: voucher1 | AH1: Wild_Arb_GH_Collected | AI1: lat_fixed | AJ1: long_fixed | AK1: lat_difference | AL1: long_difference | AM1: ADMIX_ALL_K8 | AN1: ADMIX_SS | AO1: MONG_PHYLO | AP1: MAC_PHYLO | AQ1: CONSTRUCT | AR1: GEA | AS1: MAC_DSTATS | AT1: MONG_DSTATS | AU1: MAC_PAINT | AV1: K8 | AW1: K12
C2: SRR14632920 | D2: =_xlfn.CONCAT(C2,".bam") -> SRR14632920.bam | G2: LOB | K2: Quercus lobata Nee. | L2: Quercus lobata Nee. | Q2: lobata | R2: lob | AM2: =_xlfn.IFNA(VLOOKUP(Sheet1!$C2,ADMIX_ALL!A:B,2,FALSE),"none") -> K6-18 | AN2: =_xlfn.IFNA(VLOOKUP(Sheet1!C2,ADMIX_SS!A:B,2,FALSE),"none") -> SubSample | AO2: =_xlfn.IFNA(VLOOKUP(Sheet1!$C2,MONG_PHYLO!A:C,3,FALSE),"-") -> - | AP2: =_xlfn.IFNA(VLOOKUP(Sheet1!$C2,MAC_PHYLO!A:C,3,FALSE),"-") -> lob | AQ2: =_xlfn.IFNA(VLOOKUP(Sheet1!$C2,ConStruct!A:C,3,FALSE),"-") -> - | AR2: =_xlfn.IFNA(VLOOKUP(Sheet1!$C2,GEA!A:C,3,FALSE),"-") -> - | AS2: =_xlfn.IFNA(VLOOKUP(Sheet1!$C2,MAC_DSUITE!A:D,3,FALSE),"-") -> lob | AT2: =_xlfn.IFNA(VLOOKUP(Sheet1!$C2,MONG_DSUITE!A:E,2,FALSE),"-") -> xxx | AU2: =_xlfn.IFNA(VLOOKUP(Sheet1!$C2,MAC_PAINT2!A:D,4,FALSE),"-") -> lob-macpaint
C3: SRR14632922 | D3: =_xlfn.CONCAT(C3,".bam") -> SRR14632922.bam | G3: LOB | K3: Quercus lobata Nee. | L3: Quercus lobata Nee. | Q3: lobata | R3: lob | AM3: =_xlfn.IFNA(VLOOKUP(Sheet1!$C3,ADMIX_ALL!A:B,2,FALSE),"none") -> K6-18 | AN3: =_xlfn.IFNA(VLOOKUP(Sheet1!C3,ADMIX_SS!A:B,2,FALSE),"none") -> SubSample | AO3: =_xlfn.IFNA(VLOOKUP(Sheet1!$C3,MONG_PHYLO!A:C,3,FALSE),"-") -> - | AP3: =_xlfn.IFNA(VLOOKUP(Sheet1!$C3,MAC_PHYLO!A:C,3,FALSE),"-") -> - | AQ3: =_xlfn.IFNA(VLOOKUP(Sheet1!$C3,ConStruct!A:C,3,FALSE),"-") -> - | AR3: =_xlfn.IFNA(VLOOKUP(Sheet1!$C3,GEA!A:C,3,FALSE),"-") -> - | AS3: =_xlfn.IFNA(VLOOKUP(Sheet1!$C3,MAC_DSUITE!A:D,3,FALSE),"-") -> - | AT3: =_xlfn.IFNA(VLOOKUP(Sheet1!$C3,MONG_DSUITE!A:E,2,FALSE),"-") -> xxx | AU3: =_xlfn.IFNA(VLOOKUP(Sheet1!$C3,MAC_PAINT2!A:D,4,FALSE),"-") -> -
